Workbook

Sheet Summary
A1: Amazon_Now — In Stock % by run
A2: In Stock / (In Stock + Out of Stock). Excluded from both halves: rows with no reading, rows from a store marked Serviceable = No, and "Not Available" rows (the store does not carry the item — an assortment gap, not a stock-out). The 'Not carried' block below counts those.
A4: Pincode | B4: 2026-09-11 08:45 | C4: 2026-09-11 10:32 | D4: 2026-09-11 12:01 | E4: 2026-09-11 12:53 | F4: 2026-09-12 13:30 | G4: 2026-09-12 21:41 | H4: 2026-09-12 21:58 | I4: 2026-09-13 06:25 | J4: 2026-09-13 06:40 | K4: 2026-09-13 07:59 | L4: 2026-09-13 09:54 | M4: 2026-09-13 11:59
A5: 400051 | B5: =IFERROR(SUMPRODUCT(('2026-09-11 0845'!$A$2:$A$155="400051")*('2026-09-11 0845'!$D$2:$D$155="In Stock")*('2026-09-11 0845'!$E$2:$E$155<>"No"))/SUMPRODUCT(('2026-09-11 0845'!$A$2:$A$155="400051")*(('2026-09-11 0845'!$D$2:$D$155="In Stock")+('2026-09-11 0845'!$D$2:$D$155="Out of Stock"))*('2026-09-11 0845'!$E$2:$E$155<>"No")),"") | C5: =IFERROR(SUMPRODUCT(('2026-09-11 1032'!$A$2:$A$155="400051")*('2026-09-11 1032'!$D$2:$D$155="In Stock")*('2026-09-11 1032'!$E$2:$E$155<>"No"))/SUMPRODUCT(('2026-09-11 1032'!$A$2:$A$155="400051")*(('2026-09-11 1032'!$D$2:$D$155="In Stock")+('2026-09-11 1032'!$D$2:$D$155="Out of Stock"))*('2026-09-11 1032'!$E$2:$E$155<>"No")),"") | D5: =IFERROR(SUMPRODUCT(('2026-09-11 1201'!$A$2:$A$155="400051")*('2026-09-11 1201'!$D$2:$D$155="In Stock")*('2026-09-11 1201'!$E$2:$E$155<>"No"))/SUMPRODUCT(('2026-09-11 1201'!$A$2:$A$155="400051")*(('2026-09-11 1201'!$D$2:$D$155="In Stock")+('2026-09-11 1201'!$D$2:$D$155="Out of Stock"))*('2026-09-11 1201'!$E$2:$E$155<>"No")),"") | E5: =IFERROR(SUMPRODUCT(('2026-09-11 1253'!$A$2:$A$155="400051")*('2026-09-11 1253'!$D$2:$D$155="In Stock")*('2026-09-11 1253'!$E$2:$E$155<>"No"))/SUMPRODUCT(('2026-09-11 1253'!$A$2:$A$155="400051")*(('2026-09-11 1253'!$D$2:$D$155="In Stock")+('2026-09-11 1253'!$D$2:$D$155="Out of Stock"))*('2026-09-11 1253'!$E$2:$E$155<>"No")),"") | F5: =IFERROR(SUMPRODUCT(('2026-09-12 1330'!$A$2:$A$155="400051")*('2026-09-12 1330'!$D$2:$D$155="In Stock")*('2026-09-12 1330'!$E$2:$E$155<>"No"))/SUMPRODUCT(('2026-09-12 1330'!$A$2:$A$155="400051")*(('2026-09-12 1330'!$D$2:$D$155="In Stock")+('2026-09-12 1330'!$D$2:$D$155="Out of Stock"))*('2026-09-12 1330'!$E$2:$E$155<>"No")),"") | G5: =IFERROR(SUMPRODUCT(('2026-09-12 2141'!$A$2:$A$155="400051")*('2026-09-12 2141'!$D$2:$D$155="In Stock")*('2026-09-12 2141'!$E$2:$E$155<>"No"))/SUMPRODUCT(('2026-09-12 2141'!$A$2:$A$155="400051")*(('2026-09-12 2141'!$D$2:$D$155="In Stock")+('2026-09-12 2141'!$D$2:$D$155="Out of Stock"))*('2026-09-12 2141'!$E$2:$E$155<>"No")),"") | H5: =IFERROR(SUMPRODUCT(('2026-09-12 2158'!$A$2:$A$155="400051")*('2026-09-12 2158'!$D$2:$D$155="In Stock")*('2026-09-12 2158'!$E$2:$E$155<>"No"))/SUMPRODUCT(('2026-09-12 2158'!$A$2:$A$155="400051")*(('2026-09-12 2158'!$D$2:$D$155="In Stock")+('2026-09-12 2158'!$D$2:$D$155="Out of Stock"))*('2026-09-12 2158'!$E$2:$E$155<>"No")),"") | I5: =IFERROR(SUMPRODUCT(('2026-09-13 0625'!$A$2:$A$155="400051")*('2026-09-13 0625'!$D$2:$D$155="In Stock")*('2026-09-13 0625'!$E$2:$E$155<>"No"))/SUMPRODUCT(('2026-09-13 0625'!$A$2:$A$155="400051")*(('2026-09-13 0625'!$D$2:$D$155="In Stock")+('2026-09-13 0625'!$D$2:$D$155="Out of Stock"))*('2026-09-13 0625'!$E$2:$E$155<>"No")),"") | J5: =IFERROR(SUMPRODUCT(('2026-09-13 0640'!$A$2:$A$155="400051")*('2026-09-13 0640'!$D$2:$D$155="In Stock")*('2026-09-13 0640'!$E$2:$E$155<>"No"))/SUMPRODUCT(('2026-09-13 0640'!$A$2:$A$155="400051")*(('2026-09-13 0640'!$D$2:$D$155="In Stock")+('2026-09-13 0640'!$D$2:$D$155="Out of Stock"))*('2026-09-13 0640'!$E$2:$E$155<>"No")),"") | K5: =IFERROR(SUMPRODUCT(('2026-09-13 0759'!$A$2:$A$155="400051")*('2026-09-13 0759'!$D$2:$D$155="In Stock")*('2026-09-13 0759'!$E$2:$E$155<>"No"))/SUMPRODUCT(('2026-09-13 0759'!$A$2:$A$155="400051")*(('2026-09-13 0759'!$D$2:$D$155="In Stock")+('2026-09-13 0759'!$D$2:$D$155="Out of Stock"))*('2026-09-13 0759'!$E$2:$E$155<>"No")),"") | L5: =IFERROR(SUMPRODUCT(('2026-09-13 0954'!$A$2:$A$155="400051")*('2026-09-13 0954'!$D$2:$D$155="In Stock")*('2026-09-13 0954'!$E$2:$E$155<>"No"))/SUMPRODUCT(('2026-09-13 0954'!$A$2:$A$155="400051")*(('2026-09-13 0954'!$D$2:$D$155="In Stock")+('2026-09-13 0954'!$D$2:$D$155="Out of Stock"))*('2026-09-13 0954'!$E$2:$E$155<>"No")),"") | M5: =IFERROR(SUMPRODUCT(('2026-09-13 1159'!$A$2:$A$155="400051")*('2026-09-13 1159'!$D$2:$D$155="In Stock")*('2026-09-13 1159'!$E$2:$E$155<>"No"))/SUMPRODUCT(('2026-09-13 1159'!$A$2:$A$155="400051")*(('2026-09-13 1159'!$D$2:$D$155="In Stock")+('2026-09-13 1159'!$D$2:$D$155="Out of Stock"))*('2026-09-13 1159'!$E$2:$E$155<>"No")),"")
A6: All pincodes | B6: =IFERROR(SUMPRODUCT(('2026-09-11 0845'!$D$2:$D$155="In Stock")*('2026-09-11 0845'!$E$2:$E$155<>"No"))/SUMPRODUCT((('2026-09-11 0845'!$D$2:$D$155="In Stock")+('2026-09-11 0845'!$D$2:$D$155="Out of Stock"))*('2026-09-11 0845'!$E$2:$E$155<>"No")),"") | C6: =IFERROR(SUMPRODUCT(('2026-09-11 1032'!$D$2:$D$155="In Stock")*('2026-09-11 1032'!$E$2:$E$155<>"No"))/SUMPRODUCT((('2026-09-11 1032'!$D$2:$D$155="In Stock")+('2026-09-11 1032'!$D$2:$D$155="Out of Stock"))*('2026-09-11 1032'!$E$2:$E$155<>"No")),"") | D6: =IFERROR(SUMPRODUCT(('2026-09-11 1201'!$D$2:$D$155="In Stock")*('2026-09-11 1201'!$E$2:$E$155<>"No"))/SUMPRODUCT((('2026-09-11 1201'!$D$2:$D$155="In Stock")+('2026-09-11 1201'!$D$2:$D$155="Out of Stock"))*('2026-09-11 1201'!$E$2:$E$155<>"No")),"") | E6: =IFERROR(SUMPRODUCT(('2026-09-11 1253'!$D$2:$D$155="In Stock")*('2026-09-11 1253'!$E$2:$E$155<>"No"))/SUMPRODUCT((('2026-09-11 1253'!$D$2:$D$155="In Stock")+('2026-09-11 1253'!$D$2:$D$155="Out of Stock"))*('2026-09-11 1253'!$E$2:$E$155<>"No")),"") | F6: =IFERROR(SUMPRODUCT(('2026-09-12 1330'!$D$2:$D$155="In Stock")*('2026-09-12 1330'!$E$2:$E$155<>"No"))/SUMPRODUCT((('2026-09-12 1330'!$D$2:$D$155="In Stock")+('2026-09-12 1330'!$D$2:$D$155="Out of Stock"))*('2026-09-12 1330'!$E$2:$E$155<>"No")),"") | G6: =IFERROR(SUMPRODUCT(('2026-09-12 2141'!$D$2:$D$155="In Stock")*('2026-09-12 2141'!$E$2:$E$155<>"No"))/SUMPRODUCT((('2026-09-12 2141'!$D$2:$D$155="In Stock")+('2026-09-12 2141'!$D$2:$D$155="Out of Stock"))*('2026-09-12 2141'!$E$2:$E$155<>"No")),"") | H6: =IFERROR(SUMPRODUCT(('2026-09-12 2158'!$D$2:$D$155="In Stock")*('2026-09-12 2158'!$E$2:$E$155<>"No"))/SUMPRODUCT((('2026-09-12 2158'!$D$2:$D$155="In Stock")+('2026-09-12 2158'!$D$2:$D$155="Out of Stock"))*('2026-09-12 2158'!$E$2:$E$155<>"No")),"") | I6: =IFERROR(SUMPRODUCT(('2026-09-13 0625'!$D$2:$D$155="In Stock")*('2026-09-13 0625'!$E$2:$E$155<>"No"))/SUMPRODUCT((('2026-09-13 0625'!$D$2:$D$155="In Stock")+('2026-09-13 0625'!$D$2:$D$155="Out of Stock"))*('2026-09-13 0625'!$E$2:$E$155<>"No")),"") | J6: =IFERROR(SUMPRODUCT(('2026-09-13 0640'!$D$2:$D$155="In Stock")*('2026-09-13 0640'!$E$2:$E$155<>"No"))/SUMPRODUCT((('2026-09-13 0640'!$D$2:$D$155="In Stock")+('2026-09-13 0640'!$D$2:$D$155="Out of Stock"))*('2026-09-13 0640'!$E$2:$E$155<>"No")),"") | K6: =IFERROR(SUMPRODUCT(('2026-09-13 0759'!$D$2:$D$155="In Stock")*('2026-09-13 0759'!$E$2:$E$155<>"No"))/SUMPRODUCT((('2026-09-13 0759'!$D$2:$D$155="In Stock")+('2026-09-13 0759'!$D$2:$D$155="Out of Stock"))*('2026-09-13 0759'!$E$2:$E$155<>"No")),"") | L6: =IFERROR(SUMPRODUCT(('2026-09-13 0954'!$D$2:$D$155="In Stock")*('2026-09-13 0954'!$E$2:$E$155<>"No"))/SUMPRODUCT((('2026-09-13 0954'!$D$2:$D$155="In Stock")+('2026-09-13 0954'!$D$2:$D$155="Out of Stock"))*('2026-09-13 0954'!$E$2:$E$155<>"No")),"") | M6: =IFERROR(SUMPRODUCT(('2026-09-13 1159'!$D$2:$D$155="In Stock")*('2026-09-13 1159'!$E$2:$E$155<>"No"))/SUMPRODUCT((('2026-09-13 1159'!$D$2:$D$155="In Stock")+('2026-09-13 1159'!$D$2:$D$155="Out of Stock"))*('2026-09-13 1159'!$E$2:$E$155<>"No")),"")
A7: Not carried (excluded from the % above)
A8: Pincode | B8: 2026-09-11 08:45 | C8: 2026-09-11 10:32 | D8: 2026-09-11 12:01 | E8: 2026-09-11 12:53 | F8: 2026-09-12 13:30 | G8: 2026-09-12 21:41 | H8: 2026-09-12 21:58 | I8: 2026-09-13 06:25 | J8: 2026-09-13 06:40 | K8: 2026-09-13 07:59 | L8: 2026-09-13 09:54 | M8: 2026-09-13 11:59
A9: 400051 | B9: =IF(SUMPRODUCT(--('2026-09-11 0845'!$A$2:$A$155="400051"))=0,"",SUMPRODUCT(('2026-09-11 0845'!$A$2:$A$155="400051")*('2026-09-11 0845'!$D$2:$D$155="Not Available")*('2026-09-11 0845'!$E$2:$E$155<>"No"))) | C9: =IF(SUMPRODUCT(--('2026-09-11 1032'!$A$2:$A$155="400051"))=0,"",SUMPRODUCT(('2026-09-11 1032'!$A$2:$A$155="400051")*('2026-09-11 1032'!$D$2:$D$155="Not Available")*('2026-09-11 1032'!$E$2:$E$155<>"No"))) | D9: =IF(SUMPRODUCT(--('2026-09-11 1201'!$A$2:$A$155="400051"))=0,"",SUMPRODUCT(('2026-09-11 1201'!$A$2:$A$155="400051")*('2026-09-11 1201'!$D$2:$D$155="Not Available")*('2026-09-11 1201'!$E$2:$E$155<>"No"))) | E9: =IF(SUMPRODUCT(--('2026-09-11 1253'!$A$2:$A$155="400051"))=0,"",SUMPRODUCT(('2026-09-11 1253'!$A$2:$A$155="400051")*('2026-09-11 1253'!$D$2:$D$155="Not Available")*('2026-09-11 1253'!$E$2:$E$155<>"No"))) | F9: =IF(SUMPRODUCT(--('2026-09-12 1330'!$A$2:$A$155="400051"))=0,"",SUMPRODUCT(('2026-09-12 1330'!$A$2:$A$155="400051")*('2026-09-12 1330'!$D$2:$D$155="Not Available")*('2026-09-12 1330'!$E$2:$E$155<>"No"))) | G9: =IF(SUMPRODUCT(--('2026-09-12 2141'!$A$2:$A$155="400051"))=0,"",SUMPRODUCT(('2026-09-12 2141'!$A$2:$A$155="400051")*('2026-09-12 2141'!$D$2:$D$155="Not Available")*('2026-09-12 2141'!$E$2:$E$155<>"No"))) | H9: =IF(SUMPRODUCT(--('2026-09-12 2158'!$A$2:$A$155="400051"))=0,"",SUMPRODUCT(('2026-09-12 2158'!$A$2:$A$155="400051")*('2026-09-12 2158'!$D$2:$D$155="Not Available")*('2026-09-12 2158'!$E$2:$E$155<>"No"))) | I9: =IF(SUMPRODUCT(--('2026-09-13 0625'!$A$2:$A$155="400051"))=0,"",SUMPRODUCT(('2026-09-13 0625'!$A$2:$A$155="400051")*('2026-09-13 0625'!$D$2:$D$155="Not Available")*('2026-09-13 0625'!$E$2:$E$155<>"No"))) | J9: =IF(SUMPRODUCT(--('2026-09-13 0640'!$A$2:$A$155="400051"))=0,"",SUMPRODUCT(('2026-09-13 0640'!$A$2:$A$155="400051")*('2026-09-13 0640'!$D$2:$D$155="Not Available")*('2026-09-13 0640'!$E$2:$E$155<>"No"))) | K9: =IF(SUMPRODUCT(--('2026-09-13 0759'!$A$2:$A$155="400051"))=0,"",SUMPRODUCT(('2026-09-13 0759'!$A$2:$A$155="400051")*('2026-09-13 0759'!$D$2:$D$155="Not Available")*('2026-09-13 0759'!$E$2:$E$155<>"No"))) | L9: =IF(SUMPRODUCT(--('2026-09-13 0954'!$A$2:$A$155="400051"))=0,"",SUMPRODUCT(('2026-09-13 0954'!$A$2:$A$155="400051")*('2026-09-13 0954'!$D$2:$D$155="Not Available")*('2026-09-13 0954'!$E$2:$E$155<>"No"))) | M9: =IF(SUMPRODUCT(--('2026-09-13 1159'!$A$2:$A$155="400051"))=0,"",SUMPRODUCT(('2026-09-13 1159'!$A$2:$A$155="400051")*('2026-09-13 1159'!$D$2:$D$155="Not Available")*('2026-09-13 1159'!$E$2:$E$155<>"No")))
A10: All pincodes | B10: =SUMPRODUCT(('2026-09-11 0845'!$D$2:$D$155="Not Available")*('2026-09-11 0845'!$E$2:$E$155<>"No")) | C10: =SUMPRODUCT(('2026-09-11 1032'!$D$2:$D$155="Not Available")*('2026-09-11 1032'!$E$2:$E$155<>"No")) | D10: =SUMPRODUCT(('2026-09-11 1201'!$D$2:$D$155="Not Available")*('2026-09-11 1201'!$E$2:$E$155<>"No")) | E10: =SUMPRODUCT(('2026-09-11 1253'!$D$2:$D$155="Not Available")*('2026-09-11 1253'!$E$2:$E$155<>"No")) | F10: =SUMPRODUCT(('2026-09-12 1330'!$D$2:$D$155="Not Available")*('2026-09-12 1330'!$E$2:$E$155<>"No")) | G10: =SUMPRODUCT(('2026-09-12 2141'!$D$2:$D$155="Not Available")*('2026-09-12 2141'!$E$2:$E$155<>"No")) | H10: =SUMPRODUCT(('2026-09-12 2158'!$D$2:$D$155="Not Available")*('2026-09-12 2158'!$E$2:$E$155<>"No")) | I10: =SUMPRODUCT(('2026-09-13 0625'!$D$2:$D$155="Not Available")*('2026-09-13 0625'!$E$2:$E$155<>"No")) | J10: =SUMPRODUCT(('2026-09-13 0640'!$D$2:$D$155="Not Available")*('2026-09-13 0640'!$E$2:$E$155<>"No")) | K10: =SUMPRODUCT(('2026-09-13 0759'!$D$2:$D$155="Not Available")*('2026-09-13 0759'!$E$2:$E$155<>"No")) | L10: =SUMPRODUCT(('2026-09-13 0954'!$D$2:$D$155="Not Available")*('2026-09-13 0954'!$E$2:$E$155<>"No")) | M10: =SUMPRODUCT(('2026-09-13 1159'!$D$2:$D$155="Not Available")*('2026-09-13 1159'!$E$2:$E$155<>"No"))

Sheet 2026-09-11 0845
A1: Pincode | B1: Item | C1: ProductName | D1: is_out_of_stock | E1: Serviceable | F1: Quantity | G1: Base_Final quantity | H1: Base_Final unit | I1: Segment | J1: Grocery | K1: National / PL | L1: Product_Link | M1: Backup_Links | N1: Price | O1: MRP | P1: Weight | Q1: Seller | R1: ASIN | S1: StoreId | T1: Final_Qty | U1: Final_unit | V1: Pincode_Used | W1: Used_Link | X1: Captured_At
A2: 400051 | B2: Aashirvaad Select | Pure MP Sharbati Wheat Atta for Soft Makhmali Rotis | C2: Aashirvaad Select 100% MP Sharbati Atta | D2: In Stock | F2: 5 kg | G2: 5000 | H2: g | I2: Atta, Rice & Dal | J2: Atta | L2: https://www.amazon.in/dp/B00HUJQIZK | N2: 307 | O2: 384 | P2: 5 kg | Q2: Amazon Retail QCom | R2: B00HUJQIZK | S2: 15n9g3 | T2: 5000 | U2: g | V2: 400051 | W2: https://www.amazon.in/dp/B00HUJQIZK | X2: 2026-09-11 08:45:52
A3: 400051 | B3: Fortune Chakki Fresh Atta | F3: 5 kg | G3: 5000 | H3: g | I3: Atta, Rice & Dal | J3: Atta | L3: https://www.amazon.in/dp/B0H5BRQFFJ
A4: 400051 | B4: Fortune 100% Chana Dal Besan | C4: Fortune 100% Chana Dal Besan | D4: In Stock | F4: 1 kg | G4: 1000 | H4: g | I4: Atta, Rice & Dal | J4: Besan, Sooji & Maida | L4: https://www.amazon.in/dp/B015MJI4BU | N4: 118 | O4: 169 | P4: 1 kg | Q4: Amazon Retail QCom | R4: B015MJI4BU | S4: 15n9g3 | T4: 1000 | U4: g | V4: 400051 | W4: https://www.amazon.in/dp/B015MJI4BU | X4: 2026-09-11 08:45:52
A5: 400051 | B5: Rajdhani Sooji/Rava | F5: 1 kg | G5: 1000 | H5: g | I5: Atta, Rice & Dal | J5: Besan, Sooji & Maida | L5: https://www.amazon.in/dp/B00MOFO276
A6: 400051 | B6: Tata Sampann Unpolished Masoor Dal | C6: Tata Sampann Masoor Dal (Whole) | D6: In Stock | F6: 500 g | G6: 500 | H6: g | I6: Atta, Rice & Dal | J6: Moong & Masoor | L6: https://www.amazon.in/dp/B0752S522G | N6: 72 | O6: 79 | P6: 500 g | Q6: Amazon Retail QCom | R6: B0752S522G | S6: 15n9g3 | T6: 500 | U6: g | V6: 400051 | W6: https://www.amazon.in/dp/B0752S522G | X6: 2026-09-11 08:45:52
A7: 400051 | B7: Tata Sampann Unpolished Organic Moong Sabut | C7: Tata Sampann Green Moong Dal (Whole) | D7: In Stock | F7: 1 kg | G7: 1000 | H7: g | I7: Atta, Rice & Dal | J7: Moong & Masoor | L7: https://www.amazon.in/dp/B077X8MD39 | N7: 82 | O7: 93 | P7: 500 g | Q7: Amazon Retail QCom | R7: B077X8MD39 | S7: 15n9g3 | T7: 500 | U7: g | V7: 400051 | W7: https://www.amazon.in/dp/B077X8MD39 | X7: 2026-09-11 08:45:52
A8: 400051 | B8: Nutrela Soya Mini Chunks | C8: Nutrela Soya Mini Chunks | D8: In Stock | F8: 200 g | G8: 200 | H8: g | I8: Atta, Rice & Dal | J8: Rajma, Chhole & Others | L8: https://www.amazon.in/dp/B013SAX1NG | N8: 50 | O8: 55 | P8: 200 g | Q8: Amazon Retail QCom | R8: B013SAX1NG | S8: 15n9g3 | T8: 200 | U8: g | V8: 400051 | W8: https://www.amazon.in/dp/B013SAX1NG | X8: 2026-09-11 08:45:52
A9: 400051 | B9: Tata Sampann Unpolished Kabuli Chana (Big Size) | C9: Tata Sampann Kabuli Chana (Big Size) | D9: In Stock | F9: 500 g | G9: 500 | H9: g | I9: Atta, Rice & Dal | J9: Rajma, Chhole & Others | L9: https://www.amazon.in/dp/B07DCPTP6R | N9: 89 | O9: 104 | P9: 500 g | Q9: Amazon Retail QCom | R9: B07DCPTP6R | S9: 15n9g3 | T9: 500 | U9: g | V9: 400051 | W9: https://www.amazon.in/dp/B07DCPTP6R | X9: 2026-09-11 08:45:52
A10: 400051 | B10: Tata Sampann Unpolished Rajma | C10: Tata Sampann Rajma (Chitra) | D10: In Stock | F10: 500 g | G10: 500 | H10: g | I10: Atta, Rice & Dal | J10: Rajma, Chhole & Others | L10: https://www.amazon.in/dp/B077X8CS14 | N10: 93 | O10: 108 | P10: 500 g | Q10: Amazon Retail QCom | R10: B077X8CS14 | S10: 15n9g3 | T10: 500 | U10: g | V10: 400051 | W10: https://www.amazon.in/dp/B077X8CS14 | X10: 2026-09-11 08:45:52
A11: 400051 | B11: Daawat Super Basmati Rice (Long Grain) | C11: Daawat Super Basmati Rice | D11: In Stock | F11: 5 kg | G11: 5000 | H11: g | I11: Atta, Rice & Dal | J11: Rice | L11: https://www.amazon.in/dp/B00SWKBO0K | N11: 820 | O11: 995 | P11: 5 kg | Q11: Amazon Retail QCom | R11: B00SWKBO0K | S11: 15n9g3 | T11: 5000 | U11: g | V11: 400051 | W11: https://www.amazon.in/dp/B00SWKBO0K | X11: 2026-09-11 08:45:52
A12: 400051 | B12: India Gate Daily Premium Basmati Rice (Long Grain) | C12: India Gate Everyday Dubar Pure Basmati Rice | D12: In Stock | F12: 5 kg | G12: 5000 | H12: g | I12: Atta, Rice & Dal | J12: Rice | L12: https://www.amazon.in/dp/B0BBF1FT93 | N12: 379 | O12: 515 | P12: 5 kg | Q12: Amazon Retail QCom | R12: B0BBF1FT93 | S12: 15n9g3 | T12: 5000 | U12: g | V12: 400051 | W12: https://www.amazon.in/dp/B0BBF1FT93 | X12: 2026-09-11 08:45:52
A13: 400051 | B13: Tata Sampann Unpolished Chana Dal | C13: Tata Sampann Chana Dal (Split) | D13: In Stock | F13: 500 g | G13: 500 | H13: g | I13: Atta, Rice & Dal | J13: Toor, Urad & Chana | L13: https://www.amazon.in/dp/B077X8G5DK | N13: 61 | O13: 81 | P13: 500 g | Q13: Amazon Retail QCom | R13: B077X8G5DK | S13: 15n9g3 | T13: 500 | U13: g | V13: 400051 | W13: https://www.amazon.in/dp/B077X8G5DK | X13: 2026-09-11 08:45:52
A14: 400051 | B14: Tata Sampann Unpolished Toor Dal | C14: Vedaka Toor Dal (Split) | D14: In Stock | F14: 2 kg | G14: 2000 | H14: g | I14: Atta, Rice & Dal | J14: Toor, Urad & Chana | L14: https://www.amazon.in/dp/B0BSWQXJDL | N14: 306 | O14: 575 | P14: 2 kg | Q14: Amazon Retail QCom | R14: B0BSWQXJDL | S14: 15n9g3 | T14: 2000 | U14: g | V14: 400051 | W14: https://www.amazon.in/dp/B0BSWQXJDL | X14: 2026-09-11 08:45:52
A15: 400051 | B15: Nestle Cerelac Wheat Apple Baby Cereal (6 - 24 Months) | C15: Cerelac Baby Cereal with Milk | D15: In Stock | F15: 350 g | G15: 350 | H15: g | I15: Baby Care | J15: Baby Food | L15: https://www.amazon.in/dp/B00I4SYXIK | N15: 280 | P15: 350 g | Q15: Amazon Retail QCom | R15: B00I4SYXIK | S15: 15n9g3 | T15: 350 | U15: g | V15: 400051 | W15: https://www.amazon.in/dp/B00I4SYXIK | X15: 2026-09-11 08:45:52
A16: 400051 | B16: Himalaya Gentle Baby Wipes | F16: 2 x 72 wipes | G16: 144 | H16: pcs | I16: Baby Care | J16: Baby Wipes | L16: https://www.amazon.in/dp/B0GYPN214D
A17: 400051 | B17: Johnson's Baby Soap | F17: 3 pcs | G17: 3 | H17: pcs | I17: Baby Care | J17: Bathing Needs | L17: https://www.amazon.in/dp/B06XY98VPT
A18: 400051 | B18: Pampers Happy Sleep Pant Style Baby Diaper (M) | C18: Pampers Happy Sleep Pant Style Baby Diapers - M | D18: In Stock | F18: 48 pcs | G18: 48 | H18: pcs | I18: Baby Care | J18: Diapers & More | L18: https://www.amazon.in/dp/B0DSGHM8JW | N18: 476 | O18: 609 | P18: M, 48 Pcs | Q18: RK World Infocom Pvt Ltd QCom | R18: B0DSGHM8JW | S18: 15n9g3 | V18: 400051 | W18: https://www.amazon.in/dp/B0DSGHM8JW | X18: 2026-09-11 08:45:52
A19: 400051 | B19: Johnson's Baby Lotion | C19: Johnson's Baby Lotion | D19: In Stock | F19: 200 ml | G19: 200 | H19: ml | I19: Baby Care | J19: Skin & Hair Care | L19: https://www.amazon.in/dp/B07FHHCR44 | N19: 192 | O19: 220 | P19: 200 ml | Q19: RK World Infocom Pvt Ltd QCom | R19: B07FHHCR44 | S19: 15n9g3 | T19: 200 | U19: ml | V19: 400051 | W19: https://www.amazon.in/dp/B07FHHCR44 | X19: 2026-09-11 08:45:52
A20: 400051 | B20: Weikfield Double Action Baking Powder | F20: 100 g | G20: 100 | H20: g | I20: Bakery & Biscuits | J20: Baking Ingredients | L20: https://www.amazon.in/dp/B004KFHIBK
A21: 400051 | B21: Lotte Choco Pie | F21: 168 g | G21: 168 | H21: g | I21: Bakery & Biscuits | J21: Cakes & Rolls | L21: https://www.amazon.in/dp/B019RL0C4Q
A22: 400051 | B22: Britannia Original Bourbon Creme Biscuit | C22: Cadbury Bournvita Biscuits | D22: In Stock | F22: 150 g | G22: 150 | H22: g | I22: Bakery & Biscuits | J22: Cookies | L22: https://www.amazon.in/dp/B07FR2GVVK | N22: 29 | O22: 30 | P22: 111.6 g | Q22: Amazon Retail QCom | R22: B07FR2GVVK | S22: 15n9g3 | T22: 111.6 | U22: g | V22: 400051 | W22: https://www.amazon.in/dp/B07FR2GVVK | X22: 2026-09-11 08:45:54
A23: 400051 | B23: Britannia Good Day Cashew Biscuit | C23: Britannia Good Day Cashew Cookies | D23: In Stock | F23: 200 g | G23: 200 | H23: g | I23: Bakery & Biscuits | J23: Cookies | L23: https://www.amazon.in/dp/B01M1RKTRK | N23: 82 | O23: 130 | P23: 526 g | Q23: Amazon Retail QCom | R23: B01M1RKTRK | S23: 15n9g3 | T23: 526 | U23: g | V23: 400051 | W23: https://www.amazon.in/dp/B01M1RKTRK | X23: 2026-09-11 08:45:54
A24: 400051 | B24: Malkist Cheese Flavoured Cracker Biscuit - Family Pack | F24: 144 g | G24: 144 | H24: g | I24: Bakery & Biscuits | J24: Cream Biscuits | L24: https://www.amazon.in/dp/B0F2G8Q5SX
A25: 400051 | B25: Britannia Marie Gold Marie Biscuits (208 g) | C25: Britannia Marie Gold Biscuits | D25: In Stock | F25: 208 g | G25: 208 | H25: g | I25: Bakery & Biscuits | J25: Glucose & Marie | L25: https://www.amazon.in/dp/B00S9BSEB4 | N25: 40 | P25: 250 g | Q25: Amazon Retail QCom | R25: B00S9BSEB4 | S25: 15n9g3 | T25: 250 | U25: g | V25: 400051 | W25: https://www.amazon.in/dp/B00S9BSEB4 | X25: 2026-09-11 08:45:54
A26: 400051 | B26: Britannia NutriChoice Digestive High Fibre Biscuit - 250 g Family Pack | C26: Britannia Nutrichoice 5 Grain Digestive Biscuits | D26: In Stock | F26: 250 g | G26: 250 | H26: g | I26: Bakery & Biscuits | J26: Healthy & Digestive | L26: https://www.amazon.in/dp/B00RGE4OUA | N26: 54 | O26: 65 | P26: 200 g | Q26: Amazon Retail QCom | R26: B00RGE4OUA | S26: 15n9g3 | T26: 200 | U26: g | V26: 400051 | W26: https://www.amazon.in/dp/B00RGE4OUA | X26: 2026-09-11 08:45:54
A27: 400051 | B27: McVitie's Digestive High Fibre Biscuit | F27: 959.1 g | G27: 959.1 | H27: g | I27: Bakery & Biscuits | J27: Healthy & Digestive | L27: https://www.amazon.in/dp/B0H5QXXHLP
A28: 400051 | B28: Nivea Nourishing Body Lotion | F28: 600 ml | G28: 600 | H28: ml | I28: Beauty & Cosmetics | J28: Body & Skin Care | L28: https://www.amazon.in/dp/B099NNW9LL
A29: 400051 | B29: Maybelline New York Colossal Kajal (Deep Black) | C29: Maybelline The Colossal Kajal | D29: In Stock | F29: 0.35 g | G29: 0.35 | H29: g | I29: Beauty & Cosmetics | J29: Eye Makeup | L29: https://www.amazon.in/dp/B06WGZP21B | N29: 181 | O29: 220 | P29: 0.35 g | Q29: RK World Infocom Pvt Ltd QCom | R29: B06WGZP21B | S29: 15n9g3 | T29: 0.35 | U29: g | V29: 400051 | W29: https://www.amazon.in/dp/B06WGZP21B | X29: 2026-09-11 08:45:54
A30: 400051 | B30: Pond's Bright Beauty Serum Skin Treatment Cream 34 g | F30: 35 g | G30: 35 | H30: g | I30: Beauty & Cosmetics | J30: Face Care | L30: https://www.amazon.in/dp/B077ND8562
A31: 400051 | B31: Lakme Forever Matte Compact (Pearl) | C31: Lakme Forever Matte Compact | D31: In Stock | F31: 9 g | G31: 9 | H31: g | I31: Beauty & Cosmetics | J31: Face Cosmetics | L31: https://www.amazon.in/dp/B09C3Q2YFX | N31: 172 | O31: 245 | P31: 9 g | Q31: RK World Infocom Pvt Ltd QCom | R31: B09C3Q2YFX | S31: 15n9g3 | T31: 9 | U31: g | V31: 400051 | W31: https://www.amazon.in/dp/B09C3Q2YFX | X31: 2026-09-11 08:45:54
A32: 400051 | B32: Livon Anti-Frizz Hair Serum | C32: Livon Go Frizz Free Anti-Frizz Serum | D32: In Stock | F32: 50 ml | G32: 50 | H32: ml | I32: Beauty & Cosmetics | J32: Hair Styling & Treatment | L32: https://www.amazon.in/dp/B00CBRIKIE | N32: 139 | O32: 180 | P32: 50 ml | Q32: RK World Infocom Pvt Ltd QCom | R32: B00CBRIKIE | S32: 15n9g3 | T32: 50 | U32: ml | V32: 400051 | W32: https://www.amazon.in/dp/B00CBRIKIE | X32: 2026-09-11 08:45:54
A33: 400051 | B33: Nivea Essential Care Lip Balm | C33: Nivea Original Care Lip Balm | D33: In Stock | F33: 4.8 g | G33: 4.8 | H33: g | I33: Beauty & Cosmetics | J33: Lip & Eye Care | L33: https://www.amazon.in/dp/B007E9JC7W | N33: 137 | O33: 175 | P33: 4.8 g | Q33: RK World Infocom Pvt Ltd QCom | R33: B007E9JC7W | S33: 15n9g3 | T33: 4.8 | U33: g | V33: 400051 | W33: https://www.amazon.in/dp/B007E9JC7W | X33: 2026-09-11 08:45:54
A34: 400051 | B34: Lakme 9To5 Hya Matte Lipstick (Workday Rose) | F34: 3.6 g | G34: 3.6 | H34: g | I34: Beauty & Cosmetics | J34: Lip Cosmetics | L34: https://www.amazon.in/dp/B0DWH87545
A35: 400051 | B35: Lakme Nail Paint Remover | C35: Lakme Nail Enamel Remover | D35: In Stock | F35: 27 ml | G35: 27 | H35: ml | I35: Beauty & Cosmetics | J35: Nail Cosmetics | L35: https://www.amazon.in/dp/B006LXBF0E | N35: 99 | O35: 110 | P35: 27 ml | Q35: RK World Infocom Pvt Ltd QCom | R35: B006LXBF0E | S35: 15n9g3 | T35: 27 | U35: ml | V35: 400051 | W35: https://www.amazon.in/dp/B006LXBF0E | X35: 2026-09-11 08:45:54
A36: 400051 | B36: Licious Chicken Curry Cut (Small Pieces) | F36: 450 g | G36: 450 | H36: g | I36: Chicken, Meat & Fish | J36: Fresh Meat | L36: https://www.amazon.in/dp/B0BTYJ58W1
A37: 400051 | B37: Surf Excel Easy Wash Detergent Powder | C37: Surf Excel Easy Wash Detergent Powder | D37: In Stock | F37: 1 kg | G37: 1000 | H37: g | I37: Cleaning Essentials | J37: Detergent Powder & Bars | L37: https://www.amazon.in/dp/B01ITJ6642 | N37: 80 | O37: 85 | P37: 500 g | Q37: RK World Infocom Pvt Ltd QCom | R37: B01ITJ6642 | S37: 15n9g3 | T37: 500 | U37: g | V37: 400051 | W37: https://www.amazon.in/dp/B01ITJ6642 | X37: 2026-09-11 08:45:54
A38: 400051 | B38: Scotch Brite Scrub Pad | F38: 5 pcs | G38: 5 | H38: pcs | I38: Cleaning Essentials | J38: Dishwashing Accessories | L38: https://www.amazon.in/dp/B07H4YJLP4
A39: 400051 | B39: Vim Lemon Dishwash Bar (300 g) | C39: Vim Dishwash Bar Tub | D39: In Stock | F39: 300 g | G39: 300 | H39: g | I39: Cleaning Essentials | J39: Dishwashing Bars & Tubs | L39: https://www.amazon.in/dp/B00U2DVHD4 | N39: 55 | P39: 500 g | Q39: RK World Infocom Pvt Ltd QCom | R39: B00U2DVHD4 | S39: 15n9g3 | T39: 500 | U39: g | V39: 400051 | W39: https://www.amazon.in/dp/B00U2DVHD4 | X39: 2026-09-11 08:45:54
A40: 400051 | B40: Vim Lemon Dishwash Gel | C40: Vim Dishwash Liquid Gel | D40: In Stock | F40: 750 ml | G40: 750 | H40: ml | I40: Cleaning Essentials | J40: Dishwashing Gels & Tablets | L40: https://www.amazon.in/dp/B00M99II36 | N40: 189 | O40: 199 | P40: 750 ml | Q40: RK World Infocom Pvt Ltd QCom | R40: B00M99II36 | S40: 15n9g3 | T40: 750 | U40: ml | V40: 400051 | W40: https://www.amazon.in/dp/B00M99II36 | X40: 2026-09-11 08:45:54
...

Sheet 2026-09-11 1032
A1: Pincode | B1: Item | C1: ProductName | D1: is_out_of_stock | E1: Serviceable | F1: Segment | G1: Grocery | H1: Product_Link | I1: Price | J1: MRP | K1: Weight | L1: Seller | M1: ASIN | N1: StoreId | O1: Final_Qty | P1: Final_unit | Q1: Pincode_Used | R1: Used_Link | S1: Captured_At
A2: 400051 | B2: Aashirvaad Select | Pure MP Sharbati Wheat Atta for Soft Makhmali Rotis | C2: Aashirvaad Select 100% MP Sharbati Atta | D2: In Stock | E2: Yes | F2: Atta, Rice & Dal | G2: Atta | H2: https://www.amazon.in/dp/B00HUJQIZK | I2: 307 | J2: 384 | K2: 5 kg | L2: Amazon Retail QCom | M2: B00HUJQIZK | N2: 15n9g3 | O2: 5000 | P2: g | Q2: 400051 | R2: https://www.amazon.in/dp/B00HUJQIZK | S2: 2026-09-11 10:33:00
A3: 400051 | B3: Fortune Chakki Fresh Atta | F3: Atta, Rice & Dal | G3: Atta | H3: https://www.amazon.in/dp/B0H5BRQFFJ
A4: 400051 | B4: Fortune 100% Chana Dal Besan | C4: Fortune 100% Chana Dal Besan | D4: In Stock | E4: Yes | F4: Atta, Rice & Dal | G4: Besan, Sooji & Maida | H4: https://www.amazon.in/dp/B015MJI4BU | I4: 118 | J4: 169 | K4: 1 kg | L4: Amazon Retail QCom | M4: B015MJI4BU | N4: 15n9g3 | O4: 1000 | P4: g | Q4: 400051 | R4: https://www.amazon.in/dp/B015MJI4BU | S4: 2026-09-11 10:33:00
A5: 400051 | B5: Rajdhani Sooji/Rava | F5: Atta, Rice & Dal | G5: Besan, Sooji & Maida | H5: https://www.amazon.in/dp/B00MOFO276
A6: 400051 | B6: Tata Sampann Unpolished Masoor Dal | C6: Tata Sampann Masoor Dal (Whole) | D6: In Stock | E6: Yes | F6: Atta, Rice & Dal | G6: Moong & Masoor | H6: https://www.amazon.in/dp/B0752S522G | I6: 72 | J6: 79 | K6: 500 g | L6: Amazon Retail QCom | M6: B0752S522G | N6: 15n9g3 | O6: 500 | P6: g | Q6: 400051 | R6: https://www.amazon.in/dp/B0752S522G | S6: 2026-09-11 10:33:00
A7: 400051 | B7: Tata Sampann Unpolished Organic Moong Sabut | C7: Tata Sampann Green Moong Dal (Whole) | D7: In Stock | E7: Yes | F7: Atta, Rice & Dal | G7: Moong & Masoor | H7: https://www.amazon.in/dp/B077X8MD39 | I7: 82 | J7: 93 | K7: 500 g | L7: Amazon Retail QCom | M7: B077X8MD39 | N7: 15n9g3 | O7: 500 | P7: g | Q7: 400051 | R7: https://www.amazon.in/dp/B077X8MD39 | S7: 2026-09-11 10:33:00
A8: 400051 | B8: Nutrela Soya Mini Chunks | C8: Nutrela Soya Mini Chunks | D8: In Stock | E8: Yes | F8: Atta, Rice & Dal | G8: Rajma, Chhole & Others | H8: https://www.amazon.in/dp/B013SAX1NG | I8: 50 | J8: 55 | K8: 200 g | L8: Amazon Retail QCom | M8: B013SAX1NG | N8: 15n9g3 | O8: 200 | P8: g | Q8: 400051 | R8: https://www.amazon.in/dp/B013SAX1NG | S8: 2026-09-11 10:33:00
A9: 400051 | B9: Tata Sampann Unpolished Kabuli Chana (Big Size) | C9: Tata Sampann Kabuli Chana (Big Size) | D9: In Stock | E9: Yes | F9: Atta, Rice & Dal | G9: Rajma, Chhole & Others | H9: https://www.amazon.in/dp/B07DCPTP6R | I9: 89 | J9: 104 | K9: 500 g | L9: Amazon Retail QCom | M9: B07DCPTP6R | N9: 15n9g3 | O9: 500 | P9: g | Q9: 400051 | R9: https://www.amazon.in/dp/B07DCPTP6R | S9: 2026-09-11 10:33:00
A10: 400051 | B10: Tata Sampann Unpolished Rajma | C10: Tata Sampann Rajma (Chitra) | D10: In Stock | E10: Yes | F10: Atta, Rice & Dal | G10: Rajma, Chhole & Others | H10: https://www.amazon.in/dp/B077X8CS14 | I10: 93 | J10: 108 | K10: 500 g | L10: Amazon Retail QCom | M10: B077X8CS14 | N10: 15n9g3 | O10: 500 | P10: g | Q10: 400051 | R10: https://www.amazon.in/dp/B077X8CS14 | S10: 2026-09-11 10:33:00
A11: 400051 | B11: Daawat Super Basmati Rice (Long Grain) | C11: Daawat Super Basmati Rice | D11: In Stock | E11: Yes | F11: Atta, Rice & Dal | G11: Rice | H11: https://www.amazon.in/dp/B00SWKBO0K | I11: 820 | J11: 995 | K11: 5 kg | L11: Amazon Retail QCom | M11: B00SWKBO0K | N11: 15n9g3 | O11: 5000 | P11: g | Q11: 400051 | R11: https://www.amazon.in/dp/B00SWKBO0K | S11: 2026-09-11 10:33:00
A12: 400051 | B12: India Gate Daily Premium Basmati Rice (Long Grain) | C12: India Gate Everyday Dubar Pure Basmati Rice | D12: In Stock | E12: Yes | F12: Atta, Rice & Dal | G12: Rice | H12: https://www.amazon.in/dp/B0BBF1FT93 | I12: 379 | J12: 515 | K12: 5 kg | L12: Amazon Retail QCom | M12: B0BBF1FT93 | N12: 15n9g3 | O12: 5000 | P12: g | Q12: 400051 | R12: https://www.amazon.in/dp/B0BBF1FT93 | S12: 2026-09-11 10:33:00
A13: 400051 | B13: Tata Sampann Unpolished Chana Dal | C13: Tata Sampann Chana Dal (Split) | D13: In Stock | E13: Yes | F13: Atta, Rice & Dal | G13: Toor, Urad & Chana | H13: https://www.amazon.in/dp/B077X8G5DK | I13: 61 | J13: 81 | K13: 500 g | L13: Amazon Retail QCom | M13: B077X8G5DK | N13: 15n9g3 | O13: 500 | P13: g | Q13: 400051 | R13: https://www.amazon.in/dp/B077X8G5DK | S13: 2026-09-11 10:33:00
A14: 400051 | B14: Tata Sampann Unpolished Toor Dal | C14: Vedaka Toor Dal (Split) | D14: In Stock | E14: Yes | F14: Atta, Rice & Dal | G14: Toor, Urad & Chana | H14: https://www.amazon.in/dp/B0BSWQXJDL | I14: 306 | J14: 575 | K14: 2 kg | L14: Amazon Retail QCom | M14: B0BSWQXJDL | N14: 15n9g3 | O14: 2000 | P14: g | Q14: 400051 | R14: https://www.amazon.in/dp/B0BSWQXJDL | S14: 2026-09-11 10:33:00
A15: 400051 | B15: Nestle Cerelac Wheat Apple Baby Cereal (6 - 24 Months) | C15: Cerelac Baby Cereal with Milk | D15: In Stock | E15: Yes | F15: Baby Care | G15: Baby Food | H15: https://www.amazon.in/dp/B00I4SYXIK | I15: 280 | K15: 350 g | L15: Amazon Retail QCom | M15: B00I4SYXIK | N15: 15n9g3 | O15: 350 | P15: g | Q15: 400051 | R15: https://www.amazon.in/dp/B00I4SYXIK | S15: 2026-09-11 10:33:00
A16: 400051 | B16: Himalaya Gentle Baby Wipes | F16: Baby Care | G16: Baby Wipes | H16: https://www.amazon.in/dp/B0GYPN214D
A17: 400051 | B17: Johnson's Baby Soap | F17: Baby Care | G17: Bathing Needs | H17: https://www.amazon.in/dp/B06XY98VPT
A18: 400051 | B18: Pampers Happy Sleep Pant Style Baby Diaper (M) | C18: Pampers Happy Sleep Pant Style Baby Diapers - M | D18: In Stock | E18: Yes | F18: Baby Care | G18: Diapers & More | H18: https://www.amazon.in/dp/B0DSGHM8JW | I18: 476 | J18: 609 | K18: M, 48 Pcs | L18: RK World Infocom Pvt Ltd QCom | M18: B0DSGHM8JW | N18: 15n9g3 | Q18: 400051 | R18: https://www.amazon.in/dp/B0DSGHM8JW | S18: 2026-09-11 10:33:00
A19: 400051 | B19: Johnson's Baby Lotion | C19: Johnson's Baby Lotion | D19: In Stock | E19: Yes | F19: Baby Care | G19: Skin & Hair Care | H19: https://www.amazon.in/dp/B07FHHCR44 | I19: 192 | J19: 220 | K19: 200 ml | L19: RK World Infocom Pvt Ltd QCom | M19: B07FHHCR44 | N19: 15n9g3 | O19: 200 | P19: ml | Q19: 400051 | R19: https://www.amazon.in/dp/B07FHHCR44 | S19: 2026-09-11 10:33:00
A20: 400051 | B20: Weikfield Double Action Baking Powder | F20: Bakery & Biscuits | G20: Baking Ingredients | H20: https://www.amazon.in/dp/B004KFHIBK
A21: 400051 | B21: Lotte Choco Pie | F21: Bakery & Biscuits | G21: Cakes & Rolls | H21: https://www.amazon.in/dp/B019RL0C4Q
A22: 400051 | B22: Britannia Original Bourbon Creme Biscuit | C22: Cadbury Bournvita Biscuits | D22: In Stock | E22: Yes | F22: Bakery & Biscuits | G22: Cookies | H22: https://www.amazon.in/dp/B07FR2GVVK | I22: 29 | J22: 30 | K22: 111.6 g | L22: Amazon Retail QCom | M22: B07FR2GVVK | N22: 15n9g3 | O22: 111.6 | P22: g | Q22: 400051 | R22: https://www.amazon.in/dp/B07FR2GVVK | S22: 2026-09-11 10:33:02
A23: 400051 | B23: Britannia Good Day Cashew Biscuit | C23: Britannia Good Day Cashew Cookies | D23: In Stock | E23: Yes | F23: Bakery & Biscuits | G23: Cookies | H23: https://www.amazon.in/dp/B01M1RKTRK | I23: 82 | J23: 130 | K23: 526 g | L23: Amazon Retail QCom | M23: B01M1RKTRK | N23: 15n9g3 | O23: 526 | P23: g | Q23: 400051 | R23: https://www.amazon.in/dp/B01M1RKTRK | S23: 2026-09-11 10:33:02
A24: 400051 | B24: Malkist Cheese Flavoured Cracker Biscuit - Family Pack | F24: Bakery & Biscuits | G24: Cream Biscuits | H24: https://www.amazon.in/dp/B0F2G8Q5SX
A25: 400051 | B25: Britannia Marie Gold Marie Biscuits (208 g) | C25: Britannia Marie Gold Biscuits | D25: In Stock | E25: Yes | F25: Bakery & Biscuits | G25: Glucose & Marie | H25: https://www.amazon.in/dp/B00S9BSEB4 | I25: 40 | K25: 250 g | L25: Amazon Retail QCom | M25: B00S9BSEB4 | N25: 15n9g3 | O25: 250 | P25: g | Q25: 400051 | R25: https://www.amazon.in/dp/B00S9BSEB4 | S25: 2026-09-11 10:33:02
A26: 400051 | B26: Britannia NutriChoice Digestive High Fibre Biscuit - 250 g Family Pack | C26: Britannia Nutrichoice 5 Grain Digestive Biscuits | D26: In Stock | E26: Yes | F26: Bakery & Biscuits | G26: Healthy & Digestive | H26: https://www.amazon.in/dp/B00RGE4OUA | I26: 54 | J26: 65 | K26: 200 g | L26: Amazon Retail QCom | M26: B00RGE4OUA | N26: 15n9g3 | O26: 200 | P26: g | Q26: 400051 | R26: https://www.amazon.in/dp/B00RGE4OUA | S26: 2026-09-11 10:33:02
A27: 400051 | B27: McVitie's Digestive High Fibre Biscuit | F27: Bakery & Biscuits | G27: Healthy & Digestive | H27: https://www.amazon.in/dp/B0H5QXXHLP
A28: 400051 | B28: Nivea Nourishing Body Lotion | F28: Beauty & Cosmetics | G28: Body & Skin Care | H28: https://www.amazon.in/dp/B099NNW9LL
A29: 400051 | B29: Maybelline New York Colossal Kajal (Deep Black) | C29: Maybelline The Colossal Kajal | D29: In Stock | E29: Yes | F29: Beauty & Cosmetics | G29: Eye Makeup | H29: https://www.amazon.in/dp/B06WGZP21B | I29: 181 | J29: 220 | K29: 0.35 g | L29: RK World Infocom Pvt Ltd QCom | M29: B06WGZP21B | N29: 15n9g3 | O29: 0.35 | P29: g | Q29: 400051 | R29: https://www.amazon.in/dp/B06WGZP21B | S29: 2026-09-11 10:33:02
A30: 400051 | B30: Pond's Bright Beauty Serum Skin Treatment Cream 34 g | F30: Beauty & Cosmetics | G30: Face Care | H30: https://www.amazon.in/dp/B077ND8562
A31: 400051 | B31: Lakme Forever Matte Compact (Pearl) | C31: Lakme Forever Matte Compact | D31: In Stock | E31: Yes | F31: Beauty & Cosmetics | G31: Face Cosmetics | H31: https://www.amazon.in/dp/B09C3Q2YFX | I31: 172 | J31: 245 | K31: 9 g | L31: RK World Infocom Pvt Ltd QCom | M31: B09C3Q2YFX | N31: 15n9g3 | O31: 9 | P31: g | Q31: 400051 | R31: https://www.amazon.in/dp/B09C3Q2YFX | S31: 2026-09-11 10:33:02
A32: 400051 | B32: Livon Anti-Frizz Hair Serum | C32: Livon Go Frizz Free Anti-Frizz Serum | D32: In Stock | E32: Yes | F32: Beauty & Cosmetics | G32: Hair Styling & Treatment | H32: https://www.amazon.in/dp/B00CBRIKIE | I32: 139 | J32: 180 | K32: 50 ml | L32: RK World Infocom Pvt Ltd QCom | M32: B00CBRIKIE | N32: 15n9g3 | O32: 50 | P32: ml | Q32: 400051 | R32: https://www.amazon.in/dp/B00CBRIKIE | S32: 2026-09-11 10:33:02
A33: 400051 | B33: Nivea Essential Care Lip Balm | C33: Nivea Original Care Lip Balm | D33: In Stock | E33: Yes | F33: Beauty & Cosmetics | G33: Lip & Eye Care | H33: https://www.amazon.in/dp/B007E9JC7W | I33: 137 | J33: 175 | K33: 4.8 g | L33: RK World Infocom Pvt Ltd QCom | M33: B007E9JC7W | N33: 15n9g3 | O33: 4.8 | P33: g | Q33: 400051 | R33: https://www.amazon.in/dp/B007E9JC7W | S33: 2026-09-11 10:33:02
A34: 400051 | B34: Lakme 9To5 Hya Matte Lipstick (Workday Rose) | F34: Beauty & Cosmetics | G34: Lip Cosmetics | H34: https://www.amazon.in/dp/B0DWH87545
A35: 400051 | B35: Lakme Nail Paint Remover | C35: Lakme Nail Enamel Remover | D35: In Stock | E35: Yes | F35: Beauty & Cosmetics | G35: Nail Cosmetics | H35: https://www.amazon.in/dp/B006LXBF0E | I35: 99 | J35: 110 | K35: 27 ml | L35: RK World Infocom Pvt Ltd QCom | M35: B006LXBF0E | N35: 15n9g3 | O35: 27 | P35: ml | Q35: 400051 | R35: https://www.amazon.in/dp/B006LXBF0E | S35: 2026-09-11 10:33:02
A36: 400051 | B36: Licious Chicken Curry Cut (Small Pieces) | F36: Chicken, Meat & Fish | G36: Fresh Meat | H36: https://www.amazon.in/dp/B0BTYJ58W1
A37: 400051 | B37: Surf Excel Easy Wash Detergent Powder | C37: Surf Excel Easy Wash Detergent Powder | D37: In Stock | E37: Yes | F37: Cleaning Essentials | G37: Detergent Powder & Bars | H37: https://www.amazon.in/dp/B01ITJ6642 | I37: 80 | J37: 85 | K37: 500 g | L37: RK World Infocom Pvt Ltd QCom | M37: B01ITJ6642 | N37: 15n9g3 | O37: 500 | P37: g | Q37: 400051 | R37: https://www.amazon.in/dp/B01ITJ6642 | S37: 2026-09-11 10:33:02
A38: 400051 | B38: Scotch Brite Scrub Pad | F38: Cleaning Essentials | G38: Dishwashing Accessories | H38: https://www.amazon.in/dp/B07H4YJLP4
A39: 400051 | B39: Vim Lemon Dishwash Bar (300 g) | C39: Vim Dishwash Bar Tub | D39: In Stock | E39: Yes | F39: Cleaning Essentials | G39: Dishwashing Bars & Tubs | H39: https://www.amazon.in/dp/B00U2DVHD4 | I39: 55 | K39: 500 g | L39: RK World Infocom Pvt Ltd QCom | M39: B00U2DVHD4 | N39: 15n9g3 | O39: 500 | P39: g | Q39: 400051 | R39: https://www.amazon.in/dp/B00U2DVHD4 | S39: 2026-09-11 10:33:02
A40: 400051 | B40: Vim Lemon Dishwash Gel | C40: Vim Dishwash Liquid Gel | D40: In Stock | E40: Yes | F40: Cleaning Essentials | G40: Dishwashing Gels & Tablets | H40: https://www.amazon.in/dp/B00M99II36 | I40: 189 | J40: 199 | K40: 750 ml | L40: RK World Infocom Pvt Ltd QCom | M40: B00M99II36 | N40: 15n9g3 | O40: 750 | P40: ml | Q40: 400051 | R40: https://www.amazon.in/dp/B00M99II36 | S40: 2026-09-11 10:33:02
...

Sheet 2026-09-11 1201
A1: Pincode | B1: Item | C1: ProductName | D1: is_out_of_stock | E1: Serviceable | F1: Segment | G1: Grocery | H1: Product_Link | I1: Price | J1: MRP | K1: Weight | L1: Seller | M1: ASIN | N1: StoreId | O1: Final_Qty | P1: Final_unit | Q1: Pincode_Used | R1: Used_Link | S1: Captured_At
A2: 400051 | B2: Aashirvaad Select | Pure MP Sharbati Wheat Atta for Soft Makhmali Rotis | C2: Aashirvaad Select 100% MP Sharbati Atta | D2: In Stock | E2: Yes | F2: Atta, Rice & Dal | G2: Atta | H2: https://www.amazon.in/dp/B00HUJQIZK | I2: 307 | J2: 384 | K2: 5 kg | L2: Amazon Retail QCom | M2: B00HUJQIZK | N2: 15n9g3 | O2: 5000 | P2: g | Q2: 400051 | R2: https://www.amazon.in/dp/B00HUJQIZK | S2: 2026-09-11 12:01:21
A3: 400051 | B3: Fortune Chakki Fresh Atta | F3: Atta, Rice & Dal | G3: Atta | H3: https://www.amazon.in/dp/B0H5BRQFFJ
A4: 400051 | B4: Fortune 100% Chana Dal Besan | C4: Fortune 100% Chana Dal Besan | D4: In Stock | E4: Yes | F4: Atta, Rice & Dal | G4: Besan, Sooji & Maida | H4: https://www.amazon.in/dp/B015MJI4BU | I4: 118 | J4: 169 | K4: 1 kg | L4: Amazon Retail QCom | M4: B015MJI4BU | N4: 15n9g3 | O4: 1000 | P4: g | Q4: 400051 | R4: https://www.amazon.in/dp/B015MJI4BU | S4: 2026-09-11 12:01:21
A5: 400051 | B5: Rajdhani Sooji/Rava | F5: Atta, Rice & Dal | G5: Besan, Sooji & Maida | H5: https://www.amazon.in/dp/B00MOFO276
A6: 400051 | B6: Tata Sampann Unpolished Masoor Dal | C6: Tata Sampann Masoor Dal (Whole) | D6: In Stock | E6: Yes | F6: Atta, Rice & Dal | G6: Moong & Masoor | H6: https://www.amazon.in/dp/B0752S522G | I6: 72 | J6: 79 | K6: 500 g | L6: Amazon Retail QCom | M6: B0752S522G | N6: 15n9g3 | O6: 500 | P6: g | Q6: 400051 | R6: https://www.amazon.in/dp/B0752S522G | S6: 2026-09-11 12:01:21
A7: 400051 | B7: Tata Sampann Unpolished Organic Moong Sabut | C7: Tata Sampann Green Moong Dal (Whole) | D7: In Stock | E7: Yes | F7: Atta, Rice & Dal | G7: Moong & Masoor | H7: https://www.amazon.in/dp/B077X8MD39 | I7: 82 | J7: 93 | K7: 500 g | L7: Amazon Retail QCom | M7: B077X8MD39 | N7: 15n9g3 | O7: 500 | P7: g | Q7: 400051 | R7: https://www.amazon.in/dp/B077X8MD39 | S7: 2026-09-11 12:01:21
A8: 400051 | B8: Nutrela Soya Mini Chunks | C8: Nutrela Soya Mini Chunks | D8: In Stock | E8: Yes | F8: Atta, Rice & Dal | G8: Rajma, Chhole & Others | H8: https://www.amazon.in/dp/B013SAX1NG | I8: 50 | J8: 55 | K8: 200 g | L8: Amazon Retail QCom | M8: B013SAX1NG | N8: 15n9g3 | O8: 200 | P8: g | Q8: 400051 | R8: https://www.amazon.in/dp/B013SAX1NG | S8: 2026-09-11 12:01:21
A9: 400051 | B9: Tata Sampann Unpolished Kabuli Chana (Big Size) | C9: Tata Sampann Kabuli Chana (Big Size) | D9: In Stock | E9: Yes | F9: Atta, Rice & Dal | G9: Rajma, Chhole & Others | H9: https://www.amazon.in/dp/B07DCPTP6R | I9: 89 | J9: 104 | K9: 500 g | L9: Amazon Retail QCom | M9: B07DCPTP6R | N9: 15n9g3 | O9: 500 | P9: g | Q9: 400051 | R9: https://www.amazon.in/dp/B07DCPTP6R | S9: 2026-09-11 12:01:21
A10: 400051 | B10: Tata Sampann Unpolished Rajma | C10: Tata Sampann Rajma (Chitra) | D10: In Stock | E10: Yes | F10: Atta, Rice & Dal | G10: Rajma, Chhole & Others | H10: https://www.amazon.in/dp/B077X8CS14 | I10: 93 | J10: 108 | K10: 500 g | L10: Amazon Retail QCom | M10: B077X8CS14 | N10: 15n9g3 | O10: 500 | P10: g | Q10: 400051 | R10: https://www.amazon.in/dp/B077X8CS14 | S10: 2026-09-11 12:01:21
A11: 400051 | B11: Daawat Super Basmati Rice (Long Grain) | C11: Daawat Super Basmati Rice | D11: In Stock | E11: Yes | F11: Atta, Rice & Dal | G11: Rice | H11: https://www.amazon.in/dp/B00SWKBO0K | I11: 820 | J11: 995 | K11: 5 kg | L11: Amazon Retail QCom | M11: B00SWKBO0K | N11: 15n9g3 | O11: 5000 | P11: g | Q11: 400051 | R11: https://www.amazon.in/dp/B00SWKBO0K | S11: 2026-09-11 12:01:21
A12: 400051 | B12: India Gate Daily Premium Basmati Rice (Long Grain) | C12: India Gate Everyday Dubar Pure Basmati Rice | D12: In Stock | E12: Yes | F12: Atta, Rice & Dal | G12: Rice | H12: https://www.amazon.in/dp/B0BBF1FT93 | I12: 379 | J12: 515 | K12: 5 kg | L12: Amazon Retail QCom | M12: B0BBF1FT93 | N12: 15n9g3 | O12: 5000 | P12: g | Q12: 400051 | R12: https://www.amazon.in/dp/B0BBF1FT93 | S12: 2026-09-11 12:01:21
A13: 400051 | B13: Tata Sampann Unpolished Chana Dal | F13: Atta, Rice & Dal | G13: Toor, Urad & Chana | H13: https://www.amazon.in/dp/B077X8G5DK
A14: 400051 | B14: Tata Sampann Unpolished Toor Dal | C14: Vedaka Toor Dal (Split) | D14: In Stock | E14: Yes | F14: Atta, Rice & Dal | G14: Toor, Urad & Chana | H14: https://www.amazon.in/dp/B0BSWQXJDL | I14: 306 | J14: 575 | K14: 2 kg | L14: Amazon Retail QCom | M14: B0BSWQXJDL | N14: 15n9g3 | O14: 2000 | P14: g | Q14: 400051 | R14: https://www.amazon.in/dp/B0BSWQXJDL | S14: 2026-09-11 12:01:21
A15: 400051 | B15: Nestle Cerelac Wheat Apple Baby Cereal (6 - 24 Months) | C15: Cerelac Baby Cereal with Milk | D15: In Stock | E15: Yes | F15: Baby Care | G15: Baby Food | H15: https://www.amazon.in/dp/B00I4SYXIK | I15: 280 | K15: 350 g | L15: Amazon Retail QCom | M15: B00I4SYXIK | N15: 15n9g3 | O15: 350 | P15: g | Q15: 400051 | R15: https://www.amazon.in/dp/B00I4SYXIK | S15: 2026-09-11 12:01:21
A16: 400051 | B16: Himalaya Gentle Baby Wipes | F16: Baby Care | G16: Baby Wipes | H16: https://www.amazon.in/dp/B0GYPN214D
A17: 400051 | B17: Johnson's Baby Soap | F17: Baby Care | G17: Bathing Needs | H17: https://www.amazon.in/dp/B06XY98VPT
A18: 400051 | B18: Pampers Happy Sleep Pant Style Baby Diaper (M) | C18: Pampers Happy Sleep Pant Style Baby Diapers - M | D18: In Stock | E18: Yes | F18: Baby Care | G18: Diapers & More | H18: https://www.amazon.in/dp/B0DSGHM8JW | I18: 476 | J18: 609 | K18: M, 48 Pcs | L18: RK World Infocom Pvt Ltd QCom | M18: B0DSGHM8JW | N18: 15n9g3 | Q18: 400051 | R18: https://www.amazon.in/dp/B0DSGHM8JW | S18: 2026-09-11 12:01:21
A19: 400051 | B19: Johnson's Baby Lotion | C19: Johnson's Baby Lotion | D19: In Stock | E19: Yes | F19: Baby Care | G19: Skin & Hair Care | H19: https://www.amazon.in/dp/B07FHHCR44 | I19: 192 | J19: 220 | K19: 200 ml | L19: RK World Infocom Pvt Ltd QCom | M19: B07FHHCR44 | N19: 15n9g3 | O19: 200 | P19: ml | Q19: 400051 | R19: https://www.amazon.in/dp/B07FHHCR44 | S19: 2026-09-11 12:01:21
A20: 400051 | B20: Weikfield Double Action Baking Powder | F20: Bakery & Biscuits | G20: Baking Ingredients | H20: https://www.amazon.in/dp/B004KFHIBK
A21: 400051 | B21: Lotte Choco Pie | F21: Bakery & Biscuits | G21: Cakes & Rolls | H21: https://www.amazon.in/dp/B019RL0C4Q
A22: 400051 | B22: Britannia Original Bourbon Creme Biscuit | C22: Cadbury Bournvita Biscuits | D22: In Stock | E22: Yes | F22: Bakery & Biscuits | G22: Cookies | H22: https://www.amazon.in/dp/B07FR2GVVK | I22: 29 | J22: 30 | K22: 111.6 g | L22: Amazon Retail QCom | M22: B07FR2GVVK | N22: 15n9g3 | O22: 111.6 | P22: g | Q22: 400051 | R22: https://www.amazon.in/dp/B07FR2GVVK | S22: 2026-09-11 12:01:22
A23: 400051 | B23: Britannia Good Day Cashew Biscuit | C23: Britannia Good Day Cashew Cookies | D23: In Stock | E23: Yes | F23: Bakery & Biscuits | G23: Cookies | H23: https://www.amazon.in/dp/B01M1RKTRK | I23: 82 | J23: 130 | K23: 526 g | L23: Amazon Retail QCom | M23: B01M1RKTRK | N23: 15n9g3 | O23: 526 | P23: g | Q23: 400051 | R23: https://www.amazon.in/dp/B01M1RKTRK | S23: 2026-09-11 12:01:22
A24: 400051 | B24: Malkist Cheese Flavoured Cracker Biscuit - Family Pack | F24: Bakery & Biscuits | G24: Cream Biscuits | H24: https://www.amazon.in/dp/B0F2G8Q5SX
A25: 400051 | B25: Britannia Marie Gold Marie Biscuits (208 g) | C25: Britannia Marie Gold Biscuits | D25: In Stock | E25: Yes | F25: Bakery & Biscuits | G25: Glucose & Marie | H25: https://www.amazon.in/dp/B00S9BSEB4 | I25: 40 | K25: 250 g | L25: Amazon Retail QCom | M25: B00S9BSEB4 | N25: 15n9g3 | O25: 250 | P25: g | Q25: 400051 | R25: https://www.amazon.in/dp/B00S9BSEB4 | S25: 2026-09-11 12:01:22
A26: 400051 | B26: Britannia NutriChoice Digestive High Fibre Biscuit - 250 g Family Pack | C26: Britannia Nutrichoice 5 Grain Digestive Biscuits | D26: In Stock | E26: Yes | F26: Bakery & Biscuits | G26: Healthy & Digestive | H26: https://www.amazon.in/dp/B00RGE4OUA | I26: 54 | J26: 65 | K26: 200 g | L26: Amazon Retail QCom | M26: B00RGE4OUA | N26: 15n9g3 | O26: 200 | P26: g | Q26: 400051 | R26: https://www.amazon.in/dp/B00RGE4OUA | S26: 2026-09-11 12:01:22
A27: 400051 | B27: McVitie's Digestive High Fibre Biscuit | F27: Bakery & Biscuits | G27: Healthy & Digestive | H27: https://www.amazon.in/dp/B0H5QXXHLP
A28: 400051 | B28: Nivea Nourishing Body Lotion | F28: Beauty & Cosmetics | G28: Body & Skin Care | H28: https://www.amazon.in/dp/B099NNW9LL
A29: 400051 | B29: Maybelline New York Colossal Kajal (Deep Black) | C29: Maybelline The Colossal Kajal | D29: In Stock | E29: Yes | F29: Beauty & Cosmetics | G29: Eye Makeup | H29: https://www.amazon.in/dp/B06WGZP21B | I29: 181 | J29: 220 | K29: 0.35 g | L29: RK World Infocom Pvt Ltd QCom | M29: B06WGZP21B | N29: 15n9g3 | O29: 0.35 | P29: g | Q29: 400051 | R29: https://www.amazon.in/dp/B06WGZP21B | S29: 2026-09-11 12:01:22
A30: 400051 | B30: Pond's Bright Beauty Serum Skin Treatment Cream 34 g | F30: Beauty & Cosmetics | G30: Face Care | H30: https://www.amazon.in/dp/B077ND8562
A31: 400051 | B31: Lakme Forever Matte Compact (Pearl) | C31: Lakme Forever Matte Compact | D31: In Stock | E31: Yes | F31: Beauty & Cosmetics | G31: Face Cosmetics | H31: https://www.amazon.in/dp/B09C3Q2YFX | I31: 172 | J31: 245 | K31: 9 g | L31: RK World Infocom Pvt Ltd QCom | M31: B09C3Q2YFX | N31: 15n9g3 | O31: 9 | P31: g | Q31: 400051 | R31: https://www.amazon.in/dp/B09C3Q2YFX | S31: 2026-09-11 12:01:22
A32: 400051 | B32: Livon Anti-Frizz Hair Serum | C32: Livon Go Frizz Free Anti-Frizz Serum | D32: In Stock | E32: Yes | F32: Beauty & Cosmetics | G32: Hair Styling & Treatment | H32: https://www.amazon.in/dp/B00CBRIKIE | I32: 139 | J32: 180 | K32: 50 ml | L32: RK World Infocom Pvt Ltd QCom | M32: B00CBRIKIE | N32: 15n9g3 | O32: 50 | P32: ml | Q32: 400051 | R32: https://www.amazon.in/dp/B00CBRIKIE | S32: 2026-09-11 12:01:22
A33: 400051 | B33: Nivea Essential Care Lip Balm | C33: Nivea Original Care Lip Balm | D33: In Stock | E33: Yes | F33: Beauty & Cosmetics | G33: Lip & Eye Care | H33: https://www.amazon.in/dp/B007E9JC7W | I33: 137 | J33: 175 | K33: 4.8 g | L33: RK World Infocom Pvt Ltd QCom | M33: B007E9JC7W | N33: 15n9g3 | O33: 4.8 | P33: g | Q33: 400051 | R33: https://www.amazon.in/dp/B007E9JC7W | S33: 2026-09-11 12:01:22
A34: 400051 | B34: Lakme 9To5 Hya Matte Lipstick (Workday Rose) | F34: Beauty & Cosmetics | G34: Lip Cosmetics | H34: https://www.amazon.in/dp/B0DWH87545
A35: 400051 | B35: Lakme Nail Paint Remover | C35: Lakme Nail Enamel Remover | D35: In Stock | E35: Yes | F35: Beauty & Cosmetics | G35: Nail Cosmetics | H35: https://www.amazon.in/dp/B006LXBF0E | I35: 99 | J35: 110 | K35: 27 ml | L35: RK World Infocom Pvt Ltd QCom | M35: B006LXBF0E | N35: 15n9g3 | O35: 27 | P35: ml | Q35: 400051 | R35: https://www.amazon.in/dp/B006LXBF0E | S35: 2026-09-11 12:01:22
A36: 400051 | B36: Licious Chicken Curry Cut (Small Pieces) | F36: Chicken, Meat & Fish | G36: Fresh Meat | H36: https://www.amazon.in/dp/B0BTYJ58W1
A37: 400051 | B37: Surf Excel Easy Wash Detergent Powder | C37: Surf Excel Easy Wash Detergent Powder | D37: In Stock | E37: Yes | F37: Cleaning Essentials | G37: Detergent Powder & Bars | H37: https://www.amazon.in/dp/B01ITJ6642 | I37: 80 | J37: 85 | K37: 500 g | L37: RK World Infocom Pvt Ltd QCom | M37: B01ITJ6642 | N37: 15n9g3 | O37: 500 | P37: g | Q37: 400051 | R37: https://www.amazon.in/dp/B01ITJ6642 | S37: 2026-09-11 12:01:22
A38: 400051 | B38: Scotch Brite Scrub Pad | F38: Cleaning Essentials | G38: Dishwashing Accessories | H38: https://www.amazon.in/dp/B07H4YJLP4
A39: 400051 | B39: Vim Lemon Dishwash Bar (300 g) | C39: Vim Dishwash Bar Tub | D39: In Stock | E39: Yes | F39: Cleaning Essentials | G39: Dishwashing Bars & Tubs | H39: https://www.amazon.in/dp/B00U2DVHD4 | I39: 55 | K39: 500 g | L39: RK World Infocom Pvt Ltd QCom | M39: B00U2DVHD4 | N39: 15n9g3 | O39: 500 | P39: g | Q39: 400051 | R39: https://www.amazon.in/dp/B00U2DVHD4 | S39: 2026-09-11 12:01:22
A40: 400051 | B40: Vim Lemon Dishwash Gel | C40: Vim Dishwash Liquid Gel | D40: In Stock | E40: Yes | F40: Cleaning Essentials | G40: Dishwashing Gels & Tablets | H40: https://www.amazon.in/dp/B00M99II36 | I40: 189 | J40: 199 | K40: 750 ml | L40: RK World Infocom Pvt Ltd QCom | M40: B00M99II36 | N40: 15n9g3 | O40: 750 | P40: ml | Q40: 400051 | R40: https://www.amazon.in/dp/B00M99II36 | S40: 2026-09-11 12:01:22
...

Sheet 2026-09-11 1253
A1: Pincode | B1: Item | C1: ProductName | D1: is_out_of_stock | E1: Serviceable | F1: Segment | G1: Grocery | H1: Product_Link | I1: Price | J1: MRP | K1: Weight | L1: Seller | M1: ASIN | N1: StoreId | O1: Final_Qty | P1: Final_unit | Q1: Pincode_Used | R1: Used_Link | S1: Captured_At
A2: 400051 | B2: Aashirvaad Select | Pure MP Sharbati Wheat Atta for Soft Makhmali Rotis | C2: Aashirvaad Select 100% MP Sharbati Atta | D2: In Stock | E2: Yes | F2: Atta, Rice & Dal | G2: Atta | H2: https://www.amazon.in/dp/B00HUJQIZK | I2: 307 | J2: 384 | K2: 5 kg | L2: Amazon Retail QCom | M2: B00HUJQIZK | N2: 15n9g3 | O2: 5000 | P2: g | Q2: 400051 | R2: https://www.amazon.in/dp/B00HUJQIZK | S2: 2026-09-11 12:53:06
A3: 400051 | B3: Fortune Chakki Fresh Atta | F3: Atta, Rice & Dal | G3: Atta | H3: https://www.amazon.in/dp/B0H5BRQFFJ
A4: 400051 | B4: Fortune 100% Chana Dal Besan | C4: Fortune 100% Chana Dal Besan | D4: In Stock | E4: Yes | F4: Atta, Rice & Dal | G4: Besan, Sooji & Maida | H4: https://www.amazon.in/dp/B015MJI4BU | I4: 118 | J4: 169 | K4: 1 kg | L4: Amazon Retail QCom | M4: B015MJI4BU | N4: 15n9g3 | O4: 1000 | P4: g | Q4: 400051 | R4: https://www.amazon.in/dp/B015MJI4BU | S4: 2026-09-11 12:53:06
A5: 400051 | B5: Rajdhani Sooji/Rava | F5: Atta, Rice & Dal | G5: Besan, Sooji & Maida | H5: https://www.amazon.in/dp/B00MOFO276
A6: 400051 | B6: Tata Sampann Unpolished Masoor Dal | C6: Tata Sampann Masoor Dal (Whole) | D6: In Stock | E6: Yes | F6: Atta, Rice & Dal | G6: Moong & Masoor | H6: https://www.amazon.in/dp/B0752S522G | I6: 72 | J6: 79 | K6: 500 g | L6: Amazon Retail QCom | M6: B0752S522G | N6: 15n9g3 | O6: 500 | P6: g | Q6: 400051 | R6: https://www.amazon.in/dp/B0752S522G | S6: 2026-09-11 12:53:06
A7: 400051 | B7: Tata Sampann Unpolished Organic Moong Sabut | C7: Tata Sampann Green Moong Dal (Whole) | D7: In Stock | E7: Yes | F7: Atta, Rice & Dal | G7: Moong & Masoor | H7: https://www.amazon.in/dp/B077X8MD39 | I7: 82 | J7: 93 | K7: 500 g | L7: Amazon Retail QCom | M7: B077X8MD39 | N7: 15n9g3 | O7: 500 | P7: g | Q7: 400051 | R7: https://www.amazon.in/dp/B077X8MD39 | S7: 2026-09-11 12:53:06
A8: 400051 | B8: Nutrela Soya Mini Chunks | C8: Nutrela Soya Mini Chunks | D8: In Stock | E8: Yes | F8: Atta, Rice & Dal | G8: Rajma, Chhole & Others | H8: https://www.amazon.in/dp/B013SAX1NG | I8: 50 | J8: 55 | K8: 200 g | L8: Amazon Retail QCom | M8: B013SAX1NG | N8: 15n9g3 | O8: 200 | P8: g | Q8: 400051 | R8: https://www.amazon.in/dp/B013SAX1NG | S8: 2026-09-11 12:53:06
A9: 400051 | B9: Tata Sampann Unpolished Kabuli Chana (Big Size) | C9: Tata Sampann Kabuli Chana (Big Size) | D9: In Stock | E9: Yes | F9: Atta, Rice & Dal | G9: Rajma, Chhole & Others | H9: https://www.amazon.in/dp/B07DCPTP6R | I9: 89 | J9: 104 | K9: 500 g | L9: Amazon Retail QCom | M9: B07DCPTP6R | N9: 15n9g3 | O9: 500 | P9: g | Q9: 400051 | R9: https://www.amazon.in/dp/B07DCPTP6R | S9: 2026-09-11 12:53:06
A10: 400051 | B10: Tata Sampann Unpolished Rajma | C10: Tata Sampann Rajma (Chitra) | D10: In Stock | E10: Yes | F10: Atta, Rice & Dal | G10: Rajma, Chhole & Others | H10: https://www.amazon.in/dp/B077X8CS14 | I10: 93 | J10: 108 | K10: 500 g | L10: Amazon Retail QCom | M10: B077X8CS14 | N10: 15n9g3 | O10: 500 | P10: g | Q10: 400051 | R10: https://www.amazon.in/dp/B077X8CS14 | S10: 2026-09-11 12:53:06
A11: 400051 | B11: Daawat Super Basmati Rice (Long Grain) | C11: Daawat Super Basmati Rice | D11: In Stock | E11: Yes | F11: Atta, Rice & Dal | G11: Rice | H11: https://www.amazon.in/dp/B00SWKBO0K | I11: 820 | J11: 995 | K11: 5 kg | L11: Amazon Retail QCom | M11: B00SWKBO0K | N11: 15n9g3 | O11: 5000 | P11: g | Q11: 400051 | R11: https://www.amazon.in/dp/B00SWKBO0K | S11: 2026-09-11 12:53:06
A12: 400051 | B12: India Gate Daily Premium Basmati Rice (Long Grain) | C12: India Gate Everyday Dubar Pure Basmati Rice | D12: In Stock | E12: Yes | F12: Atta, Rice & Dal | G12: Rice | H12: https://www.amazon.in/dp/B0BBF1FT93 | I12: 379 | J12: 515 | K12: 5 kg | L12: Amazon Retail QCom | M12: B0BBF1FT93 | N12: 15n9g3 | O12: 5000 | P12: g | Q12: 400051 | R12: https://www.amazon.in/dp/B0BBF1FT93 | S12: 2026-09-11 12:53:06
A13: 400051 | B13: Tata Sampann Unpolished Chana Dal | F13: Atta, Rice & Dal | G13: Toor, Urad & Chana | H13: https://www.amazon.in/dp/B077X8G5DK
A14: 400051 | B14: Tata Sampann Unpolished Toor Dal | C14: Vedaka Toor Dal (Split) | D14: In Stock | E14: Yes | F14: Atta, Rice & Dal | G14: Toor, Urad & Chana | H14: https://www.amazon.in/dp/B0BSWQXJDL | I14: 306 | J14: 575 | K14: 2 kg | L14: Amazon Retail QCom | M14: B0BSWQXJDL | N14: 15n9g3 | O14: 2000 | P14: g | Q14: 400051 | R14: https://www.amazon.in/dp/B0BSWQXJDL | S14: 2026-09-11 12:53:06
A15: 400051 | B15: Nestle Cerelac Wheat Apple Baby Cereal (6 - 24 Months) | C15: Cerelac Baby Cereal with Milk | D15: In Stock | E15: Yes | F15: Baby Care | G15: Baby Food | H15: https://www.amazon.in/dp/B00I4SYXIK | I15: 280 | K15: 350 g | L15: Amazon Retail QCom | M15: B00I4SYXIK | N15: 15n9g3 | O15: 350 | P15: g | Q15: 400051 | R15: https://www.amazon.in/dp/B00I4SYXIK | S15: 2026-09-11 12:53:06
A16: 400051 | B16: Himalaya Gentle Baby Wipes | F16: Baby Care | G16: Baby Wipes | H16: https://www.amazon.in/dp/B0GYPN214D
A17: 400051 | B17: Johnson's Baby Soap | F17: Baby Care | G17: Bathing Needs | H17: https://www.amazon.in/dp/B06XY98VPT
A18: 400051 | B18: Pampers Happy Sleep Pant Style Baby Diaper (M) | C18: Pampers Happy Sleep Pant Style Baby Diapers - M | D18: In Stock | E18: Yes | F18: Baby Care | G18: Diapers & More | H18: https://www.amazon.in/dp/B0DSGHM8JW | I18: 476 | J18: 609 | K18: M, 48 Pcs | L18: RK World Infocom Pvt Ltd QCom | M18: B0DSGHM8JW | N18: 15n9g3 | Q18: 400051 | R18: https://www.amazon.in/dp/B0DSGHM8JW | S18: 2026-09-11 12:53:06
A19: 400051 | B19: Johnson's Baby Lotion | C19: Johnson's Baby Lotion | D19: In Stock | E19: Yes | F19: Baby Care | G19: Skin & Hair Care | H19: https://www.amazon.in/dp/B07FHHCR44 | I19: 192 | J19: 220 | K19: 200 ml | L19: RK World Infocom Pvt Ltd QCom | M19: B07FHHCR44 | N19: 15n9g3 | O19: 200 | P19: ml | Q19: 400051 | R19: https://www.amazon.in/dp/B07FHHCR44 | S19: 2026-09-11 12:53:06
A20: 400051 | B20: Weikfield Double Action Baking Powder | F20: Bakery & Biscuits | G20: Baking Ingredients | H20: https://www.amazon.in/dp/B004KFHIBK
A21: 400051 | B21: Lotte Choco Pie | F21: Bakery & Biscuits | G21: Cakes & Rolls | H21: https://www.amazon.in/dp/B019RL0C4Q
A22: 400051 | B22: Britannia Original Bourbon Creme Biscuit | C22: Cadbury Bournvita Biscuits | D22: In Stock | E22: Yes | F22: Bakery & Biscuits | G22: Cookies | H22: https://www.amazon.in/dp/B07FR2GVVK | I22: 29 | J22: 30 | K22: 111.6 g | L22: Amazon Retail QCom | M22: B07FR2GVVK | N22: 15n9g3 | O22: 111.6 | P22: g | Q22: 400051 | R22: https://www.amazon.in/dp/B07FR2GVVK | S22: 2026-09-11 12:53:07
A23: 400051 | B23: Britannia Good Day Cashew Biscuit | C23: Britannia Good Day Cashew Cookies | D23: In Stock | E23: Yes | F23: Bakery & Biscuits | G23: Cookies | H23: https://www.amazon.in/dp/B01M1RKTRK | I23: 82 | J23: 130 | K23: 526 g | L23: Amazon Retail QCom | M23: B01M1RKTRK | N23: 15n9g3 | O23: 526 | P23: g | Q23: 400051 | R23: https://www.amazon.in/dp/B01M1RKTRK | S23: 2026-09-11 12:53:07
A24: 400051 | B24: Malkist Cheese Flavoured Cracker Biscuit - Family Pack | F24: Bakery & Biscuits | G24: Cream Biscuits | H24: https://www.amazon.in/dp/B0F2G8Q5SX
A25: 400051 | B25: Britannia Marie Gold Marie Biscuits (208 g) | C25: Britannia Marie Gold Biscuits | D25: In Stock | E25: Yes | F25: Bakery & Biscuits | G25: Glucose & Marie | H25: https://www.amazon.in/dp/B00S9BSEB4 | I25: 40 | K25: 250 g | L25: Amazon Retail QCom | M25: B00S9BSEB4 | N25: 15n9g3 | O25: 250 | P25: g | Q25: 400051 | R25: https://www.amazon.in/dp/B00S9BSEB4 | S25: 2026-09-11 12:53:07
A26: 400051 | B26: Britannia NutriChoice Digestive High Fibre Biscuit - 250 g Family Pack | C26: Britannia Nutrichoice 5 Grain Digestive Biscuits | D26: In Stock | E26: Yes | F26: Bakery & Biscuits | G26: Healthy & Digestive | H26: https://www.amazon.in/dp/B00RGE4OUA | I26: 54 | J26: 65 | K26: 200 g | L26: Amazon Retail QCom | M26: B00RGE4OUA | N26: 15n9g3 | O26: 200 | P26: g | Q26: 400051 | R26: https://www.amazon.in/dp/B00RGE4OUA | S26: 2026-09-11 12:53:07
A27: 400051 | B27: McVitie's Digestive High Fibre Biscuit | F27: Bakery & Biscuits | G27: Healthy & Digestive | H27: https://www.amazon.in/dp/B0H5QXXHLP
A28: 400051 | B28: Nivea Nourishing Body Lotion | F28: Beauty & Cosmetics | G28: Body & Skin Care | H28: https://www.amazon.in/dp/B099NNW9LL
