Workbook

Sheet Summary
A1: FK_Minutes — In Stock % by run
A2: In Stock / (In Stock + Out of Stock). Excluded from both halves: rows with no reading, rows from a store marked Serviceable = No, and "Not Available" rows (the store does not carry the item — an assortment gap, not a stock-out). The 'Not carried' block below counts those.
A4: Pincode | B4: 2026-09-10 21:47 | C4: 2026-09-11 07:21 | D4: 2026-09-11 08:45 | E4: 2026-09-11 10:33 | F4: 2026-09-11 12:01 | G4: 2026-09-11 12:53 | H4: 2026-09-12 12:52 | I4: 2026-09-12 13:30 | J4: 2026-09-12 21:41 | K4: 2026-09-12 21:58 | L4: 2026-09-13 06:40 | M4: 2026-09-13 07:59 | N4: 2026-09-13 09:54 | O4: 2026-09-13 11:59 | P4: 2026-09-13 18:58 | Q4: 2026-09-14 08:51
A5: 110060 | B5: =IFERROR(SUMPRODUCT(('2026-09-10 2147'!$A$2:$A$309="110060")*('2026-09-10 2147'!$D$2:$D$309="In Stock")*('2026-09-10 2147'!$E$2:$E$309<>"No"))/SUMPRODUCT(('2026-09-10 2147'!$A$2:$A$309="110060")*(('2026-09-10 2147'!$D$2:$D$309="In Stock")+('2026-09-10 2147'!$D$2:$D$309="Out of Stock"))*('2026-09-10 2147'!$E$2:$E$309<>"No")),"") | C5: =IFERROR(SUMPRODUCT(('2026-09-11 0721'!$A$2:$A$309="110060")*('2026-09-11 0721'!$D$2:$D$309="In Stock")*('2026-09-11 0721'!$E$2:$E$309<>"No"))/SUMPRODUCT(('2026-09-11 0721'!$A$2:$A$309="110060")*(('2026-09-11 0721'!$D$2:$D$309="In Stock")+('2026-09-11 0721'!$D$2:$D$309="Out of Stock"))*('2026-09-11 0721'!$E$2:$E$309<>"No")),"") | D5: =IFERROR(SUMPRODUCT(('2026-09-11 0845'!$A$2:$A$309="110060")*('2026-09-11 0845'!$D$2:$D$309="In Stock")*('2026-09-11 0845'!$E$2:$E$309<>"No"))/SUMPRODUCT(('2026-09-11 0845'!$A$2:$A$309="110060")*(('2026-09-11 0845'!$D$2:$D$309="In Stock")+('2026-09-11 0845'!$D$2:$D$309="Out of Stock"))*('2026-09-11 0845'!$E$2:$E$309<>"No")),"") | E5: =IFERROR(SUMPRODUCT(('2026-09-11 1033'!$A$2:$A$155="110060")*('2026-09-11 1033'!$D$2:$D$155="In Stock")*('2026-09-11 1033'!$E$2:$E$155<>"No"))/SUMPRODUCT(('2026-09-11 1033'!$A$2:$A$155="110060")*(('2026-09-11 1033'!$D$2:$D$155="In Stock")+('2026-09-11 1033'!$D$2:$D$155="Out of Stock"))*('2026-09-11 1033'!$E$2:$E$155<>"No")),"") | F5: =IFERROR(SUMPRODUCT(('2026-09-11 1201'!$A$2:$A$155="110060")*('2026-09-11 1201'!$D$2:$D$155="In Stock")*('2026-09-11 1201'!$E$2:$E$155<>"No"))/SUMPRODUCT(('2026-09-11 1201'!$A$2:$A$155="110060")*(('2026-09-11 1201'!$D$2:$D$155="In Stock")+('2026-09-11 1201'!$D$2:$D$155="Out of Stock"))*('2026-09-11 1201'!$E$2:$E$155<>"No")),"") | G5: =IFERROR(SUMPRODUCT(('2026-09-11 1253'!$A$2:$A$155="110060")*('2026-09-11 1253'!$D$2:$D$155="In Stock")*('2026-09-11 1253'!$E$2:$E$155<>"No"))/SUMPRODUCT(('2026-09-11 1253'!$A$2:$A$155="110060")*(('2026-09-11 1253'!$D$2:$D$155="In Stock")+('2026-09-11 1253'!$D$2:$D$155="Out of Stock"))*('2026-09-11 1253'!$E$2:$E$155<>"No")),"") | H5: =IFERROR(SUMPRODUCT(('2026-09-12 1252'!$A$2:$A$155="110060")*('2026-09-12 1252'!$D$2:$D$155="In Stock")*('2026-09-12 1252'!$E$2:$E$155<>"No"))/SUMPRODUCT(('2026-09-12 1252'!$A$2:$A$155="110060")*(('2026-09-12 1252'!$D$2:$D$155="In Stock")+('2026-09-12 1252'!$D$2:$D$155="Out of Stock"))*('2026-09-12 1252'!$E$2:$E$155<>"No")),"") | I5: =IFERROR(SUMPRODUCT(('2026-09-12 1330'!$A$2:$A$155="110060")*('2026-09-12 1330'!$D$2:$D$155="In Stock")*('2026-09-12 1330'!$E$2:$E$155<>"No"))/SUMPRODUCT(('2026-09-12 1330'!$A$2:$A$155="110060")*(('2026-09-12 1330'!$D$2:$D$155="In Stock")+('2026-09-12 1330'!$D$2:$D$155="Out of Stock"))*('2026-09-12 1330'!$E$2:$E$155<>"No")),"") | J5: =IFERROR(SUMPRODUCT(('2026-09-12 2141'!$A$2:$A$155="110060")*('2026-09-12 2141'!$D$2:$D$155="In Stock")*('2026-09-12 2141'!$E$2:$E$155<>"No"))/SUMPRODUCT(('2026-09-12 2141'!$A$2:$A$155="110060")*(('2026-09-12 2141'!$D$2:$D$155="In Stock")+('2026-09-12 2141'!$D$2:$D$155="Out of Stock"))*('2026-09-12 2141'!$E$2:$E$155<>"No")),"") | K5: =IFERROR(SUMPRODUCT(('2026-09-12 2158'!$A$2:$A$155="110060")*('2026-09-12 2158'!$D$2:$D$155="In Stock")*('2026-09-12 2158'!$E$2:$E$155<>"No"))/SUMPRODUCT(('2026-09-12 2158'!$A$2:$A$155="110060")*(('2026-09-12 2158'!$D$2:$D$155="In Stock")+('2026-09-12 2158'!$D$2:$D$155="Out of Stock"))*('2026-09-12 2158'!$E$2:$E$155<>"No")),"") | L5: =IFERROR(SUMPRODUCT(('2026-09-13 0640'!$A$2:$A$309="110060")*('2026-09-13 0640'!$D$2:$D$309="In Stock")*('2026-09-13 0640'!$E$2:$E$309<>"No"))/SUMPRODUCT(('2026-09-13 0640'!$A$2:$A$309="110060")*(('2026-09-13 0640'!$D$2:$D$309="In Stock")+('2026-09-13 0640'!$D$2:$D$309="Out of Stock"))*('2026-09-13 0640'!$E$2:$E$309<>"No")),"") | M5: =IFERROR(SUMPRODUCT(('2026-09-13 0759'!$A$2:$A$463="110060")*('2026-09-13 0759'!$D$2:$D$463="In Stock")*('2026-09-13 0759'!$E$2:$E$463<>"No"))/SUMPRODUCT(('2026-09-13 0759'!$A$2:$A$463="110060")*(('2026-09-13 0759'!$D$2:$D$463="In Stock")+('2026-09-13 0759'!$D$2:$D$463="Out of Stock"))*('2026-09-13 0759'!$E$2:$E$463<>"No")),"") | N5: =IFERROR(SUMPRODUCT(('2026-09-13 0954'!$A$2:$A$463="110060")*('2026-09-13 0954'!$D$2:$D$463="In Stock")*('2026-09-13 0954'!$E$2:$E$463<>"No"))/SUMPRODUCT(('2026-09-13 0954'!$A$2:$A$463="110060")*(('2026-09-13 0954'!$D$2:$D$463="In Stock")+('2026-09-13 0954'!$D$2:$D$463="Out of Stock"))*('2026-09-13 0954'!$E$2:$E$463<>"No")),"") | O5: =IFERROR(SUMPRODUCT(('2026-09-13 1159'!$A$2:$A$463="110060")*('2026-09-13 1159'!$D$2:$D$463="In Stock")*('2026-09-13 1159'!$E$2:$E$463<>"No"))/SUMPRODUCT(('2026-09-13 1159'!$A$2:$A$463="110060")*(('2026-09-13 1159'!$D$2:$D$463="In Stock")+('2026-09-13 1159'!$D$2:$D$463="Out of Stock"))*('2026-09-13 1159'!$E$2:$E$463<>"No")),"") | P5: =IFERROR(SUMPRODUCT(('2026-09-13 1858'!$A$2:$A$463="110060")*('2026-09-13 1858'!$D$2:$D$463="In Stock")*('2026-09-13 1858'!$E$2:$E$463<>"No"))/SUMPRODUCT(('2026-09-13 1858'!$A$2:$A$463="110060")*(('2026-09-13 1858'!$D$2:$D$463="In Stock")+('2026-09-13 1858'!$D$2:$D$463="Out of Stock"))*('2026-09-13 1858'!$E$2:$E$463<>"No")),"") | Q5: =IFERROR(SUMPRODUCT(('2026-09-14 0851'!$A$2:$A$463="110060")*('2026-09-14 0851'!$D$2:$D$463="In Stock")*('2026-09-14 0851'!$E$2:$E$463<>"No"))/SUMPRODUCT(('2026-09-14 0851'!$A$2:$A$463="110060")*(('2026-09-14 0851'!$D$2:$D$463="In Stock")+('2026-09-14 0851'!$D$2:$D$463="Out of Stock"))*('2026-09-14 0851'!$E$2:$E$463<>"No")),"")
A6: 400051 | B6: =IFERROR(SUMPRODUCT(('2026-09-10 2147'!$A$2:$A$309="400051")*('2026-09-10 2147'!$D$2:$D$309="In Stock")*('2026-09-10 2147'!$E$2:$E$309<>"No"))/SUMPRODUCT(('2026-09-10 2147'!$A$2:$A$309="400051")*(('2026-09-10 2147'!$D$2:$D$309="In Stock")+('2026-09-10 2147'!$D$2:$D$309="Out of Stock"))*('2026-09-10 2147'!$E$2:$E$309<>"No")),"") | C6: =IFERROR(SUMPRODUCT(('2026-09-11 0721'!$A$2:$A$309="400051")*('2026-09-11 0721'!$D$2:$D$309="In Stock")*('2026-09-11 0721'!$E$2:$E$309<>"No"))/SUMPRODUCT(('2026-09-11 0721'!$A$2:$A$309="400051")*(('2026-09-11 0721'!$D$2:$D$309="In Stock")+('2026-09-11 0721'!$D$2:$D$309="Out of Stock"))*('2026-09-11 0721'!$E$2:$E$309<>"No")),"") | D6: =IFERROR(SUMPRODUCT(('2026-09-11 0845'!$A$2:$A$309="400051")*('2026-09-11 0845'!$D$2:$D$309="In Stock")*('2026-09-11 0845'!$E$2:$E$309<>"No"))/SUMPRODUCT(('2026-09-11 0845'!$A$2:$A$309="400051")*(('2026-09-11 0845'!$D$2:$D$309="In Stock")+('2026-09-11 0845'!$D$2:$D$309="Out of Stock"))*('2026-09-11 0845'!$E$2:$E$309<>"No")),"") | E6: =IFERROR(SUMPRODUCT(('2026-09-11 1033'!$A$2:$A$155="400051")*('2026-09-11 1033'!$D$2:$D$155="In Stock")*('2026-09-11 1033'!$E$2:$E$155<>"No"))/SUMPRODUCT(('2026-09-11 1033'!$A$2:$A$155="400051")*(('2026-09-11 1033'!$D$2:$D$155="In Stock")+('2026-09-11 1033'!$D$2:$D$155="Out of Stock"))*('2026-09-11 1033'!$E$2:$E$155<>"No")),"") | F6: =IFERROR(SUMPRODUCT(('2026-09-11 1201'!$A$2:$A$155="400051")*('2026-09-11 1201'!$D$2:$D$155="In Stock")*('2026-09-11 1201'!$E$2:$E$155<>"No"))/SUMPRODUCT(('2026-09-11 1201'!$A$2:$A$155="400051")*(('2026-09-11 1201'!$D$2:$D$155="In Stock")+('2026-09-11 1201'!$D$2:$D$155="Out of Stock"))*('2026-09-11 1201'!$E$2:$E$155<>"No")),"") | G6: =IFERROR(SUMPRODUCT(('2026-09-11 1253'!$A$2:$A$155="400051")*('2026-09-11 1253'!$D$2:$D$155="In Stock")*('2026-09-11 1253'!$E$2:$E$155<>"No"))/SUMPRODUCT(('2026-09-11 1253'!$A$2:$A$155="400051")*(('2026-09-11 1253'!$D$2:$D$155="In Stock")+('2026-09-11 1253'!$D$2:$D$155="Out of Stock"))*('2026-09-11 1253'!$E$2:$E$155<>"No")),"") | H6: =IFERROR(SUMPRODUCT(('2026-09-12 1252'!$A$2:$A$155="400051")*('2026-09-12 1252'!$D$2:$D$155="In Stock")*('2026-09-12 1252'!$E$2:$E$155<>"No"))/SUMPRODUCT(('2026-09-12 1252'!$A$2:$A$155="400051")*(('2026-09-12 1252'!$D$2:$D$155="In Stock")+('2026-09-12 1252'!$D$2:$D$155="Out of Stock"))*('2026-09-12 1252'!$E$2:$E$155<>"No")),"") | I6: =IFERROR(SUMPRODUCT(('2026-09-12 1330'!$A$2:$A$155="400051")*('2026-09-12 1330'!$D$2:$D$155="In Stock")*('2026-09-12 1330'!$E$2:$E$155<>"No"))/SUMPRODUCT(('2026-09-12 1330'!$A$2:$A$155="400051")*(('2026-09-12 1330'!$D$2:$D$155="In Stock")+('2026-09-12 1330'!$D$2:$D$155="Out of Stock"))*('2026-09-12 1330'!$E$2:$E$155<>"No")),"") | J6: =IFERROR(SUMPRODUCT(('2026-09-12 2141'!$A$2:$A$155="400051")*('2026-09-12 2141'!$D$2:$D$155="In Stock")*('2026-09-12 2141'!$E$2:$E$155<>"No"))/SUMPRODUCT(('2026-09-12 2141'!$A$2:$A$155="400051")*(('2026-09-12 2141'!$D$2:$D$155="In Stock")+('2026-09-12 2141'!$D$2:$D$155="Out of Stock"))*('2026-09-12 2141'!$E$2:$E$155<>"No")),"") | K6: =IFERROR(SUMPRODUCT(('2026-09-12 2158'!$A$2:$A$155="400051")*('2026-09-12 2158'!$D$2:$D$155="In Stock")*('2026-09-12 2158'!$E$2:$E$155<>"No"))/SUMPRODUCT(('2026-09-12 2158'!$A$2:$A$155="400051")*(('2026-09-12 2158'!$D$2:$D$155="In Stock")+('2026-09-12 2158'!$D$2:$D$155="Out of Stock"))*('2026-09-12 2158'!$E$2:$E$155<>"No")),"") | L6: =IFERROR(SUMPRODUCT(('2026-09-13 0640'!$A$2:$A$309="400051")*('2026-09-13 0640'!$D$2:$D$309="In Stock")*('2026-09-13 0640'!$E$2:$E$309<>"No"))/SUMPRODUCT(('2026-09-13 0640'!$A$2:$A$309="400051")*(('2026-09-13 0640'!$D$2:$D$309="In Stock")+('2026-09-13 0640'!$D$2:$D$309="Out of Stock"))*('2026-09-13 0640'!$E$2:$E$309<>"No")),"") | M6: =IFERROR(SUMPRODUCT(('2026-09-13 0759'!$A$2:$A$463="400051")*('2026-09-13 0759'!$D$2:$D$463="In Stock")*('2026-09-13 0759'!$E$2:$E$463<>"No"))/SUMPRODUCT(('2026-09-13 0759'!$A$2:$A$463="400051")*(('2026-09-13 0759'!$D$2:$D$463="In Stock")+('2026-09-13 0759'!$D$2:$D$463="Out of Stock"))*('2026-09-13 0759'!$E$2:$E$463<>"No")),"") | N6: =IFERROR(SUMPRODUCT(('2026-09-13 0954'!$A$2:$A$463="400051")*('2026-09-13 0954'!$D$2:$D$463="In Stock")*('2026-09-13 0954'!$E$2:$E$463<>"No"))/SUMPRODUCT(('2026-09-13 0954'!$A$2:$A$463="400051")*(('2026-09-13 0954'!$D$2:$D$463="In Stock")+('2026-09-13 0954'!$D$2:$D$463="Out of Stock"))*('2026-09-13 0954'!$E$2:$E$463<>"No")),"") | O6: =IFERROR(SUMPRODUCT(('2026-09-13 1159'!$A$2:$A$463="400051")*('2026-09-13 1159'!$D$2:$D$463="In Stock")*('2026-09-13 1159'!$E$2:$E$463<>"No"))/SUMPRODUCT(('2026-09-13 1159'!$A$2:$A$463="400051")*(('2026-09-13 1159'!$D$2:$D$463="In Stock")+('2026-09-13 1159'!$D$2:$D$463="Out of Stock"))*('2026-09-13 1159'!$E$2:$E$463<>"No")),"") | P6: =IFERROR(SUMPRODUCT(('2026-09-13 1858'!$A$2:$A$463="400051")*('2026-09-13 1858'!$D$2:$D$463="In Stock")*('2026-09-13 1858'!$E$2:$E$463<>"No"))/SUMPRODUCT(('2026-09-13 1858'!$A$2:$A$463="400051")*(('2026-09-13 1858'!$D$2:$D$463="In Stock")+('2026-09-13 1858'!$D$2:$D$463="Out of Stock"))*('2026-09-13 1858'!$E$2:$E$463<>"No")),"") | Q6: =IFERROR(SUMPRODUCT(('2026-09-14 0851'!$A$2:$A$463="400051")*('2026-09-14 0851'!$D$2:$D$463="In Stock")*('2026-09-14 0851'!$E$2:$E$463<>"No"))/SUMPRODUCT(('2026-09-14 0851'!$A$2:$A$463="400051")*(('2026-09-14 0851'!$D$2:$D$463="In Stock")+('2026-09-14 0851'!$D$2:$D$463="Out of Stock"))*('2026-09-14 0851'!$E$2:$E$463<>"No")),"")
A7: 560017 | B7: =IFERROR(SUMPRODUCT(('2026-09-10 2147'!$A$2:$A$309="560017")*('2026-09-10 2147'!$D$2:$D$309="In Stock")*('2026-09-10 2147'!$E$2:$E$309<>"No"))/SUMPRODUCT(('2026-09-10 2147'!$A$2:$A$309="560017")*(('2026-09-10 2147'!$D$2:$D$309="In Stock")+('2026-09-10 2147'!$D$2:$D$309="Out of Stock"))*('2026-09-10 2147'!$E$2:$E$309<>"No")),"") | C7: =IFERROR(SUMPRODUCT(('2026-09-11 0721'!$A$2:$A$309="560017")*('2026-09-11 0721'!$D$2:$D$309="In Stock")*('2026-09-11 0721'!$E$2:$E$309<>"No"))/SUMPRODUCT(('2026-09-11 0721'!$A$2:$A$309="560017")*(('2026-09-11 0721'!$D$2:$D$309="In Stock")+('2026-09-11 0721'!$D$2:$D$309="Out of Stock"))*('2026-09-11 0721'!$E$2:$E$309<>"No")),"") | D7: =IFERROR(SUMPRODUCT(('2026-09-11 0845'!$A$2:$A$309="560017")*('2026-09-11 0845'!$D$2:$D$309="In Stock")*('2026-09-11 0845'!$E$2:$E$309<>"No"))/SUMPRODUCT(('2026-09-11 0845'!$A$2:$A$309="560017")*(('2026-09-11 0845'!$D$2:$D$309="In Stock")+('2026-09-11 0845'!$D$2:$D$309="Out of Stock"))*('2026-09-11 0845'!$E$2:$E$309<>"No")),"") | E7: =IFERROR(SUMPRODUCT(('2026-09-11 1033'!$A$2:$A$155="560017")*('2026-09-11 1033'!$D$2:$D$155="In Stock")*('2026-09-11 1033'!$E$2:$E$155<>"No"))/SUMPRODUCT(('2026-09-11 1033'!$A$2:$A$155="560017")*(('2026-09-11 1033'!$D$2:$D$155="In Stock")+('2026-09-11 1033'!$D$2:$D$155="Out of Stock"))*('2026-09-11 1033'!$E$2:$E$155<>"No")),"") | F7: =IFERROR(SUMPRODUCT(('2026-09-11 1201'!$A$2:$A$155="560017")*('2026-09-11 1201'!$D$2:$D$155="In Stock")*('2026-09-11 1201'!$E$2:$E$155<>"No"))/SUMPRODUCT(('2026-09-11 1201'!$A$2:$A$155="560017")*(('2026-09-11 1201'!$D$2:$D$155="In Stock")+('2026-09-11 1201'!$D$2:$D$155="Out of Stock"))*('2026-09-11 1201'!$E$2:$E$155<>"No")),"") | G7: =IFERROR(SUMPRODUCT(('2026-09-11 1253'!$A$2:$A$155="560017")*('2026-09-11 1253'!$D$2:$D$155="In Stock")*('2026-09-11 1253'!$E$2:$E$155<>"No"))/SUMPRODUCT(('2026-09-11 1253'!$A$2:$A$155="560017")*(('2026-09-11 1253'!$D$2:$D$155="In Stock")+('2026-09-11 1253'!$D$2:$D$155="Out of Stock"))*('2026-09-11 1253'!$E$2:$E$155<>"No")),"") | H7: =IFERROR(SUMPRODUCT(('2026-09-12 1252'!$A$2:$A$155="560017")*('2026-09-12 1252'!$D$2:$D$155="In Stock")*('2026-09-12 1252'!$E$2:$E$155<>"No"))/SUMPRODUCT(('2026-09-12 1252'!$A$2:$A$155="560017")*(('2026-09-12 1252'!$D$2:$D$155="In Stock")+('2026-09-12 1252'!$D$2:$D$155="Out of Stock"))*('2026-09-12 1252'!$E$2:$E$155<>"No")),"") | I7: =IFERROR(SUMPRODUCT(('2026-09-12 1330'!$A$2:$A$155="560017")*('2026-09-12 1330'!$D$2:$D$155="In Stock")*('2026-09-12 1330'!$E$2:$E$155<>"No"))/SUMPRODUCT(('2026-09-12 1330'!$A$2:$A$155="560017")*(('2026-09-12 1330'!$D$2:$D$155="In Stock")+('2026-09-12 1330'!$D$2:$D$155="Out of Stock"))*('2026-09-12 1330'!$E$2:$E$155<>"No")),"") | J7: =IFERROR(SUMPRODUCT(('2026-09-12 2141'!$A$2:$A$155="560017")*('2026-09-12 2141'!$D$2:$D$155="In Stock")*('2026-09-12 2141'!$E$2:$E$155<>"No"))/SUMPRODUCT(('2026-09-12 2141'!$A$2:$A$155="560017")*(('2026-09-12 2141'!$D$2:$D$155="In Stock")+('2026-09-12 2141'!$D$2:$D$155="Out of Stock"))*('2026-09-12 2141'!$E$2:$E$155<>"No")),"") | K7: =IFERROR(SUMPRODUCT(('2026-09-12 2158'!$A$2:$A$155="560017")*('2026-09-12 2158'!$D$2:$D$155="In Stock")*('2026-09-12 2158'!$E$2:$E$155<>"No"))/SUMPRODUCT(('2026-09-12 2158'!$A$2:$A$155="560017")*(('2026-09-12 2158'!$D$2:$D$155="In Stock")+('2026-09-12 2158'!$D$2:$D$155="Out of Stock"))*('2026-09-12 2158'!$E$2:$E$155<>"No")),"") | L7: =IFERROR(SUMPRODUCT(('2026-09-13 0640'!$A$2:$A$309="560017")*('2026-09-13 0640'!$D$2:$D$309="In Stock")*('2026-09-13 0640'!$E$2:$E$309<>"No"))/SUMPRODUCT(('2026-09-13 0640'!$A$2:$A$309="560017")*(('2026-09-13 0640'!$D$2:$D$309="In Stock")+('2026-09-13 0640'!$D$2:$D$309="Out of Stock"))*('2026-09-13 0640'!$E$2:$E$309<>"No")),"") | M7: =IFERROR(SUMPRODUCT(('2026-09-13 0759'!$A$2:$A$463="560017")*('2026-09-13 0759'!$D$2:$D$463="In Stock")*('2026-09-13 0759'!$E$2:$E$463<>"No"))/SUMPRODUCT(('2026-09-13 0759'!$A$2:$A$463="560017")*(('2026-09-13 0759'!$D$2:$D$463="In Stock")+('2026-09-13 0759'!$D$2:$D$463="Out of Stock"))*('2026-09-13 0759'!$E$2:$E$463<>"No")),"") | N7: =IFERROR(SUMPRODUCT(('2026-09-13 0954'!$A$2:$A$463="560017")*('2026-09-13 0954'!$D$2:$D$463="In Stock")*('2026-09-13 0954'!$E$2:$E$463<>"No"))/SUMPRODUCT(('2026-09-13 0954'!$A$2:$A$463="560017")*(('2026-09-13 0954'!$D$2:$D$463="In Stock")+('2026-09-13 0954'!$D$2:$D$463="Out of Stock"))*('2026-09-13 0954'!$E$2:$E$463<>"No")),"") | O7: =IFERROR(SUMPRODUCT(('2026-09-13 1159'!$A$2:$A$463="560017")*('2026-09-13 1159'!$D$2:$D$463="In Stock")*('2026-09-13 1159'!$E$2:$E$463<>"No"))/SUMPRODUCT(('2026-09-13 1159'!$A$2:$A$463="560017")*(('2026-09-13 1159'!$D$2:$D$463="In Stock")+('2026-09-13 1159'!$D$2:$D$463="Out of Stock"))*('2026-09-13 1159'!$E$2:$E$463<>"No")),"") | P7: =IFERROR(SUMPRODUCT(('2026-09-13 1858'!$A$2:$A$463="560017")*('2026-09-13 1858'!$D$2:$D$463="In Stock")*('2026-09-13 1858'!$E$2:$E$463<>"No"))/SUMPRODUCT(('2026-09-13 1858'!$A$2:$A$463="560017")*(('2026-09-13 1858'!$D$2:$D$463="In Stock")+('2026-09-13 1858'!$D$2:$D$463="Out of Stock"))*('2026-09-13 1858'!$E$2:$E$463<>"No")),"") | Q7: =IFERROR(SUMPRODUCT(('2026-09-14 0851'!$A$2:$A$463="560017")*('2026-09-14 0851'!$D$2:$D$463="In Stock")*('2026-09-14 0851'!$E$2:$E$463<>"No"))/SUMPRODUCT(('2026-09-14 0851'!$A$2:$A$463="560017")*(('2026-09-14 0851'!$D$2:$D$463="In Stock")+('2026-09-14 0851'!$D$2:$D$463="Out of Stock"))*('2026-09-14 0851'!$E$2:$E$463<>"No")),"")
A8: 560048 | B8: =IFERROR(SUMPRODUCT(('2026-09-10 2147'!$A$2:$A$309="560048")*('2026-09-10 2147'!$D$2:$D$309="In Stock")*('2026-09-10 2147'!$E$2:$E$309<>"No"))/SUMPRODUCT(('2026-09-10 2147'!$A$2:$A$309="560048")*(('2026-09-10 2147'!$D$2:$D$309="In Stock")+('2026-09-10 2147'!$D$2:$D$309="Out of Stock"))*('2026-09-10 2147'!$E$2:$E$309<>"No")),"") | C8: =IFERROR(SUMPRODUCT(('2026-09-11 0721'!$A$2:$A$309="560048")*('2026-09-11 0721'!$D$2:$D$309="In Stock")*('2026-09-11 0721'!$E$2:$E$309<>"No"))/SUMPRODUCT(('2026-09-11 0721'!$A$2:$A$309="560048")*(('2026-09-11 0721'!$D$2:$D$309="In Stock")+('2026-09-11 0721'!$D$2:$D$309="Out of Stock"))*('2026-09-11 0721'!$E$2:$E$309<>"No")),"") | D8: =IFERROR(SUMPRODUCT(('2026-09-11 0845'!$A$2:$A$309="560048")*('2026-09-11 0845'!$D$2:$D$309="In Stock")*('2026-09-11 0845'!$E$2:$E$309<>"No"))/SUMPRODUCT(('2026-09-11 0845'!$A$2:$A$309="560048")*(('2026-09-11 0845'!$D$2:$D$309="In Stock")+('2026-09-11 0845'!$D$2:$D$309="Out of Stock"))*('2026-09-11 0845'!$E$2:$E$309<>"No")),"") | E8: =IFERROR(SUMPRODUCT(('2026-09-11 1033'!$A$2:$A$155="560048")*('2026-09-11 1033'!$D$2:$D$155="In Stock")*('2026-09-11 1033'!$E$2:$E$155<>"No"))/SUMPRODUCT(('2026-09-11 1033'!$A$2:$A$155="560048")*(('2026-09-11 1033'!$D$2:$D$155="In Stock")+('2026-09-11 1033'!$D$2:$D$155="Out of Stock"))*('2026-09-11 1033'!$E$2:$E$155<>"No")),"") | F8: =IFERROR(SUMPRODUCT(('2026-09-11 1201'!$A$2:$A$155="560048")*('2026-09-11 1201'!$D$2:$D$155="In Stock")*('2026-09-11 1201'!$E$2:$E$155<>"No"))/SUMPRODUCT(('2026-09-11 1201'!$A$2:$A$155="560048")*(('2026-09-11 1201'!$D$2:$D$155="In Stock")+('2026-09-11 1201'!$D$2:$D$155="Out of Stock"))*('2026-09-11 1201'!$E$2:$E$155<>"No")),"") | G8: =IFERROR(SUMPRODUCT(('2026-09-11 1253'!$A$2:$A$155="560048")*('2026-09-11 1253'!$D$2:$D$155="In Stock")*('2026-09-11 1253'!$E$2:$E$155<>"No"))/SUMPRODUCT(('2026-09-11 1253'!$A$2:$A$155="560048")*(('2026-09-11 1253'!$D$2:$D$155="In Stock")+('2026-09-11 1253'!$D$2:$D$155="Out of Stock"))*('2026-09-11 1253'!$E$2:$E$155<>"No")),"") | H8: =IFERROR(SUMPRODUCT(('2026-09-12 1252'!$A$2:$A$155="560048")*('2026-09-12 1252'!$D$2:$D$155="In Stock")*('2026-09-12 1252'!$E$2:$E$155<>"No"))/SUMPRODUCT(('2026-09-12 1252'!$A$2:$A$155="560048")*(('2026-09-12 1252'!$D$2:$D$155="In Stock")+('2026-09-12 1252'!$D$2:$D$155="Out of Stock"))*('2026-09-12 1252'!$E$2:$E$155<>"No")),"") | I8: =IFERROR(SUMPRODUCT(('2026-09-12 1330'!$A$2:$A$155="560048")*('2026-09-12 1330'!$D$2:$D$155="In Stock")*('2026-09-12 1330'!$E$2:$E$155<>"No"))/SUMPRODUCT(('2026-09-12 1330'!$A$2:$A$155="560048")*(('2026-09-12 1330'!$D$2:$D$155="In Stock")+('2026-09-12 1330'!$D$2:$D$155="Out of Stock"))*('2026-09-12 1330'!$E$2:$E$155<>"No")),"") | J8: =IFERROR(SUMPRODUCT(('2026-09-12 2141'!$A$2:$A$155="560048")*('2026-09-12 2141'!$D$2:$D$155="In Stock")*('2026-09-12 2141'!$E$2:$E$155<>"No"))/SUMPRODUCT(('2026-09-12 2141'!$A$2:$A$155="560048")*(('2026-09-12 2141'!$D$2:$D$155="In Stock")+('2026-09-12 2141'!$D$2:$D$155="Out of Stock"))*('2026-09-12 2141'!$E$2:$E$155<>"No")),"") | K8: =IFERROR(SUMPRODUCT(('2026-09-12 2158'!$A$2:$A$155="560048")*('2026-09-12 2158'!$D$2:$D$155="In Stock")*('2026-09-12 2158'!$E$2:$E$155<>"No"))/SUMPRODUCT(('2026-09-12 2158'!$A$2:$A$155="560048")*(('2026-09-12 2158'!$D$2:$D$155="In Stock")+('2026-09-12 2158'!$D$2:$D$155="Out of Stock"))*('2026-09-12 2158'!$E$2:$E$155<>"No")),"") | L8: =IFERROR(SUMPRODUCT(('2026-09-13 0640'!$A$2:$A$309="560048")*('2026-09-13 0640'!$D$2:$D$309="In Stock")*('2026-09-13 0640'!$E$2:$E$309<>"No"))/SUMPRODUCT(('2026-09-13 0640'!$A$2:$A$309="560048")*(('2026-09-13 0640'!$D$2:$D$309="In Stock")+('2026-09-13 0640'!$D$2:$D$309="Out of Stock"))*('2026-09-13 0640'!$E$2:$E$309<>"No")),"") | M8: =IFERROR(SUMPRODUCT(('2026-09-13 0759'!$A$2:$A$463="560048")*('2026-09-13 0759'!$D$2:$D$463="In Stock")*('2026-09-13 0759'!$E$2:$E$463<>"No"))/SUMPRODUCT(('2026-09-13 0759'!$A$2:$A$463="560048")*(('2026-09-13 0759'!$D$2:$D$463="In Stock")+('2026-09-13 0759'!$D$2:$D$463="Out of Stock"))*('2026-09-13 0759'!$E$2:$E$463<>"No")),"") | N8: =IFERROR(SUMPRODUCT(('2026-09-13 0954'!$A$2:$A$463="560048")*('2026-09-13 0954'!$D$2:$D$463="In Stock")*('2026-09-13 0954'!$E$2:$E$463<>"No"))/SUMPRODUCT(('2026-09-13 0954'!$A$2:$A$463="560048")*(('2026-09-13 0954'!$D$2:$D$463="In Stock")+('2026-09-13 0954'!$D$2:$D$463="Out of Stock"))*('2026-09-13 0954'!$E$2:$E$463<>"No")),"") | O8: =IFERROR(SUMPRODUCT(('2026-09-13 1159'!$A$2:$A$463="560048")*('2026-09-13 1159'!$D$2:$D$463="In Stock")*('2026-09-13 1159'!$E$2:$E$463<>"No"))/SUMPRODUCT(('2026-09-13 1159'!$A$2:$A$463="560048")*(('2026-09-13 1159'!$D$2:$D$463="In Stock")+('2026-09-13 1159'!$D$2:$D$463="Out of Stock"))*('2026-09-13 1159'!$E$2:$E$463<>"No")),"") | P8: =IFERROR(SUMPRODUCT(('2026-09-13 1858'!$A$2:$A$463="560048")*('2026-09-13 1858'!$D$2:$D$463="In Stock")*('2026-09-13 1858'!$E$2:$E$463<>"No"))/SUMPRODUCT(('2026-09-13 1858'!$A$2:$A$463="560048")*(('2026-09-13 1858'!$D$2:$D$463="In Stock")+('2026-09-13 1858'!$D$2:$D$463="Out of Stock"))*('2026-09-13 1858'!$E$2:$E$463<>"No")),"") | Q8: =IFERROR(SUMPRODUCT(('2026-09-14 0851'!$A$2:$A$463="560048")*('2026-09-14 0851'!$D$2:$D$463="In Stock")*('2026-09-14 0851'!$E$2:$E$463<>"No"))/SUMPRODUCT(('2026-09-14 0851'!$A$2:$A$463="560048")*(('2026-09-14 0851'!$D$2:$D$463="In Stock")+('2026-09-14 0851'!$D$2:$D$463="Out of Stock"))*('2026-09-14 0851'!$E$2:$E$463<>"No")),"")
A9: All pincodes | B9: =IFERROR(SUMPRODUCT(('2026-09-10 2147'!$D$2:$D$309="In Stock")*('2026-09-10 2147'!$E$2:$E$309<>"No"))/SUMPRODUCT((('2026-09-10 2147'!$D$2:$D$309="In Stock")+('2026-09-10 2147'!$D$2:$D$309="Out of Stock"))*('2026-09-10 2147'!$E$2:$E$309<>"No")),"") | C9: =IFERROR(SUMPRODUCT(('2026-09-11 0721'!$D$2:$D$309="In Stock")*('2026-09-11 0721'!$E$2:$E$309<>"No"))/SUMPRODUCT((('2026-09-11 0721'!$D$2:$D$309="In Stock")+('2026-09-11 0721'!$D$2:$D$309="Out of Stock"))*('2026-09-11 0721'!$E$2:$E$309<>"No")),"") | D9: =IFERROR(SUMPRODUCT(('2026-09-11 0845'!$D$2:$D$309="In Stock")*('2026-09-11 0845'!$E$2:$E$309<>"No"))/SUMPRODUCT((('2026-09-11 0845'!$D$2:$D$309="In Stock")+('2026-09-11 0845'!$D$2:$D$309="Out of Stock"))*('2026-09-11 0845'!$E$2:$E$309<>"No")),"") | E9: =IFERROR(SUMPRODUCT(('2026-09-11 1033'!$D$2:$D$155="In Stock")*('2026-09-11 1033'!$E$2:$E$155<>"No"))/SUMPRODUCT((('2026-09-11 1033'!$D$2:$D$155="In Stock")+('2026-09-11 1033'!$D$2:$D$155="Out of Stock"))*('2026-09-11 1033'!$E$2:$E$155<>"No")),"") | F9: =IFERROR(SUMPRODUCT(('2026-09-11 1201'!$D$2:$D$155="In Stock")*('2026-09-11 1201'!$E$2:$E$155<>"No"))/SUMPRODUCT((('2026-09-11 1201'!$D$2:$D$155="In Stock")+('2026-09-11 1201'!$D$2:$D$155="Out of Stock"))*('2026-09-11 1201'!$E$2:$E$155<>"No")),"") | G9: =IFERROR(SUMPRODUCT(('2026-09-11 1253'!$D$2:$D$155="In Stock")*('2026-09-11 1253'!$E$2:$E$155<>"No"))/SUMPRODUCT((('2026-09-11 1253'!$D$2:$D$155="In Stock")+('2026-09-11 1253'!$D$2:$D$155="Out of Stock"))*('2026-09-11 1253'!$E$2:$E$155<>"No")),"") | H9: =IFERROR(SUMPRODUCT(('2026-09-12 1252'!$D$2:$D$155="In Stock")*('2026-09-12 1252'!$E$2:$E$155<>"No"))/SUMPRODUCT((('2026-09-12 1252'!$D$2:$D$155="In Stock")+('2026-09-12 1252'!$D$2:$D$155="Out of Stock"))*('2026-09-12 1252'!$E$2:$E$155<>"No")),"") | I9: =IFERROR(SUMPRODUCT(('2026-09-12 1330'!$D$2:$D$155="In Stock")*('2026-09-12 1330'!$E$2:$E$155<>"No"))/SUMPRODUCT((('2026-09-12 1330'!$D$2:$D$155="In Stock")+('2026-09-12 1330'!$D$2:$D$155="Out of Stock"))*('2026-09-12 1330'!$E$2:$E$155<>"No")),"") | J9: =IFERROR(SUMPRODUCT(('2026-09-12 2141'!$D$2:$D$155="In Stock")*('2026-09-12 2141'!$E$2:$E$155<>"No"))/SUMPRODUCT((('2026-09-12 2141'!$D$2:$D$155="In Stock")+('2026-09-12 2141'!$D$2:$D$155="Out of Stock"))*('2026-09-12 2141'!$E$2:$E$155<>"No")),"") | K9: =IFERROR(SUMPRODUCT(('2026-09-12 2158'!$D$2:$D$155="In Stock")*('2026-09-12 2158'!$E$2:$E$155<>"No"))/SUMPRODUCT((('2026-09-12 2158'!$D$2:$D$155="In Stock")+('2026-09-12 2158'!$D$2:$D$155="Out of Stock"))*('2026-09-12 2158'!$E$2:$E$155<>"No")),"") | L9: =IFERROR(SUMPRODUCT(('2026-09-13 0640'!$D$2:$D$309="In Stock")*('2026-09-13 0640'!$E$2:$E$309<>"No"))/SUMPRODUCT((('2026-09-13 0640'!$D$2:$D$309="In Stock")+('2026-09-13 0640'!$D$2:$D$309="Out of Stock"))*('2026-09-13 0640'!$E$2:$E$309<>"No")),"") | M9: =IFERROR(SUMPRODUCT(('2026-09-13 0759'!$D$2:$D$463="In Stock")*('2026-09-13 0759'!$E$2:$E$463<>"No"))/SUMPRODUCT((('2026-09-13 0759'!$D$2:$D$463="In Stock")+('2026-09-13 0759'!$D$2:$D$463="Out of Stock"))*('2026-09-13 0759'!$E$2:$E$463<>"No")),"") | N9: =IFERROR(SUMPRODUCT(('2026-09-13 0954'!$D$2:$D$463="In Stock")*('2026-09-13 0954'!$E$2:$E$463<>"No"))/SUMPRODUCT((('2026-09-13 0954'!$D$2:$D$463="In Stock")+('2026-09-13 0954'!$D$2:$D$463="Out of Stock"))*('2026-09-13 0954'!$E$2:$E$463<>"No")),"") | O9: =IFERROR(SUMPRODUCT(('2026-09-13 1159'!$D$2:$D$463="In Stock")*('2026-09-13 1159'!$E$2:$E$463<>"No"))/SUMPRODUCT((('2026-09-13 1159'!$D$2:$D$463="In Stock")+('2026-09-13 1159'!$D$2:$D$463="Out of Stock"))*('2026-09-13 1159'!$E$2:$E$463<>"No")),"") | P9: =IFERROR(SUMPRODUCT(('2026-09-13 1858'!$D$2:$D$463="In Stock")*('2026-09-13 1858'!$E$2:$E$463<>"No"))/SUMPRODUCT((('2026-09-13 1858'!$D$2:$D$463="In Stock")+('2026-09-13 1858'!$D$2:$D$463="Out of Stock"))*('2026-09-13 1858'!$E$2:$E$463<>"No")),"") | Q9: =IFERROR(SUMPRODUCT(('2026-09-14 0851'!$D$2:$D$463="In Stock")*('2026-09-14 0851'!$E$2:$E$463<>"No"))/SUMPRODUCT((('2026-09-14 0851'!$D$2:$D$463="In Stock")+('2026-09-14 0851'!$D$2:$D$463="Out of Stock"))*('2026-09-14 0851'!$E$2:$E$463<>"No")),"")
A10: Not carried (excluded from the % above)
A11: Pincode | B11: 2026-09-10 21:47 | C11: 2026-09-11 07:21 | D11: 2026-09-11 08:45 | E11: 2026-09-11 10:33 | F11: 2026-09-11 12:01 | G11: 2026-09-11 12:53 | H11: 2026-09-12 12:52 | I11: 2026-09-12 13:30 | J11: 2026-09-12 21:41 | K11: 2026-09-12 21:58 | L11: 2026-09-13 06:40 | M11: 2026-09-13 07:59 | N11: 2026-09-13 09:54 | O11: 2026-09-13 11:59 | P11: 2026-09-13 18:58 | Q11: 2026-09-14 08:51
A12: 110060 | B12: =IF(SUMPRODUCT(--('2026-09-10 2147'!$A$2:$A$309="110060"))=0,"",SUMPRODUCT(('2026-09-10 2147'!$A$2:$A$309="110060")*('2026-09-10 2147'!$D$2:$D$309="Not Available")*('2026-09-10 2147'!$E$2:$E$309<>"No"))) | C12: =IF(SUMPRODUCT(--('2026-09-11 0721'!$A$2:$A$309="110060"))=0,"",SUMPRODUCT(('2026-09-11 0721'!$A$2:$A$309="110060")*('2026-09-11 0721'!$D$2:$D$309="Not Available")*('2026-09-11 0721'!$E$2:$E$309<>"No"))) | D12: =IF(SUMPRODUCT(--('2026-09-11 0845'!$A$2:$A$309="110060"))=0,"",SUMPRODUCT(('2026-09-11 0845'!$A$2:$A$309="110060")*('2026-09-11 0845'!$D$2:$D$309="Not Available")*('2026-09-11 0845'!$E$2:$E$309<>"No"))) | E12: =IF(SUMPRODUCT(--('2026-09-11 1033'!$A$2:$A$155="110060"))=0,"",SUMPRODUCT(('2026-09-11 1033'!$A$2:$A$155="110060")*('2026-09-11 1033'!$D$2:$D$155="Not Available")*('2026-09-11 1033'!$E$2:$E$155<>"No"))) | F12: =IF(SUMPRODUCT(--('2026-09-11 1201'!$A$2:$A$155="110060"))=0,"",SUMPRODUCT(('2026-09-11 1201'!$A$2:$A$155="110060")*('2026-09-11 1201'!$D$2:$D$155="Not Available")*('2026-09-11 1201'!$E$2:$E$155<>"No"))) | G12: =IF(SUMPRODUCT(--('2026-09-11 1253'!$A$2:$A$155="110060"))=0,"",SUMPRODUCT(('2026-09-11 1253'!$A$2:$A$155="110060")*('2026-09-11 1253'!$D$2:$D$155="Not Available")*('2026-09-11 1253'!$E$2:$E$155<>"No"))) | H12: =IF(SUMPRODUCT(--('2026-09-12 1252'!$A$2:$A$155="110060"))=0,"",SUMPRODUCT(('2026-09-12 1252'!$A$2:$A$155="110060")*('2026-09-12 1252'!$D$2:$D$155="Not Available")*('2026-09-12 1252'!$E$2:$E$155<>"No"))) | I12: =IF(SUMPRODUCT(--('2026-09-12 1330'!$A$2:$A$155="110060"))=0,"",SUMPRODUCT(('2026-09-12 1330'!$A$2:$A$155="110060")*('2026-09-12 1330'!$D$2:$D$155="Not Available")*('2026-09-12 1330'!$E$2:$E$155<>"No"))) | J12: =IF(SUMPRODUCT(--('2026-09-12 2141'!$A$2:$A$155="110060"))=0,"",SUMPRODUCT(('2026-09-12 2141'!$A$2:$A$155="110060")*('2026-09-12 2141'!$D$2:$D$155="Not Available")*('2026-09-12 2141'!$E$2:$E$155<>"No"))) | K12: =IF(SUMPRODUCT(--('2026-09-12 2158'!$A$2:$A$155="110060"))=0,"",SUMPRODUCT(('2026-09-12 2158'!$A$2:$A$155="110060")*('2026-09-12 2158'!$D$2:$D$155="Not Available")*('2026-09-12 2158'!$E$2:$E$155<>"No"))) | L12: =IF(SUMPRODUCT(--('2026-09-13 0640'!$A$2:$A$309="110060"))=0,"",SUMPRODUCT(('2026-09-13 0640'!$A$2:$A$309="110060")*('2026-09-13 0640'!$D$2:$D$309="Not Available")*('2026-09-13 0640'!$E$2:$E$309<>"No"))) | M12: =IF(SUMPRODUCT(--('2026-09-13 0759'!$A$2:$A$463="110060"))=0,"",SUMPRODUCT(('2026-09-13 0759'!$A$2:$A$463="110060")*('2026-09-13 0759'!$D$2:$D$463="Not Available")*('2026-09-13 0759'!$E$2:$E$463<>"No"))) | N12: =IF(SUMPRODUCT(--('2026-09-13 0954'!$A$2:$A$463="110060"))=0,"",SUMPRODUCT(('2026-09-13 0954'!$A$2:$A$463="110060")*('2026-09-13 0954'!$D$2:$D$463="Not Available")*('2026-09-13 0954'!$E$2:$E$463<>"No"))) | O12: =IF(SUMPRODUCT(--('2026-09-13 1159'!$A$2:$A$463="110060"))=0,"",SUMPRODUCT(('2026-09-13 1159'!$A$2:$A$463="110060")*('2026-09-13 1159'!$D$2:$D$463="Not Available")*('2026-09-13 1159'!$E$2:$E$463<>"No"))) | P12: =IF(SUMPRODUCT(--('2026-09-13 1858'!$A$2:$A$463="110060"))=0,"",SUMPRODUCT(('2026-09-13 1858'!$A$2:$A$463="110060")*('2026-09-13 1858'!$D$2:$D$463="Not Available")*('2026-09-13 1858'!$E$2:$E$463<>"No"))) | Q12: =IF(SUMPRODUCT(--('2026-09-14 0851'!$A$2:$A$463="110060"))=0,"",SUMPRODUCT(('2026-09-14 0851'!$A$2:$A$463="110060")*('2026-09-14 0851'!$D$2:$D$463="Not Available")*('2026-09-14 0851'!$E$2:$E$463<>"No")))
A13: 400051 | B13: =IF(SUMPRODUCT(--('2026-09-10 2147'!$A$2:$A$309="400051"))=0,"",SUMPRODUCT(('2026-09-10 2147'!$A$2:$A$309="400051")*('2026-09-10 2147'!$D$2:$D$309="Not Available")*('2026-09-10 2147'!$E$2:$E$309<>"No"))) | C13: =IF(SUMPRODUCT(--('2026-09-11 0721'!$A$2:$A$309="400051"))=0,"",SUMPRODUCT(('2026-09-11 0721'!$A$2:$A$309="400051")*('2026-09-11 0721'!$D$2:$D$309="Not Available")*('2026-09-11 0721'!$E$2:$E$309<>"No"))) | D13: =IF(SUMPRODUCT(--('2026-09-11 0845'!$A$2:$A$309="400051"))=0,"",SUMPRODUCT(('2026-09-11 0845'!$A$2:$A$309="400051")*('2026-09-11 0845'!$D$2:$D$309="Not Available")*('2026-09-11 0845'!$E$2:$E$309<>"No"))) | E13: =IF(SUMPRODUCT(--('2026-09-11 1033'!$A$2:$A$155="400051"))=0,"",SUMPRODUCT(('2026-09-11 1033'!$A$2:$A$155="400051")*('2026-09-11 1033'!$D$2:$D$155="Not Available")*('2026-09-11 1033'!$E$2:$E$155<>"No"))) | F13: =IF(SUMPRODUCT(--('2026-09-11 1201'!$A$2:$A$155="400051"))=0,"",SUMPRODUCT(('2026-09-11 1201'!$A$2:$A$155="400051")*('2026-09-11 1201'!$D$2:$D$155="Not Available")*('2026-09-11 1201'!$E$2:$E$155<>"No"))) | G13: =IF(SUMPRODUCT(--('2026-09-11 1253'!$A$2:$A$155="400051"))=0,"",SUMPRODUCT(('2026-09-11 1253'!$A$2:$A$155="400051")*('2026-09-11 1253'!$D$2:$D$155="Not Available")*('2026-09-11 1253'!$E$2:$E$155<>"No"))) | H13: =IF(SUMPRODUCT(--('2026-09-12 1252'!$A$2:$A$155="400051"))=0,"",SUMPRODUCT(('2026-09-12 1252'!$A$2:$A$155="400051")*('2026-09-12 1252'!$D$2:$D$155="Not Available")*('2026-09-12 1252'!$E$2:$E$155<>"No"))) | I13: =IF(SUMPRODUCT(--('2026-09-12 1330'!$A$2:$A$155="400051"))=0,"",SUMPRODUCT(('2026-09-12 1330'!$A$2:$A$155="400051")*('2026-09-12 1330'!$D$2:$D$155="Not Available")*('2026-09-12 1330'!$E$2:$E$155<>"No"))) | J13: =IF(SUMPRODUCT(--('2026-09-12 2141'!$A$2:$A$155="400051"))=0,"",SUMPRODUCT(('2026-09-12 2141'!$A$2:$A$155="400051")*('2026-09-12 2141'!$D$2:$D$155="Not Available")*('2026-09-12 2141'!$E$2:$E$155<>"No"))) | K13: =IF(SUMPRODUCT(--('2026-09-12 2158'!$A$2:$A$155="400051"))=0,"",SUMPRODUCT(('2026-09-12 2158'!$A$2:$A$155="400051")*('2026-09-12 2158'!$D$2:$D$155="Not Available")*('2026-09-12 2158'!$E$2:$E$155<>"No"))) | L13: =IF(SUMPRODUCT(--('2026-09-13 0640'!$A$2:$A$309="400051"))=0,"",SUMPRODUCT(('2026-09-13 0640'!$A$2:$A$309="400051")*('2026-09-13 0640'!$D$2:$D$309="Not Available")*('2026-09-13 0640'!$E$2:$E$309<>"No"))) | M13: =IF(SUMPRODUCT(--('2026-09-13 0759'!$A$2:$A$463="400051"))=0,"",SUMPRODUCT(('2026-09-13 0759'!$A$2:$A$463="400051")*('2026-09-13 0759'!$D$2:$D$463="Not Available")*('2026-09-13 0759'!$E$2:$E$463<>"No"))) | N13: =IF(SUMPRODUCT(--('2026-09-13 0954'!$A$2:$A$463="400051"))=0,"",SUMPRODUCT(('2026-09-13 0954'!$A$2:$A$463="400051")*('2026-09-13 0954'!$D$2:$D$463="Not Available")*('2026-09-13 0954'!$E$2:$E$463<>"No"))) | O13: =IF(SUMPRODUCT(--('2026-09-13 1159'!$A$2:$A$463="400051"))=0,"",SUMPRODUCT(('2026-09-13 1159'!$A$2:$A$463="400051")*('2026-09-13 1159'!$D$2:$D$463="Not Available")*('2026-09-13 1159'!$E$2:$E$463<>"No"))) | P13: =IF(SUMPRODUCT(--('2026-09-13 1858'!$A$2:$A$463="400051"))=0,"",SUMPRODUCT(('2026-09-13 1858'!$A$2:$A$463="400051")*('2026-09-13 1858'!$D$2:$D$463="Not Available")*('2026-09-13 1858'!$E$2:$E$463<>"No"))) | Q13: =IF(SUMPRODUCT(--('2026-09-14 0851'!$A$2:$A$463="400051"))=0,"",SUMPRODUCT(('2026-09-14 0851'!$A$2:$A$463="400051")*('2026-09-14 0851'!$D$2:$D$463="Not Available")*('2026-09-14 0851'!$E$2:$E$463<>"No")))
A14: 560017 | B14: =IF(SUMPRODUCT(--('2026-09-10 2147'!$A$2:$A$309="560017"))=0,"",SUMPRODUCT(('2026-09-10 2147'!$A$2:$A$309="560017")*('2026-09-10 2147'!$D$2:$D$309="Not Available")*('2026-09-10 2147'!$E$2:$E$309<>"No"))) | C14: =IF(SUMPRODUCT(--('2026-09-11 0721'!$A$2:$A$309="560017"))=0,"",SUMPRODUCT(('2026-09-11 0721'!$A$2:$A$309="560017")*('2026-09-11 0721'!$D$2:$D$309="Not Available")*('2026-09-11 0721'!$E$2:$E$309<>"No"))) | D14: =IF(SUMPRODUCT(--('2026-09-11 0845'!$A$2:$A$309="560017"))=0,"",SUMPRODUCT(('2026-09-11 0845'!$A$2:$A$309="560017")*('2026-09-11 0845'!$D$2:$D$309="Not Available")*('2026-09-11 0845'!$E$2:$E$309<>"No"))) | E14: =IF(SUMPRODUCT(--('2026-09-11 1033'!$A$2:$A$155="560017"))=0,"",SUMPRODUCT(('2026-09-11 1033'!$A$2:$A$155="560017")*('2026-09-11 1033'!$D$2:$D$155="Not Available")*('2026-09-11 1033'!$E$2:$E$155<>"No"))) | F14: =IF(SUMPRODUCT(--('2026-09-11 1201'!$A$2:$A$155="560017"))=0,"",SUMPRODUCT(('2026-09-11 1201'!$A$2:$A$155="560017")*('2026-09-11 1201'!$D$2:$D$155="Not Available")*('2026-09-11 1201'!$E$2:$E$155<>"No"))) | G14: =IF(SUMPRODUCT(--('2026-09-11 1253'!$A$2:$A$155="560017"))=0,"",SUMPRODUCT(('2026-09-11 1253'!$A$2:$A$155="560017")*('2026-09-11 1253'!$D$2:$D$155="Not Available")*('2026-09-11 1253'!$E$2:$E$155<>"No"))) | H14: =IF(SUMPRODUCT(--('2026-09-12 1252'!$A$2:$A$155="560017"))=0,"",SUMPRODUCT(('2026-09-12 1252'!$A$2:$A$155="560017")*('2026-09-12 1252'!$D$2:$D$155="Not Available")*('2026-09-12 1252'!$E$2:$E$155<>"No"))) | I14: =IF(SUMPRODUCT(--('2026-09-12 1330'!$A$2:$A$155="560017"))=0,"",SUMPRODUCT(('2026-09-12 1330'!$A$2:$A$155="560017")*('2026-09-12 1330'!$D$2:$D$155="Not Available")*('2026-09-12 1330'!$E$2:$E$155<>"No"))) | J14: =IF(SUMPRODUCT(--('2026-09-12 2141'!$A$2:$A$155="560017"))=0,"",SUMPRODUCT(('2026-09-12 2141'!$A$2:$A$155="560017")*('2026-09-12 2141'!$D$2:$D$155="Not Available")*('2026-09-12 2141'!$E$2:$E$155<>"No"))) | K14: =IF(SUMPRODUCT(--('2026-09-12 2158'!$A$2:$A$155="560017"))=0,"",SUMPRODUCT(('2026-09-12 2158'!$A$2:$A$155="560017")*('2026-09-12 2158'!$D$2:$D$155="Not Available")*('2026-09-12 2158'!$E$2:$E$155<>"No"))) | L14: =IF(SUMPRODUCT(--('2026-09-13 0640'!$A$2:$A$309="560017"))=0,"",SUMPRODUCT(('2026-09-13 0640'!$A$2:$A$309="560017")*('2026-09-13 0640'!$D$2:$D$309="Not Available")*('2026-09-13 0640'!$E$2:$E$309<>"No"))) | M14: =IF(SUMPRODUCT(--('2026-09-13 0759'!$A$2:$A$463="560017"))=0,"",SUMPRODUCT(('2026-09-13 0759'!$A$2:$A$463="560017")*('2026-09-13 0759'!$D$2:$D$463="Not Available")*('2026-09-13 0759'!$E$2:$E$463<>"No"))) | N14: =IF(SUMPRODUCT(--('2026-09-13 0954'!$A$2:$A$463="560017"))=0,"",SUMPRODUCT(('2026-09-13 0954'!$A$2:$A$463="560017")*('2026-09-13 0954'!$D$2:$D$463="Not Available")*('2026-09-13 0954'!$E$2:$E$463<>"No"))) | O14: =IF(SUMPRODUCT(--('2026-09-13 1159'!$A$2:$A$463="560017"))=0,"",SUMPRODUCT(('2026-09-13 1159'!$A$2:$A$463="560017")*('2026-09-13 1159'!$D$2:$D$463="Not Available")*('2026-09-13 1159'!$E$2:$E$463<>"No"))) | P14: =IF(SUMPRODUCT(--('2026-09-13 1858'!$A$2:$A$463="560017"))=0,"",SUMPRODUCT(('2026-09-13 1858'!$A$2:$A$463="560017")*('2026-09-13 1858'!$D$2:$D$463="Not Available")*('2026-09-13 1858'!$E$2:$E$463<>"No"))) | Q14: =IF(SUMPRODUCT(--('2026-09-14 0851'!$A$2:$A$463="560017"))=0,"",SUMPRODUCT(('2026-09-14 0851'!$A$2:$A$463="560017")*('2026-09-14 0851'!$D$2:$D$463="Not Available")*('2026-09-14 0851'!$E$2:$E$463<>"No")))
A15: 560048 | B15: =IF(SUMPRODUCT(--('2026-09-10 2147'!$A$2:$A$309="560048"))=0,"",SUMPRODUCT(('2026-09-10 2147'!$A$2:$A$309="560048")*('2026-09-10 2147'!$D$2:$D$309="Not Available")*('2026-09-10 2147'!$E$2:$E$309<>"No"))) | C15: =IF(SUMPRODUCT(--('2026-09-11 0721'!$A$2:$A$309="560048"))=0,"",SUMPRODUCT(('2026-09-11 0721'!$A$2:$A$309="560048")*('2026-09-11 0721'!$D$2:$D$309="Not Available")*('2026-09-11 0721'!$E$2:$E$309<>"No"))) | D15: =IF(SUMPRODUCT(--('2026-09-11 0845'!$A$2:$A$309="560048"))=0,"",SUMPRODUCT(('2026-09-11 0845'!$A$2:$A$309="560048")*('2026-09-11 0845'!$D$2:$D$309="Not Available")*('2026-09-11 0845'!$E$2:$E$309<>"No"))) | E15: =IF(SUMPRODUCT(--('2026-09-11 1033'!$A$2:$A$155="560048"))=0,"",SUMPRODUCT(('2026-09-11 1033'!$A$2:$A$155="560048")*('2026-09-11 1033'!$D$2:$D$155="Not Available")*('2026-09-11 1033'!$E$2:$E$155<>"No"))) | F15: =IF(SUMPRODUCT(--('2026-09-11 1201'!$A$2:$A$155="560048"))=0,"",SUMPRODUCT(('2026-09-11 1201'!$A$2:$A$155="560048")*('2026-09-11 1201'!$D$2:$D$155="Not Available")*('2026-09-11 1201'!$E$2:$E$155<>"No"))) | G15: =IF(SUMPRODUCT(--('2026-09-11 1253'!$A$2:$A$155="560048"))=0,"",SUMPRODUCT(('2026-09-11 1253'!$A$2:$A$155="560048")*('2026-09-11 1253'!$D$2:$D$155="Not Available")*('2026-09-11 1253'!$E$2:$E$155<>"No"))) | H15: =IF(SUMPRODUCT(--('2026-09-12 1252'!$A$2:$A$155="560048"))=0,"",SUMPRODUCT(('2026-09-12 1252'!$A$2:$A$155="560048")*('2026-09-12 1252'!$D$2:$D$155="Not Available")*('2026-09-12 1252'!$E$2:$E$155<>"No"))) | I15: =IF(SUMPRODUCT(--('2026-09-12 1330'!$A$2:$A$155="560048"))=0,"",SUMPRODUCT(('2026-09-12 1330'!$A$2:$A$155="560048")*('2026-09-12 1330'!$D$2:$D$155="Not Available")*('2026-09-12 1330'!$E$2:$E$155<>"No"))) | J15: =IF(SUMPRODUCT(--('2026-09-12 2141'!$A$2:$A$155="560048"))=0,"",SUMPRODUCT(('2026-09-12 2141'!$A$2:$A$155="560048")*('2026-09-12 2141'!$D$2:$D$155="Not Available")*('2026-09-12 2141'!$E$2:$E$155<>"No"))) | K15: =IF(SUMPRODUCT(--('2026-09-12 2158'!$A$2:$A$155="560048"))=0,"",SUMPRODUCT(('2026-09-12 2158'!$A$2:$A$155="560048")*('2026-09-12 2158'!$D$2:$D$155="Not Available")*('2026-09-12 2158'!$E$2:$E$155<>"No"))) | L15: =IF(SUMPRODUCT(--('2026-09-13 0640'!$A$2:$A$309="560048"))=0,"",SUMPRODUCT(('2026-09-13 0640'!$A$2:$A$309="560048")*('2026-09-13 0640'!$D$2:$D$309="Not Available")*('2026-09-13 0640'!$E$2:$E$309<>"No"))) | M15: =IF(SUMPRODUCT(--('2026-09-13 0759'!$A$2:$A$463="560048"))=0,"",SUMPRODUCT(('2026-09-13 0759'!$A$2:$A$463="560048")*('2026-09-13 0759'!$D$2:$D$463="Not Available")*('2026-09-13 0759'!$E$2:$E$463<>"No"))) | N15: =IF(SUMPRODUCT(--('2026-09-13 0954'!$A$2:$A$463="560048"))=0,"",SUMPRODUCT(('2026-09-13 0954'!$A$2:$A$463="560048")*('2026-09-13 0954'!$D$2:$D$463="Not Available")*('2026-09-13 0954'!$E$2:$E$463<>"No"))) | O15: =IF(SUMPRODUCT(--('2026-09-13 1159'!$A$2:$A$463="560048"))=0,"",SUMPRODUCT(('2026-09-13 1159'!$A$2:$A$463="560048")*('2026-09-13 1159'!$D$2:$D$463="Not Available")*('2026-09-13 1159'!$E$2:$E$463<>"No"))) | P15: =IF(SUMPRODUCT(--('2026-09-13 1858'!$A$2:$A$463="560048"))=0,"",SUMPRODUCT(('2026-09-13 1858'!$A$2:$A$463="560048")*('2026-09-13 1858'!$D$2:$D$463="Not Available")*('2026-09-13 1858'!$E$2:$E$463<>"No"))) | Q15: =IF(SUMPRODUCT(--('2026-09-14 0851'!$A$2:$A$463="560048"))=0,"",SUMPRODUCT(('2026-09-14 0851'!$A$2:$A$463="560048")*('2026-09-14 0851'!$D$2:$D$463="Not Available")*('2026-09-14 0851'!$E$2:$E$463<>"No")))
A16: All pincodes | B16: =SUMPRODUCT(('2026-09-10 2147'!$D$2:$D$309="Not Available")*('2026-09-10 2147'!$E$2:$E$309<>"No")) | C16: =SUMPRODUCT(('2026-09-11 0721'!$D$2:$D$309="Not Available")*('2026-09-11 0721'!$E$2:$E$309<>"No")) | D16: =SUMPRODUCT(('2026-09-11 0845'!$D$2:$D$309="Not Available")*('2026-09-11 0845'!$E$2:$E$309<>"No")) | E16: =SUMPRODUCT(('2026-09-11 1033'!$D$2:$D$155="Not Available")*('2026-09-11 1033'!$E$2:$E$155<>"No")) | F16: =SUMPRODUCT(('2026-09-11 1201'!$D$2:$D$155="Not Available")*('2026-09-11 1201'!$E$2:$E$155<>"No")) | G16: =SUMPRODUCT(('2026-09-11 1253'!$D$2:$D$155="Not Available")*('2026-09-11 1253'!$E$2:$E$155<>"No")) | H16: =SUMPRODUCT(('2026-09-12 1252'!$D$2:$D$155="Not Available")*('2026-09-12 1252'!$E$2:$E$155<>"No")) | I16: =SUMPRODUCT(('2026-09-12 1330'!$D$2:$D$155="Not Available")*('2026-09-12 1330'!$E$2:$E$155<>"No")) | J16: =SUMPRODUCT(('2026-09-12 2141'!$D$2:$D$155="Not Available")*('2026-09-12 2141'!$E$2:$E$155<>"No")) | K16: =SUMPRODUCT(('2026-09-12 2158'!$D$2:$D$155="Not Available")*('2026-09-12 2158'!$E$2:$E$155<>"No")) | L16: =SUMPRODUCT(('2026-09-13 0640'!$D$2:$D$309="Not Available")*('2026-09-13 0640'!$E$2:$E$309<>"No")) | M16: =SUMPRODUCT(('2026-09-13 0759'!$D$2:$D$463="Not Available")*('2026-09-13 0759'!$E$2:$E$463<>"No")) | N16: =SUMPRODUCT(('2026-09-13 0954'!$D$2:$D$463="Not Available")*('2026-09-13 0954'!$E$2:$E$463<>"No")) | O16: =SUMPRODUCT(('2026-09-13 1159'!$D$2:$D$463="Not Available")*('2026-09-13 1159'!$E$2:$E$463<>"No")) | P16: =SUMPRODUCT(('2026-09-13 1858'!$D$2:$D$463="Not Available")*('2026-09-13 1858'!$E$2:$E$463<>"No")) | Q16: =SUMPRODUCT(('2026-09-14 0851'!$D$2:$D$463="Not Available")*('2026-09-14 0851'!$E$2:$E$463<>"No"))

Sheet 2026-09-10 2147
A1: Pincode | B1: Item | C1: ProductName | D1: is_out_of_stock | E1: Serviceable | F1: Quantity | G1: Base_Final quantity | H1: Base_Final unit | I1: Segment | J1: Grocery | K1: National / PL | L1: Product_Link | M1: Backup_Links | N1: Price | O1: MRP | P1: XtraSaverPrice | Q1: Weight | R1: Volume | S1: Seller | T1: StoreId | U1: Final_Qty | V1: Final_unit | W1: Pincode_Used | X1: Used_Link | Y1: Captured_At
A2: 400051 | B2: Aashirvaad Select | Pure MP Sharbati Wheat Atta for Soft Makhmali Rotis | C2: Superior MP Atta | D2: In Stock | F2: 5 kg | G2: 5000 | H2: g | I2: Atta, Rice & Dal | J2: Atta | L2: https://www.flipkart.com/aashirvaad-superior-mp-atta/p/itmevbgvupx4gqxb?pid=FLREUC5PSFQUBHTC&marketplace=HYPERLOCAL | N2: 257 | O2: 314 | Q2: 5 kg | S2: AASHIRVAAD | T2: mum_187_wh_hl_01 | U2: 5000 | V2: g | W2: 400051 | Y2: 2026-09-10 21:48:06
A3: 400051 | B3: Fortune Chakki Fresh Atta | C3: Chakki Fresh Atta | D3: In Stock | F3: 5 kg | G3: 5000 | H3: g | I3: Atta, Rice & Dal | J3: Atta | L3: https://www.flipkart.com/fortune-chakki-fresh-atta/p/itmf8zjux3v4utqz?pid=FLRF8ZJU5KHYVCDC&marketplace=HYPERLOCAL | N3: 220 | O3: 277 | Q3: 5 kg | S3: FORTUNE | T3: mum_187_wh_hl_01 | U3: 5000 | V3: g | W3: 400051 | Y3: 2026-09-10 21:48:07
A4: 400051 | B4: Fortune 100% Chana Dal Besan | C4: Copy Link | D4: In Stock | F4: 1 kg | G4: 1000 | H4: g | I4: Atta, Rice & Dal | J4: Besan, Sooji & Maida | L4: https://www.flipkart.com/fortune-besan/p/itmetefhhdrhpfge?pid=FLRETEFHZHCFSEDD&marketplace=HYPERLOCAL | N4: 118 | O4: 169 | P4: 116 | Q4: 1 kg | S4: FORTUNE | T4: mum_187_wh_hl_01 | U4: 1000 | V4: g | W4: 400051 | Y4: 2026-09-10 21:48:09
A5: 400051 | B5: Rajdhani Sooji/Rava | C5: Copy Link | D5: In Stock | F5: 1 kg | G5: 1000 | H5: g | I5: Atta, Rice & Dal | J5: Besan, Sooji & Maida | L5: https://www.flipkart.com/rajdhani-sooji/p/itmf6yfkzqrf9twn?pid=FLRF6YFKKQ39F9MZ&marketplace=HYPERLOCAL | N5: 74 | O5: 98 | Q5: 1 kg | S5: Rajdhani | T5: mum_187_wh_hl_01 | U5: 1000 | V5: g | W5: 400051 | Y5: 2026-09-10 21:48:10
A6: 400051 | B6: Tata Sampann Unpolished Masoor Dal | C6: Copy Link | D6: In Stock | F6: 500 g | G6: 500 | H6: g | I6: Atta, Rice & Dal | J6: Moong & Masoor | L6: https://www.flipkart.com/tata-sampann-unpolished-red-masoor-dal-whole/p/itmb8901742a9e80?pid=PLSEUHQJGDGFGFQC&marketplace=HYPERLOCAL | N6: 76 | O6: 79 | P6: 74 | Q6: 500 g | S6: Tata Sampann | T6: mum_187_wh_hl_01 | U6: 500 | V6: g | W6: 400051 | Y6: 2026-09-10 21:48:12
A7: 400051 | B7: Tata Sampann Unpolished Organic Moong Sabut | C7: Unpolished Yellow Moong Dal (Split) | D7: In Stock | F7: 1 kg | G7: 1000 | H7: g | I7: Atta, Rice & Dal | J7: Moong & Masoor | L7: https://www.flipkart.com/tata-sampann-organic-unpolished-yellow-moong-dal-split/p/itmc58d782587d5f?pid=PLSF8GXG5GGPFCZH&marketplace=HYPERLOCAL | N7: 121 | O7: 140 | P7: 118 | Q7: 500 g | S7: Tata Sampann Organic | T7: mum_187_wh_hl_01 | U7: 500 | V7: g | W7: 400051 | Y7: 2026-09-10 21:48:14
A8: 400051 | B8: Nutrela Soya Mini Chunks | C8: Soya Chunks | D8: In Stock | F8: 200 g | G8: 200 | H8: g | I8: Atta, Rice & Dal | J8: Rajma, Chhole & Others | L8: https://www.flipkart.com/nutrela-soya-chunks/p/itm4e39c268eb367?pid=SYCG9G85AEWQJBKP&marketplace=HYPERLOCAL | N8: 137 | O8: 190 | Q8: 1 kg | S8: NUTRELA | T8: mum_187_wh_hl_01 | U8: 1000 | V8: g | W8: 400051 | Y8: 2026-09-10 21:48:15
A9: 400051 | B9: Tata Sampann Unpolished Kabuli Chana (Big Size) | C9: Unpolished Kabuli Chana | D9: In Stock | F9: 500 g | G9: 500 | H9: g | I9: Atta, Rice & Dal | J9: Rajma, Chhole & Others | L9: https://www.flipkart.com/tata-sampann-unpolished-kabuli-chana/p/itm210199349460e?pid=PLSGHKPK5EWUDFNS&marketplace=HYPERLOCAL | N9: 162 | O9: 168 | Q9: 1 kg | S9: Tata Sampann | T9: mum_187_wh_hl_01 | U9: 1000 | V9: g | W9: 400051 | Y9: 2026-09-10 21:48:17
A10: 400051 | B10: Tata Sampann Unpolished Rajma | C10: Copy Link | D10: In Stock | F10: 500 g | G10: 500 | H10: g | I10: Atta, Rice & Dal | J10: Rajma, Chhole & Others | L10: https://www.flipkart.com/rajdhani-unpolished-kashmiri-rajma/p/itme0c53828d1ebf?pid=PLSF6Y2DWKB5NAMU&marketplace=HYPERLOCAL | N10: 76 | O10: 112 | P10: 74 | Q10: 500 g | S10: Rajdhani | T10: mum_187_wh_hl_01 | U10: 500 | V10: g | W10: 400051 | Y10: 2026-09-10 21:48:19
A11: 400051 | B11: Daawat Super Basmati Rice (Long Grain) | C11: Copy Link | D11: In Stock | F11: 5 kg | G11: 5000 | H11: g | I11: Atta, Rice & Dal | J11: Rice | L11: https://www.flipkart.com/daawat-super-basmati-rice-long-grain/p/itm5e7f4d650da77?pid=RICEUC2YGH9ZBNEH&marketplace=HYPERLOCAL | N11: 832 | O11: 995 | P11: 748 | Q11: 5 kg | S11: Daawat | T11: mum_187_wh_hl_01 | U11: 5000 | V11: g | W11: 400051 | Y11: 2026-09-10 21:48:20
A12: 400051 | B12: India Gate Daily Premium Basmati Rice (Long Grain) | C12: Copy Link | D12: In Stock | F12: 5 kg | G12: 5000 | H12: g | I12: Atta, Rice & Dal | J12: Rice | L12: https://www.flipkart.com/india-gate-flavourful-fine-daily-premium-long-slender-grains-naturally-aged-basmati-rice-long-grain-polished/p/itm4e4c0ed865572?pid=RICGGJZYTF4DW3VB&marketplace=HYPERLOCAL | N12: 528 | O12: 680 | P12: 522 | Q12: 5 kg | S12: INDIA GATE | T12: mum_187_wh_hl_01 | U12: 5000 | V12: g | W12: 400051 | Y12: 2026-09-10 21:48:22
A13: 400051 | B13: Tata Sampann Unpolished Chana Dal | C13: Unpolished Yellow Chana Dal (Split) | D13: In Stock | F13: 500 g | G13: 500 | H13: g | I13: Atta, Rice & Dal | J13: Toor, Urad & Chana | L13: https://www.flipkart.com/tata-sampann-unpolished-yellow-chana-dal-split/p/itm549c1ab20445b?pid=PLSETEHFG2EY2UCQ&marketplace=HYPERLOCAL | N13: 71 | O13: 81 | P13: 68 | Q13: 500 g | S13: Tata Sampann | T13: mum_187_wh_hl_01 | U13: 500 | V13: g | W13: 400051 | Y13: 2026-09-10 21:48:24
A14: 400051 | B14: Tata Sampann Unpolished Toor Dal | C14: Unpolished Yellow Toor/Arhar Dal | D14: In Stock | F14: 2 kg | G14: 2000 | H14: g | I14: Atta, Rice & Dal | J14: Toor, Urad & Chana | L14: https://www.flipkart.com/tata-sampann-unpolished-yellow-toor-arhar-dal/p/itmed34edd39d2e9?pid=PLSG93HVZF2ERNWR&marketplace=HYPERLOCAL | N14: 339 | O14: 448 | Q14: 2 kg | S14: Tata Sampann | T14: mum_187_wh_hl_01 | U14: 2000 | V14: g | W14: 400051 | Y14: 2026-09-10 21:48:26
A15: 400051 | B15: Nestle Cerelac Wheat Apple Baby Cereal (6 - 24 Months) | C15: Copy Link | D15: In Stock | F15: 350 g | G15: 350 | H15: g | I15: Baby Care | J15: Baby Food | L15: https://www.flipkart.com/nestle-cerelac-wheat-apple-baby-food-cereal-no-preservatives/p/itmb753364d0fd30?pid=INFETZV5GYZ6Q9FW&marketplace=HYPERLOCAL | N15: 260 | O15: 260 | Q15: 350 g | S15: Nestle Cerelac | T15: mum_187_wh_hl_01 | U15: 350 | V15: g | W15: 400051 | Y15: 2026-09-10 21:48:28
A16: 400051 | B16: Himalaya Gentle Baby Wipes | C16: Copy Link | D16: In Stock | F16: 2 x 72 wipes | G16: 144 | H16: pcs | I16: Baby Care | J16: Baby Wipes | L16: https://www.flipkart.com/johnson-s-baby-skincare-wipes-72s/p/itm85e9b2b25d29c?pid=WIPDAJ2MZYF564HG&marketplace=HYPERLOCAL | N16: 241 | O16: 280 | P16: 236 | Q16: 72 Wipes | S16: JOHNSON'S | T16: mum_187_wh_hl_01 | W16: 400051 | Y16: 2026-09-10 21:48:29
A17: 400051 | B17: Johnson's Baby Soap | C17: Copy Link | D17: In Stock | F17: 3 pcs | G17: 3 | H17: pcs | I17: Baby Care | J17: Bathing Needs | L17: https://www.flipkart.com/himalaya-extra-moisturizing-baby-soap-dry-skin-b3g1-free-75g-helps-lock-moisture/p/itmc8f1ec744e790?pid=SOPEUBZRWAGG5NR8&marketplace=HYPERLOCAL | N17: 141 | O17: 195 | P17: 138 | Q17: 3x100 g | S17: HIMALAYA | T17: mum_187_wh_hl_01 | U17: 300 | V17: g | W17: 400051 | Y17: 2026-09-10 21:48:31
A18: 400051 | B18: Pampers Happy Sleep Pant Style Baby Diaper (M) | C18: Happy Sleep Anti Rash Shield Pant Diapers - M | D18: In Stock | F18: 48 pcs | G18: 48 | H18: pcs | I18: Baby Care | J18: Diapers & More | L18: https://www.flipkart.com/pampers-happy-sleep-anti-rash-shield-m/p/itm24477fbc6c3c2?pid=DPRH3SCGZZWJQZ5M&marketplace=HYPERLOCAL | N18: 508 | O18: 609 | P18: 457 | Q18: M | 48 Pcs | S18: Pampers | T18: mum_187_wh_hl_01 | W18: 400051 | Y18: 2026-09-10 21:48:33
A19: 400051 | B19: Johnson's Baby Lotion | C19: All Day Long Baby Lotion | D19: In Stock | F19: 200 ml | G19: 200 | H19: ml | I19: Baby Care | J19: Skin & Hair Care | L19: https://www.flipkart.com/johnson-s-all-day-long-baby-lotion/p/itmf9rb3byqhwfcr?pid=MSCF6SWQ6DNGZ3AH&marketplace=HYPERLOCAL | N19: 379 | O19: 475 | P19: 371 | Q19: 500 ml | S19: JOHNSON'S | T19: mum_187_wh_hl_01 | U19: 500 | V19: ml | W19: 400051 | Y19: 2026-09-10 21:48:35
A20: 400051 | B20: Weikfield Double Action Baking Powder | C20: Copy Link | D20: In Stock | F20: 100 g | G20: 100 | H20: g | I20: Bakery & Biscuits | J20: Baking Ingredients | L20: https://www.flipkart.com/weikfield-baking-powder-100-double-action-fluppy-cakes-cookies-powder/p/itmew5z7ujzcpyje?pid=BKIEUHNZXUWBHJ2W&marketplace=HYPERLOCAL | N20: 38 | O20: 40 | P20: 36 | Q20: 100 g | S20: WeiKFiELD | T20: mum_187_wh_hl_01 | U20: 100 | V20: g | W20: 400051 | Y20: 2026-09-10 21:48:36
A21: 400051 | B21: Lotte Choco Pie | C21: Copy Link | D21: In Stock | F21: 168 g | G21: 168 | H21: g | I21: Bakery & Biscuits | J21: Cakes & Rolls | L21: https://www.flipkart.com/lotte-choco-pie-soft-biscuits-coated-premium-chocolate-cream-sandwich-biscuit/p/itm600e9df6b15a2?pid=CKBEUARSF4EKDX2U&marketplace=HYPERLOCAL | N21: 139 | O21: 180 | P21: 136 | Q21: 336 g | S21: Lotte | T21: mum_187_wh_hl_01 | U21: 336 | V21: g | W21: 400051 | Y21: 2026-09-10 21:48:38
A22: 400051 | B22: Britannia Original Bourbon Creme Biscuit | C22: Copy Link | D22: In Stock | F22: 150 g | G22: 150 | H22: g | I22: Bakery & Biscuits | J22: Cookies | L22: https://www.flipkart.com/britannia-treat-bourbon-biscuits-cream-sandwich-biscuit/p/itmd5423e0a84931?pid=CKBG7BHRWSR3AHZW&marketplace=HYPERLOCAL | N22: 10 | O22: 10 | Q22: 50 g | S22: BRITANNIA | T22: mum_187_wh_hl_01 | U22: 50 | V22: g | W22: 400051 | Y22: 2026-09-10 21:48:40
A23: 400051 | B23: Britannia Good Day Cashew Biscuit | C23: Copy Link | D23: In Stock | F23: 200 g | G23: 200 | H23: g | I23: Bakery & Biscuits | J23: Cookies | L23: https://www.flipkart.com/britannia-good-day-cashew-cookies/p/itmb56a4a28a3424?pid=CKBET6WUZUR9PUSR&marketplace=HYPERLOCAL | N23: 43 | O23: 45 | Q23: 200 g | S23: BRITANNIA | T23: mum_187_wh_hl_01 | U23: 200 | V23: g | W23: 400051 | Y23: 2026-09-10 21:48:42
A24: 400051 | B24: Malkist Cheese Flavoured Cracker Biscuit - Family Pack | C24: Copy Link | D24: Out of Stock | F24: 144 g | G24: 144 | H24: g | I24: Bakery & Biscuits | J24: Cream Biscuits | L24: https://www.flipkart.com/malkist-cheese-cream-cracker-biscuit/p/itm2ff267d048c58?pid=CKBFT7N3QQG8NVZZ&marketplace=HYPERLOCAL | N24: 57 | O24: 60 | P24: 55 | Q24: 144 g | S24: Malkist | T24: mum_187_wh_hl_01 | U24: 144 | V24: g | W24: 400051 | Y24: 2026-09-10 21:48:44
A25: 400051 | B25: Britannia Marie Gold Marie Biscuits (208 g) | C25: Copy Link | D25: In Stock | F25: 208 g | G25: 208 | H25: g | I25: Bakery & Biscuits | J25: Glucose & Marie | L25: https://www.flipkart.com/britannia-vita-gold-marie-biscuit/p/itm5b8071bd3b51b?pid=CKBET6WVSMK7UFHE&marketplace=HYPERLOCAL | N25: 38 | O25: 45 | Q25: 248 g | S25: BRITANNIA | T25: mum_187_wh_hl_01 | U25: 248 | V25: g | W25: 400051 | Y25: 2026-09-10 21:48:45
A26: 400051 | B26: Britannia NutriChoice Digestive High Fibre Biscuit - 250 g Family Pack | C26: Gold Marie Biscuit | D26: In Stock | F26: 250 g | G26: 250 | H26: g | I26: Bakery & Biscuits | J26: Healthy & Digestive | L26: https://www.flipkart.com/britannia-gold-marie-biscuit/p/itm353dd93c372d2?pid=CKBET6WU3CEGCYV2&marketplace=HYPERLOCAL | N26: 38 | O26: 40 | Q26: 250 g | S26: BRITANNIA | T26: mum_187_wh_hl_01 | U26: 250 | V26: g | W26: 400051 | Y26: 2026-09-10 21:48:47
A27: 400051 | B27: McVitie's Digestive High Fibre Biscuit | C27: Copy Link | D27: Out of Stock | F27: 959.1 g | G27: 959.1 | H27: g | I27: Bakery & Biscuits | J27: Healthy & Digestive | L27: https://www.flipkart.com/mcvitie-s-high-fibre-biscuits-trans-fat-free-digestive-biscuit/p/itmd3de9538585f5?pid=CKBGVZFJNBTRRJPH&marketplace=HYPERLOCAL | N27: 0 | O27: 0 | S27: McVitie's | W27: 400051 | Y27: 2026-09-10 21:48:49
A28: 400051 | B28: Nivea Nourishing Body Lotion | C28: Body Lotion for Very Dry Skin, Nourishing Body Milk with 2x Almond Oil, For Men & Women | D28: In Stock | F28: 600 ml | G28: 600 | H28: ml | I28: Beauty & Cosmetics | J28: Body & Skin Care | L28: https://www.flipkart.com/nivea-body-lotion-very-dry-skin-nourishing-milk-2x-almond-oil-men-women/p/itmfa397ef11314a?pid=MSCET7YRBUNFUGV2&marketplace=HYPERLOCAL | N28: 110 | O28: 130 | P28: 107 | Q28: 120 ml | S28: NIVEA | T28: mum_187_wh_hl_01 | U28: 120 | V28: ml | W28: 400051 | Y28: 2026-09-10 21:48:50
A29: 400051 | B29: Maybelline New York Colossal Kajal (Deep Black) | C29: Copy Link | D29: In Stock | F29: 0.35 g | G29: 0.35 | H29: g | I29: Beauty & Cosmetics | J29: Eye Makeup | L29: https://www.flipkart.com/maybelline-new-york-colossal-kajal/p/itm689854fb6af5f?pid=KJLE2DAJUF7KADCQ&marketplace=HYPERLOCAL | N29: 150 | O29: 220 | Q29: Black | S29: MAYBELLINE NEW YORK | T29: mum_187_wh_hl_01 | W29: 400051 | Y29: 2026-09-10 21:48:52
A30: 400051 | B30: Pond's Bright Beauty Serum Skin Treatment Cream 34 g | F30: 35 g | G30: 35 | H30: g | I30: Beauty & Cosmetics | J30: Face Care
A31: 400051 | B31: Lakme Forever Matte Compact (Pearl) | C31: Copy Link | D31: In Stock | F31: 9 g | G31: 9 | H31: g | I31: Beauty & Cosmetics | J31: Face Cosmetics | L31: https://www.flipkart.com/lakm-forever-matte-compact/p/itm70a5e612ec622?pid=CMPG5K3DYPJBSZK3&marketplace=HYPERLOCAL | N31: 206 | O31: 245 | P31: 201 | S31: Lakmé | T31: mum_187_wh_hl_01 | W31: 400051 | Y31: 2026-09-10 21:48:54
A32: 400051 | B32: Livon Anti-Frizz Hair Serum | C32: Hair Serum,For Dry & Frizzy Hair, Provides shine, smoothness & damage protection | D32: In Stock | F32: 50 ml | G32: 50 | H32: ml | I32: Beauty & Cosmetics | J32: Hair Styling & Treatment | L32: https://www.flipkart.com/livon-hair-serum-for-dry-frizzy-hair-provides-shine-smoothness-damage-protection/p/itm46b51dbec7c99?pid=HSMDDAZEGXVQ2PD4&marketplace=HYPERLOCAL | N32: 203 | O32: 350 | P32: 198 | Q32: 100 ml | S32: LIVON | T32: mum_187_wh_hl_01 | U32: 100 | V32: ml | W32: 400051 | Y32: 2026-09-10 21:48:56
A33: 400051 | B33: Nivea Essential Care Lip Balm | C33: Essential Original Care Lip Balm Natural | D33: In Stock | F33: 4.8 g | G33: 4.8 | H33: g | I33: Beauty & Cosmetics | J33: Lip & Eye Care | L33: https://www.flipkart.com/nivea-care-natural/p/itmet5uxkbysnrjr?pid=LPBET5UXDPYZQH6Z&marketplace=HYPERLOCAL | N33: 138 | O33: 175 | P33: 135 | S33: NIVEA | T33: mum_187_wh_hl_01 | W33: 400051 | Y33: 2026-09-10 21:48:57
A34: 400051 | B34: Lakme 9To5 Hya Matte Lipstick (Workday Rose) | C34: Copy Link | D34: Out of Stock | F34: 3.6 g | G34: 3.6 | H34: g | I34: Beauty & Cosmetics | J34: Lip Cosmetics | L34: https://www.flipkart.com/lakm-9to5-primer-matte-lip-color/p/itmc921adcfbfd56?pid=LSKFX4KERQHZ8KCT&marketplace=HYPERLOCAL | N34: 483 | O34: 650 | P34: 473 | Q34: MR5 Berry Base | S34: Lakmé | T34: mum_187_wh_hl_01 | W34: 400051 | Y34: 2026-09-10 21:48:59
A35: 400051 | B35: Lakme Nail Paint Remover | C35: Copy Link | D35: In Stock | F35: 27 ml | G35: 27 | H35: ml | I35: Beauty & Cosmetics | J35: Nail Cosmetics | L35: https://www.flipkart.com/lakm-liquid-nail-polish-remover-vitamin-e-27ml/p/itm483b1bf92a749?pid=NPRGXQC9B6M7URE2&marketplace=HYPERLOCAL | N35: 96 | O35: 110 | P35: 94 | S35: Lakmé | T35: mum_187_wh_hl_01 | W35: 400051 | Y35: 2026-09-10 21:49:01
A36: 400051 | B36: Licious Chicken Curry Cut (Small Pieces) | C36: Copy Link | D36: Out of Stock | F36: 450 g | G36: 450 | H36: g | I36: Chicken, Meat & Fish | J36: Fresh Meat | L36: https://www.flipkart.com/licious-chicken-curry-cut-large-pcs/p/itm3babb9d82c00e?pid=MEAFSCBFTHQK8S42&marketplace=HYPERLOCAL | N36: 0 | O36: 0 | S36: Licious | W36: 400051 | Y36: 2026-09-10 21:49:02
A37: 400051 | B37: Surf Excel Easy Wash Detergent Powder | C37: Easy Wash Detergent Powder | D37: In Stock | F37: 1 kg | G37: 1000 | H37: g | I37: Cleaning Essentials | J37: Detergent Powder & Bars | L37: https://www.flipkart.com/surf-excel-easy-wash-detergent-powder/p/itm2ebbcc2dd9963?pid=LDTET5UDBXDFKWAZ&marketplace=HYPERLOCAL | N37: 80 | O37: 85 | Q37: 500 g | S37: Surf excel | T37: mum_187_wh_hl_01 | U37: 500 | V37: g | W37: 400051 | Y37: 2026-09-10 21:49:05
A38: 400051 | B38: Scotch Brite Scrub Pad | C38: Copy Link | D38: In Stock | F38: 5 pcs | G38: 5 | H38: pcs | I38: Cleaning Essentials | J38: Dishwashing Accessories | L38: https://www.flipkart.com/scotch-brite-super-strong7x10-cm-scrub-pad/p/itmbf74cb7a4cce7?pid=SRPGREGHT3BHJHFH&marketplace=HYPERLOCAL | N38: 32 | O38: 45 | P38: 30 | Q38: Pack of 1 | S38: Scotch-Brite | T38: mum_187_wh_hl_01 | W38: 400051 | Y38: 2026-09-10 21:49:07
A39: 400051 | B39: Vim Lemon Dishwash Bar (300 g) | C39: Dishwash Bar | D39: In Stock | F39: 300 g | G39: 300 | H39: g | I39: Cleaning Essentials | J39: Dishwashing Bars & Tubs | L39: https://www.flipkart.com/vim-dishwash-bar/p/itmew7uegahfruem?pid=DWBEU6M6WTGKAG9Q&marketplace=HYPERLOCAL | N39: 28 | O39: 30 | Q39: 275 g | S39: Vim | T39: mum_187_wh_hl_01 | U39: 275 | V39: g | W39: 400051 | Y39: 2026-09-10 21:49:09
A40: 400051 | B40: Vim Lemon Dishwash Gel | C40: Dish Cleaning Gel | D40: In Stock | F40: 750 ml | G40: 750 | H40: ml | I40: Cleaning Essentials | J40: Dishwashing Gels & Tablets | L40: https://www.flipkart.com/vim-dish-cleaning-gel/p/itmfd4qydmg59zvy?pid=DCGEUJSDG7NPZKHP&marketplace=HYPERLOCAL | N40: 137 | O40: 140 | Q40: 0.5 L | S40: Vim | T40: mum_187_wh_hl_01 | U40: 500 | V40: ml | W40: 400051 | Y40: 2026-09-10 21:49:11
...

Sheet 2026-09-11 0721
