Workbook

Sheet Summary
A1: Zepto — In Stock % by run
A2: In Stock / (In Stock + Out of Stock). Excluded from both halves: rows with no reading, rows from a store marked Serviceable = No, and "Not Available" rows (the store does not carry the item — an assortment gap, not a stock-out). The 'Not carried' block below counts those.
A4: Pincode | B4: 2026-09-10 16:02 | C4: 2026-09-10 21:49 | D4: 2026-09-11 12:01 | E4: 2026-09-11 12:53 | F4: 2026-09-12 12:52 | G4: 2026-09-12 13:30 | H4: 2026-09-12 21:41 | I4: 2026-09-12 21:58 | J4: 2026-09-13 06:25 | K4: 2026-09-13 06:40 | L4: 2026-09-13 07:59 | M4: 2026-09-13 09:54 | N4: 2026-09-13 11:59 | O4: 2026-09-13 18:58 | P4: 2026-09-14 08:51
A5: 110060 | B5: =IFERROR(SUMPRODUCT(('2026-09-10 1602'!$A$2:$A$309="110060")*('2026-09-10 1602'!$D$2:$D$309="In Stock")*('2026-09-10 1602'!$E$2:$E$309<>"No"))/SUMPRODUCT(('2026-09-10 1602'!$A$2:$A$309="110060")*(('2026-09-10 1602'!$D$2:$D$309="In Stock")+('2026-09-10 1602'!$D$2:$D$309="Out of Stock"))*('2026-09-10 1602'!$E$2:$E$309<>"No")),"") | C5: =IFERROR(SUMPRODUCT(('2026-09-10 2149'!$A$2:$A$309="110060")*('2026-09-10 2149'!$D$2:$D$309="In Stock")*('2026-09-10 2149'!$E$2:$E$309<>"No"))/SUMPRODUCT(('2026-09-10 2149'!$A$2:$A$309="110060")*(('2026-09-10 2149'!$D$2:$D$309="In Stock")+('2026-09-10 2149'!$D$2:$D$309="Out of Stock"))*('2026-09-10 2149'!$E$2:$E$309<>"No")),"") | D5: =IFERROR(SUMPRODUCT(('2026-09-11 1201'!$A$2:$A$309="110060")*('2026-09-11 1201'!$D$2:$D$309="In Stock")*('2026-09-11 1201'!$E$2:$E$309<>"No"))/SUMPRODUCT(('2026-09-11 1201'!$A$2:$A$309="110060")*(('2026-09-11 1201'!$D$2:$D$309="In Stock")+('2026-09-11 1201'!$D$2:$D$309="Out of Stock"))*('2026-09-11 1201'!$E$2:$E$309<>"No")),"") | E5: =IFERROR(SUMPRODUCT(('2026-09-11 1253'!$A$2:$A$309="110060")*('2026-09-11 1253'!$D$2:$D$309="In Stock")*('2026-09-11 1253'!$E$2:$E$309<>"No"))/SUMPRODUCT(('2026-09-11 1253'!$A$2:$A$309="110060")*(('2026-09-11 1253'!$D$2:$D$309="In Stock")+('2026-09-11 1253'!$D$2:$D$309="Out of Stock"))*('2026-09-11 1253'!$E$2:$E$309<>"No")),"") | F5: =IFERROR(SUMPRODUCT(('2026-09-12 1252'!$A$2:$A$309="110060")*('2026-09-12 1252'!$D$2:$D$309="In Stock")*('2026-09-12 1252'!$E$2:$E$309<>"No"))/SUMPRODUCT(('2026-09-12 1252'!$A$2:$A$309="110060")*(('2026-09-12 1252'!$D$2:$D$309="In Stock")+('2026-09-12 1252'!$D$2:$D$309="Out of Stock"))*('2026-09-12 1252'!$E$2:$E$309<>"No")),"") | G5: =IFERROR(SUMPRODUCT(('2026-09-12 1330'!$A$2:$A$155="110060")*('2026-09-12 1330'!$D$2:$D$155="In Stock")*('2026-09-12 1330'!$E$2:$E$155<>"No"))/SUMPRODUCT(('2026-09-12 1330'!$A$2:$A$155="110060")*(('2026-09-12 1330'!$D$2:$D$155="In Stock")+('2026-09-12 1330'!$D$2:$D$155="Out of Stock"))*('2026-09-12 1330'!$E$2:$E$155<>"No")),"") | H5: =IFERROR(SUMPRODUCT(('2026-09-12 2141'!$A$2:$A$155="110060")*('2026-09-12 2141'!$D$2:$D$155="In Stock")*('2026-09-12 2141'!$E$2:$E$155<>"No"))/SUMPRODUCT(('2026-09-12 2141'!$A$2:$A$155="110060")*(('2026-09-12 2141'!$D$2:$D$155="In Stock")+('2026-09-12 2141'!$D$2:$D$155="Out of Stock"))*('2026-09-12 2141'!$E$2:$E$155<>"No")),"") | I5: =IFERROR(SUMPRODUCT(('2026-09-12 2158'!$A$2:$A$155="110060")*('2026-09-12 2158'!$D$2:$D$155="In Stock")*('2026-09-12 2158'!$E$2:$E$155<>"No"))/SUMPRODUCT(('2026-09-12 2158'!$A$2:$A$155="110060")*(('2026-09-12 2158'!$D$2:$D$155="In Stock")+('2026-09-12 2158'!$D$2:$D$155="Out of Stock"))*('2026-09-12 2158'!$E$2:$E$155<>"No")),"") | J5: =IFERROR(SUMPRODUCT(('2026-09-13 0625'!$A$2:$A$155="110060")*('2026-09-13 0625'!$D$2:$D$155="In Stock")*('2026-09-13 0625'!$E$2:$E$155<>"No"))/SUMPRODUCT(('2026-09-13 0625'!$A$2:$A$155="110060")*(('2026-09-13 0625'!$D$2:$D$155="In Stock")+('2026-09-13 0625'!$D$2:$D$155="Out of Stock"))*('2026-09-13 0625'!$E$2:$E$155<>"No")),"") | K5: =IFERROR(SUMPRODUCT(('2026-09-13 0640'!$A$2:$A$463="110060")*('2026-09-13 0640'!$D$2:$D$463="In Stock")*('2026-09-13 0640'!$E$2:$E$463<>"No"))/SUMPRODUCT(('2026-09-13 0640'!$A$2:$A$463="110060")*(('2026-09-13 0640'!$D$2:$D$463="In Stock")+('2026-09-13 0640'!$D$2:$D$463="Out of Stock"))*('2026-09-13 0640'!$E$2:$E$463<>"No")),"") | L5: =IFERROR(SUMPRODUCT(('2026-09-13 0759'!$A$2:$A$463="110060")*('2026-09-13 0759'!$D$2:$D$463="In Stock")*('2026-09-13 0759'!$E$2:$E$463<>"No"))/SUMPRODUCT(('2026-09-13 0759'!$A$2:$A$463="110060")*(('2026-09-13 0759'!$D$2:$D$463="In Stock")+('2026-09-13 0759'!$D$2:$D$463="Out of Stock"))*('2026-09-13 0759'!$E$2:$E$463<>"No")),"") | M5: =IFERROR(SUMPRODUCT(('2026-09-13 0954'!$A$2:$A$463="110060")*('2026-09-13 0954'!$D$2:$D$463="In Stock")*('2026-09-13 0954'!$E$2:$E$463<>"No"))/SUMPRODUCT(('2026-09-13 0954'!$A$2:$A$463="110060")*(('2026-09-13 0954'!$D$2:$D$463="In Stock")+('2026-09-13 0954'!$D$2:$D$463="Out of Stock"))*('2026-09-13 0954'!$E$2:$E$463<>"No")),"") | N5: =IFERROR(SUMPRODUCT(('2026-09-13 1159'!$A$2:$A$463="110060")*('2026-09-13 1159'!$D$2:$D$463="In Stock")*('2026-09-13 1159'!$E$2:$E$463<>"No"))/SUMPRODUCT(('2026-09-13 1159'!$A$2:$A$463="110060")*(('2026-09-13 1159'!$D$2:$D$463="In Stock")+('2026-09-13 1159'!$D$2:$D$463="Out of Stock"))*('2026-09-13 1159'!$E$2:$E$463<>"No")),"") | O5: =IFERROR(SUMPRODUCT(('2026-09-13 1858'!$A$2:$A$463="110060")*('2026-09-13 1858'!$D$2:$D$463="In Stock")*('2026-09-13 1858'!$E$2:$E$463<>"No"))/SUMPRODUCT(('2026-09-13 1858'!$A$2:$A$463="110060")*(('2026-09-13 1858'!$D$2:$D$463="In Stock")+('2026-09-13 1858'!$D$2:$D$463="Out of Stock"))*('2026-09-13 1858'!$E$2:$E$463<>"No")),"") | P5: =IFERROR(SUMPRODUCT(('2026-09-14 0851'!$A$2:$A$463="110060")*('2026-09-14 0851'!$D$2:$D$463="In Stock")*('2026-09-14 0851'!$E$2:$E$463<>"No"))/SUMPRODUCT(('2026-09-14 0851'!$A$2:$A$463="110060")*(('2026-09-14 0851'!$D$2:$D$463="In Stock")+('2026-09-14 0851'!$D$2:$D$463="Out of Stock"))*('2026-09-14 0851'!$E$2:$E$463<>"No")),"")
A6: 400011 | B6: =IFERROR(SUMPRODUCT(('2026-09-10 1602'!$A$2:$A$309="400011")*('2026-09-10 1602'!$D$2:$D$309="In Stock")*('2026-09-10 1602'!$E$2:$E$309<>"No"))/SUMPRODUCT(('2026-09-10 1602'!$A$2:$A$309="400011")*(('2026-09-10 1602'!$D$2:$D$309="In Stock")+('2026-09-10 1602'!$D$2:$D$309="Out of Stock"))*('2026-09-10 1602'!$E$2:$E$309<>"No")),"") | C6: =IFERROR(SUMPRODUCT(('2026-09-10 2149'!$A$2:$A$309="400011")*('2026-09-10 2149'!$D$2:$D$309="In Stock")*('2026-09-10 2149'!$E$2:$E$309<>"No"))/SUMPRODUCT(('2026-09-10 2149'!$A$2:$A$309="400011")*(('2026-09-10 2149'!$D$2:$D$309="In Stock")+('2026-09-10 2149'!$D$2:$D$309="Out of Stock"))*('2026-09-10 2149'!$E$2:$E$309<>"No")),"") | D6: =IFERROR(SUMPRODUCT(('2026-09-11 1201'!$A$2:$A$309="400011")*('2026-09-11 1201'!$D$2:$D$309="In Stock")*('2026-09-11 1201'!$E$2:$E$309<>"No"))/SUMPRODUCT(('2026-09-11 1201'!$A$2:$A$309="400011")*(('2026-09-11 1201'!$D$2:$D$309="In Stock")+('2026-09-11 1201'!$D$2:$D$309="Out of Stock"))*('2026-09-11 1201'!$E$2:$E$309<>"No")),"") | E6: =IFERROR(SUMPRODUCT(('2026-09-11 1253'!$A$2:$A$309="400011")*('2026-09-11 1253'!$D$2:$D$309="In Stock")*('2026-09-11 1253'!$E$2:$E$309<>"No"))/SUMPRODUCT(('2026-09-11 1253'!$A$2:$A$309="400011")*(('2026-09-11 1253'!$D$2:$D$309="In Stock")+('2026-09-11 1253'!$D$2:$D$309="Out of Stock"))*('2026-09-11 1253'!$E$2:$E$309<>"No")),"") | F6: =IFERROR(SUMPRODUCT(('2026-09-12 1252'!$A$2:$A$309="400011")*('2026-09-12 1252'!$D$2:$D$309="In Stock")*('2026-09-12 1252'!$E$2:$E$309<>"No"))/SUMPRODUCT(('2026-09-12 1252'!$A$2:$A$309="400011")*(('2026-09-12 1252'!$D$2:$D$309="In Stock")+('2026-09-12 1252'!$D$2:$D$309="Out of Stock"))*('2026-09-12 1252'!$E$2:$E$309<>"No")),"") | G6: =IFERROR(SUMPRODUCT(('2026-09-12 1330'!$A$2:$A$155="400011")*('2026-09-12 1330'!$D$2:$D$155="In Stock")*('2026-09-12 1330'!$E$2:$E$155<>"No"))/SUMPRODUCT(('2026-09-12 1330'!$A$2:$A$155="400011")*(('2026-09-12 1330'!$D$2:$D$155="In Stock")+('2026-09-12 1330'!$D$2:$D$155="Out of Stock"))*('2026-09-12 1330'!$E$2:$E$155<>"No")),"") | H6: =IFERROR(SUMPRODUCT(('2026-09-12 2141'!$A$2:$A$155="400011")*('2026-09-12 2141'!$D$2:$D$155="In Stock")*('2026-09-12 2141'!$E$2:$E$155<>"No"))/SUMPRODUCT(('2026-09-12 2141'!$A$2:$A$155="400011")*(('2026-09-12 2141'!$D$2:$D$155="In Stock")+('2026-09-12 2141'!$D$2:$D$155="Out of Stock"))*('2026-09-12 2141'!$E$2:$E$155<>"No")),"") | I6: =IFERROR(SUMPRODUCT(('2026-09-12 2158'!$A$2:$A$155="400011")*('2026-09-12 2158'!$D$2:$D$155="In Stock")*('2026-09-12 2158'!$E$2:$E$155<>"No"))/SUMPRODUCT(('2026-09-12 2158'!$A$2:$A$155="400011")*(('2026-09-12 2158'!$D$2:$D$155="In Stock")+('2026-09-12 2158'!$D$2:$D$155="Out of Stock"))*('2026-09-12 2158'!$E$2:$E$155<>"No")),"") | J6: =IFERROR(SUMPRODUCT(('2026-09-13 0625'!$A$2:$A$155="400011")*('2026-09-13 0625'!$D$2:$D$155="In Stock")*('2026-09-13 0625'!$E$2:$E$155<>"No"))/SUMPRODUCT(('2026-09-13 0625'!$A$2:$A$155="400011")*(('2026-09-13 0625'!$D$2:$D$155="In Stock")+('2026-09-13 0625'!$D$2:$D$155="Out of Stock"))*('2026-09-13 0625'!$E$2:$E$155<>"No")),"") | K6: =IFERROR(SUMPRODUCT(('2026-09-13 0640'!$A$2:$A$463="400011")*('2026-09-13 0640'!$D$2:$D$463="In Stock")*('2026-09-13 0640'!$E$2:$E$463<>"No"))/SUMPRODUCT(('2026-09-13 0640'!$A$2:$A$463="400011")*(('2026-09-13 0640'!$D$2:$D$463="In Stock")+('2026-09-13 0640'!$D$2:$D$463="Out of Stock"))*('2026-09-13 0640'!$E$2:$E$463<>"No")),"") | L6: =IFERROR(SUMPRODUCT(('2026-09-13 0759'!$A$2:$A$463="400011")*('2026-09-13 0759'!$D$2:$D$463="In Stock")*('2026-09-13 0759'!$E$2:$E$463<>"No"))/SUMPRODUCT(('2026-09-13 0759'!$A$2:$A$463="400011")*(('2026-09-13 0759'!$D$2:$D$463="In Stock")+('2026-09-13 0759'!$D$2:$D$463="Out of Stock"))*('2026-09-13 0759'!$E$2:$E$463<>"No")),"") | M6: =IFERROR(SUMPRODUCT(('2026-09-13 0954'!$A$2:$A$463="400011")*('2026-09-13 0954'!$D$2:$D$463="In Stock")*('2026-09-13 0954'!$E$2:$E$463<>"No"))/SUMPRODUCT(('2026-09-13 0954'!$A$2:$A$463="400011")*(('2026-09-13 0954'!$D$2:$D$463="In Stock")+('2026-09-13 0954'!$D$2:$D$463="Out of Stock"))*('2026-09-13 0954'!$E$2:$E$463<>"No")),"") | N6: =IFERROR(SUMPRODUCT(('2026-09-13 1159'!$A$2:$A$463="400011")*('2026-09-13 1159'!$D$2:$D$463="In Stock")*('2026-09-13 1159'!$E$2:$E$463<>"No"))/SUMPRODUCT(('2026-09-13 1159'!$A$2:$A$463="400011")*(('2026-09-13 1159'!$D$2:$D$463="In Stock")+('2026-09-13 1159'!$D$2:$D$463="Out of Stock"))*('2026-09-13 1159'!$E$2:$E$463<>"No")),"") | O6: =IFERROR(SUMPRODUCT(('2026-09-13 1858'!$A$2:$A$463="400011")*('2026-09-13 1858'!$D$2:$D$463="In Stock")*('2026-09-13 1858'!$E$2:$E$463<>"No"))/SUMPRODUCT(('2026-09-13 1858'!$A$2:$A$463="400011")*(('2026-09-13 1858'!$D$2:$D$463="In Stock")+('2026-09-13 1858'!$D$2:$D$463="Out of Stock"))*('2026-09-13 1858'!$E$2:$E$463<>"No")),"") | P6: =IFERROR(SUMPRODUCT(('2026-09-14 0851'!$A$2:$A$463="400011")*('2026-09-14 0851'!$D$2:$D$463="In Stock")*('2026-09-14 0851'!$E$2:$E$463<>"No"))/SUMPRODUCT(('2026-09-14 0851'!$A$2:$A$463="400011")*(('2026-09-14 0851'!$D$2:$D$463="In Stock")+('2026-09-14 0851'!$D$2:$D$463="Out of Stock"))*('2026-09-14 0851'!$E$2:$E$463<>"No")),"")
A7: 400051 | B7: =IFERROR(SUMPRODUCT(('2026-09-10 1602'!$A$2:$A$309="400051")*('2026-09-10 1602'!$D$2:$D$309="In Stock")*('2026-09-10 1602'!$E$2:$E$309<>"No"))/SUMPRODUCT(('2026-09-10 1602'!$A$2:$A$309="400051")*(('2026-09-10 1602'!$D$2:$D$309="In Stock")+('2026-09-10 1602'!$D$2:$D$309="Out of Stock"))*('2026-09-10 1602'!$E$2:$E$309<>"No")),"") | C7: =IFERROR(SUMPRODUCT(('2026-09-10 2149'!$A$2:$A$309="400051")*('2026-09-10 2149'!$D$2:$D$309="In Stock")*('2026-09-10 2149'!$E$2:$E$309<>"No"))/SUMPRODUCT(('2026-09-10 2149'!$A$2:$A$309="400051")*(('2026-09-10 2149'!$D$2:$D$309="In Stock")+('2026-09-10 2149'!$D$2:$D$309="Out of Stock"))*('2026-09-10 2149'!$E$2:$E$309<>"No")),"") | D7: =IFERROR(SUMPRODUCT(('2026-09-11 1201'!$A$2:$A$309="400051")*('2026-09-11 1201'!$D$2:$D$309="In Stock")*('2026-09-11 1201'!$E$2:$E$309<>"No"))/SUMPRODUCT(('2026-09-11 1201'!$A$2:$A$309="400051")*(('2026-09-11 1201'!$D$2:$D$309="In Stock")+('2026-09-11 1201'!$D$2:$D$309="Out of Stock"))*('2026-09-11 1201'!$E$2:$E$309<>"No")),"") | E7: =IFERROR(SUMPRODUCT(('2026-09-11 1253'!$A$2:$A$309="400051")*('2026-09-11 1253'!$D$2:$D$309="In Stock")*('2026-09-11 1253'!$E$2:$E$309<>"No"))/SUMPRODUCT(('2026-09-11 1253'!$A$2:$A$309="400051")*(('2026-09-11 1253'!$D$2:$D$309="In Stock")+('2026-09-11 1253'!$D$2:$D$309="Out of Stock"))*('2026-09-11 1253'!$E$2:$E$309<>"No")),"") | F7: =IFERROR(SUMPRODUCT(('2026-09-12 1252'!$A$2:$A$309="400051")*('2026-09-12 1252'!$D$2:$D$309="In Stock")*('2026-09-12 1252'!$E$2:$E$309<>"No"))/SUMPRODUCT(('2026-09-12 1252'!$A$2:$A$309="400051")*(('2026-09-12 1252'!$D$2:$D$309="In Stock")+('2026-09-12 1252'!$D$2:$D$309="Out of Stock"))*('2026-09-12 1252'!$E$2:$E$309<>"No")),"") | G7: =IFERROR(SUMPRODUCT(('2026-09-12 1330'!$A$2:$A$155="400051")*('2026-09-12 1330'!$D$2:$D$155="In Stock")*('2026-09-12 1330'!$E$2:$E$155<>"No"))/SUMPRODUCT(('2026-09-12 1330'!$A$2:$A$155="400051")*(('2026-09-12 1330'!$D$2:$D$155="In Stock")+('2026-09-12 1330'!$D$2:$D$155="Out of Stock"))*('2026-09-12 1330'!$E$2:$E$155<>"No")),"") | H7: =IFERROR(SUMPRODUCT(('2026-09-12 2141'!$A$2:$A$155="400051")*('2026-09-12 2141'!$D$2:$D$155="In Stock")*('2026-09-12 2141'!$E$2:$E$155<>"No"))/SUMPRODUCT(('2026-09-12 2141'!$A$2:$A$155="400051")*(('2026-09-12 2141'!$D$2:$D$155="In Stock")+('2026-09-12 2141'!$D$2:$D$155="Out of Stock"))*('2026-09-12 2141'!$E$2:$E$155<>"No")),"") | I7: =IFERROR(SUMPRODUCT(('2026-09-12 2158'!$A$2:$A$155="400051")*('2026-09-12 2158'!$D$2:$D$155="In Stock")*('2026-09-12 2158'!$E$2:$E$155<>"No"))/SUMPRODUCT(('2026-09-12 2158'!$A$2:$A$155="400051")*(('2026-09-12 2158'!$D$2:$D$155="In Stock")+('2026-09-12 2158'!$D$2:$D$155="Out of Stock"))*('2026-09-12 2158'!$E$2:$E$155<>"No")),"") | J7: =IFERROR(SUMPRODUCT(('2026-09-13 0625'!$A$2:$A$155="400051")*('2026-09-13 0625'!$D$2:$D$155="In Stock")*('2026-09-13 0625'!$E$2:$E$155<>"No"))/SUMPRODUCT(('2026-09-13 0625'!$A$2:$A$155="400051")*(('2026-09-13 0625'!$D$2:$D$155="In Stock")+('2026-09-13 0625'!$D$2:$D$155="Out of Stock"))*('2026-09-13 0625'!$E$2:$E$155<>"No")),"") | K7: =IFERROR(SUMPRODUCT(('2026-09-13 0640'!$A$2:$A$463="400051")*('2026-09-13 0640'!$D$2:$D$463="In Stock")*('2026-09-13 0640'!$E$2:$E$463<>"No"))/SUMPRODUCT(('2026-09-13 0640'!$A$2:$A$463="400051")*(('2026-09-13 0640'!$D$2:$D$463="In Stock")+('2026-09-13 0640'!$D$2:$D$463="Out of Stock"))*('2026-09-13 0640'!$E$2:$E$463<>"No")),"") | L7: =IFERROR(SUMPRODUCT(('2026-09-13 0759'!$A$2:$A$463="400051")*('2026-09-13 0759'!$D$2:$D$463="In Stock")*('2026-09-13 0759'!$E$2:$E$463<>"No"))/SUMPRODUCT(('2026-09-13 0759'!$A$2:$A$463="400051")*(('2026-09-13 0759'!$D$2:$D$463="In Stock")+('2026-09-13 0759'!$D$2:$D$463="Out of Stock"))*('2026-09-13 0759'!$E$2:$E$463<>"No")),"") | M7: =IFERROR(SUMPRODUCT(('2026-09-13 0954'!$A$2:$A$463="400051")*('2026-09-13 0954'!$D$2:$D$463="In Stock")*('2026-09-13 0954'!$E$2:$E$463<>"No"))/SUMPRODUCT(('2026-09-13 0954'!$A$2:$A$463="400051")*(('2026-09-13 0954'!$D$2:$D$463="In Stock")+('2026-09-13 0954'!$D$2:$D$463="Out of Stock"))*('2026-09-13 0954'!$E$2:$E$463<>"No")),"") | N7: =IFERROR(SUMPRODUCT(('2026-09-13 1159'!$A$2:$A$463="400051")*('2026-09-13 1159'!$D$2:$D$463="In Stock")*('2026-09-13 1159'!$E$2:$E$463<>"No"))/SUMPRODUCT(('2026-09-13 1159'!$A$2:$A$463="400051")*(('2026-09-13 1159'!$D$2:$D$463="In Stock")+('2026-09-13 1159'!$D$2:$D$463="Out of Stock"))*('2026-09-13 1159'!$E$2:$E$463<>"No")),"") | O7: =IFERROR(SUMPRODUCT(('2026-09-13 1858'!$A$2:$A$463="400051")*('2026-09-13 1858'!$D$2:$D$463="In Stock")*('2026-09-13 1858'!$E$2:$E$463<>"No"))/SUMPRODUCT(('2026-09-13 1858'!$A$2:$A$463="400051")*(('2026-09-13 1858'!$D$2:$D$463="In Stock")+('2026-09-13 1858'!$D$2:$D$463="Out of Stock"))*('2026-09-13 1858'!$E$2:$E$463<>"No")),"") | P7: =IFERROR(SUMPRODUCT(('2026-09-14 0851'!$A$2:$A$463="400051")*('2026-09-14 0851'!$D$2:$D$463="In Stock")*('2026-09-14 0851'!$E$2:$E$463<>"No"))/SUMPRODUCT(('2026-09-14 0851'!$A$2:$A$463="400051")*(('2026-09-14 0851'!$D$2:$D$463="In Stock")+('2026-09-14 0851'!$D$2:$D$463="Out of Stock"))*('2026-09-14 0851'!$E$2:$E$463<>"No")),"")
A8: 560037 | B8: =IFERROR(SUMPRODUCT(('2026-09-10 1602'!$A$2:$A$309="560037")*('2026-09-10 1602'!$D$2:$D$309="In Stock")*('2026-09-10 1602'!$E$2:$E$309<>"No"))/SUMPRODUCT(('2026-09-10 1602'!$A$2:$A$309="560037")*(('2026-09-10 1602'!$D$2:$D$309="In Stock")+('2026-09-10 1602'!$D$2:$D$309="Out of Stock"))*('2026-09-10 1602'!$E$2:$E$309<>"No")),"") | C8: =IFERROR(SUMPRODUCT(('2026-09-10 2149'!$A$2:$A$309="560037")*('2026-09-10 2149'!$D$2:$D$309="In Stock")*('2026-09-10 2149'!$E$2:$E$309<>"No"))/SUMPRODUCT(('2026-09-10 2149'!$A$2:$A$309="560037")*(('2026-09-10 2149'!$D$2:$D$309="In Stock")+('2026-09-10 2149'!$D$2:$D$309="Out of Stock"))*('2026-09-10 2149'!$E$2:$E$309<>"No")),"") | D8: =IFERROR(SUMPRODUCT(('2026-09-11 1201'!$A$2:$A$309="560037")*('2026-09-11 1201'!$D$2:$D$309="In Stock")*('2026-09-11 1201'!$E$2:$E$309<>"No"))/SUMPRODUCT(('2026-09-11 1201'!$A$2:$A$309="560037")*(('2026-09-11 1201'!$D$2:$D$309="In Stock")+('2026-09-11 1201'!$D$2:$D$309="Out of Stock"))*('2026-09-11 1201'!$E$2:$E$309<>"No")),"") | E8: =IFERROR(SUMPRODUCT(('2026-09-11 1253'!$A$2:$A$309="560037")*('2026-09-11 1253'!$D$2:$D$309="In Stock")*('2026-09-11 1253'!$E$2:$E$309<>"No"))/SUMPRODUCT(('2026-09-11 1253'!$A$2:$A$309="560037")*(('2026-09-11 1253'!$D$2:$D$309="In Stock")+('2026-09-11 1253'!$D$2:$D$309="Out of Stock"))*('2026-09-11 1253'!$E$2:$E$309<>"No")),"") | F8: =IFERROR(SUMPRODUCT(('2026-09-12 1252'!$A$2:$A$309="560037")*('2026-09-12 1252'!$D$2:$D$309="In Stock")*('2026-09-12 1252'!$E$2:$E$309<>"No"))/SUMPRODUCT(('2026-09-12 1252'!$A$2:$A$309="560037")*(('2026-09-12 1252'!$D$2:$D$309="In Stock")+('2026-09-12 1252'!$D$2:$D$309="Out of Stock"))*('2026-09-12 1252'!$E$2:$E$309<>"No")),"") | G8: =IFERROR(SUMPRODUCT(('2026-09-12 1330'!$A$2:$A$155="560037")*('2026-09-12 1330'!$D$2:$D$155="In Stock")*('2026-09-12 1330'!$E$2:$E$155<>"No"))/SUMPRODUCT(('2026-09-12 1330'!$A$2:$A$155="560037")*(('2026-09-12 1330'!$D$2:$D$155="In Stock")+('2026-09-12 1330'!$D$2:$D$155="Out of Stock"))*('2026-09-12 1330'!$E$2:$E$155<>"No")),"") | H8: =IFERROR(SUMPRODUCT(('2026-09-12 2141'!$A$2:$A$155="560037")*('2026-09-12 2141'!$D$2:$D$155="In Stock")*('2026-09-12 2141'!$E$2:$E$155<>"No"))/SUMPRODUCT(('2026-09-12 2141'!$A$2:$A$155="560037")*(('2026-09-12 2141'!$D$2:$D$155="In Stock")+('2026-09-12 2141'!$D$2:$D$155="Out of Stock"))*('2026-09-12 2141'!$E$2:$E$155<>"No")),"") | I8: =IFERROR(SUMPRODUCT(('2026-09-12 2158'!$A$2:$A$155="560037")*('2026-09-12 2158'!$D$2:$D$155="In Stock")*('2026-09-12 2158'!$E$2:$E$155<>"No"))/SUMPRODUCT(('2026-09-12 2158'!$A$2:$A$155="560037")*(('2026-09-12 2158'!$D$2:$D$155="In Stock")+('2026-09-12 2158'!$D$2:$D$155="Out of Stock"))*('2026-09-12 2158'!$E$2:$E$155<>"No")),"") | J8: =IFERROR(SUMPRODUCT(('2026-09-13 0625'!$A$2:$A$155="560037")*('2026-09-13 0625'!$D$2:$D$155="In Stock")*('2026-09-13 0625'!$E$2:$E$155<>"No"))/SUMPRODUCT(('2026-09-13 0625'!$A$2:$A$155="560037")*(('2026-09-13 0625'!$D$2:$D$155="In Stock")+('2026-09-13 0625'!$D$2:$D$155="Out of Stock"))*('2026-09-13 0625'!$E$2:$E$155<>"No")),"") | K8: =IFERROR(SUMPRODUCT(('2026-09-13 0640'!$A$2:$A$463="560037")*('2026-09-13 0640'!$D$2:$D$463="In Stock")*('2026-09-13 0640'!$E$2:$E$463<>"No"))/SUMPRODUCT(('2026-09-13 0640'!$A$2:$A$463="560037")*(('2026-09-13 0640'!$D$2:$D$463="In Stock")+('2026-09-13 0640'!$D$2:$D$463="Out of Stock"))*('2026-09-13 0640'!$E$2:$E$463<>"No")),"") | L8: =IFERROR(SUMPRODUCT(('2026-09-13 0759'!$A$2:$A$463="560037")*('2026-09-13 0759'!$D$2:$D$463="In Stock")*('2026-09-13 0759'!$E$2:$E$463<>"No"))/SUMPRODUCT(('2026-09-13 0759'!$A$2:$A$463="560037")*(('2026-09-13 0759'!$D$2:$D$463="In Stock")+('2026-09-13 0759'!$D$2:$D$463="Out of Stock"))*('2026-09-13 0759'!$E$2:$E$463<>"No")),"") | M8: =IFERROR(SUMPRODUCT(('2026-09-13 0954'!$A$2:$A$463="560037")*('2026-09-13 0954'!$D$2:$D$463="In Stock")*('2026-09-13 0954'!$E$2:$E$463<>"No"))/SUMPRODUCT(('2026-09-13 0954'!$A$2:$A$463="560037")*(('2026-09-13 0954'!$D$2:$D$463="In Stock")+('2026-09-13 0954'!$D$2:$D$463="Out of Stock"))*('2026-09-13 0954'!$E$2:$E$463<>"No")),"") | N8: =IFERROR(SUMPRODUCT(('2026-09-13 1159'!$A$2:$A$463="560037")*('2026-09-13 1159'!$D$2:$D$463="In Stock")*('2026-09-13 1159'!$E$2:$E$463<>"No"))/SUMPRODUCT(('2026-09-13 1159'!$A$2:$A$463="560037")*(('2026-09-13 1159'!$D$2:$D$463="In Stock")+('2026-09-13 1159'!$D$2:$D$463="Out of Stock"))*('2026-09-13 1159'!$E$2:$E$463<>"No")),"") | O8: =IFERROR(SUMPRODUCT(('2026-09-13 1858'!$A$2:$A$463="560037")*('2026-09-13 1858'!$D$2:$D$463="In Stock")*('2026-09-13 1858'!$E$2:$E$463<>"No"))/SUMPRODUCT(('2026-09-13 1858'!$A$2:$A$463="560037")*(('2026-09-13 1858'!$D$2:$D$463="In Stock")+('2026-09-13 1858'!$D$2:$D$463="Out of Stock"))*('2026-09-13 1858'!$E$2:$E$463<>"No")),"") | P8: =IFERROR(SUMPRODUCT(('2026-09-14 0851'!$A$2:$A$463="560037")*('2026-09-14 0851'!$D$2:$D$463="In Stock")*('2026-09-14 0851'!$E$2:$E$463<>"No"))/SUMPRODUCT(('2026-09-14 0851'!$A$2:$A$463="560037")*(('2026-09-14 0851'!$D$2:$D$463="In Stock")+('2026-09-14 0851'!$D$2:$D$463="Out of Stock"))*('2026-09-14 0851'!$E$2:$E$463<>"No")),"")
A9: All pincodes | B9: =IFERROR(SUMPRODUCT(('2026-09-10 1602'!$D$2:$D$309="In Stock")*('2026-09-10 1602'!$E$2:$E$309<>"No"))/SUMPRODUCT((('2026-09-10 1602'!$D$2:$D$309="In Stock")+('2026-09-10 1602'!$D$2:$D$309="Out of Stock"))*('2026-09-10 1602'!$E$2:$E$309<>"No")),"") | C9: =IFERROR(SUMPRODUCT(('2026-09-10 2149'!$D$2:$D$309="In Stock")*('2026-09-10 2149'!$E$2:$E$309<>"No"))/SUMPRODUCT((('2026-09-10 2149'!$D$2:$D$309="In Stock")+('2026-09-10 2149'!$D$2:$D$309="Out of Stock"))*('2026-09-10 2149'!$E$2:$E$309<>"No")),"") | D9: =IFERROR(SUMPRODUCT(('2026-09-11 1201'!$D$2:$D$309="In Stock")*('2026-09-11 1201'!$E$2:$E$309<>"No"))/SUMPRODUCT((('2026-09-11 1201'!$D$2:$D$309="In Stock")+('2026-09-11 1201'!$D$2:$D$309="Out of Stock"))*('2026-09-11 1201'!$E$2:$E$309<>"No")),"") | E9: =IFERROR(SUMPRODUCT(('2026-09-11 1253'!$D$2:$D$309="In Stock")*('2026-09-11 1253'!$E$2:$E$309<>"No"))/SUMPRODUCT((('2026-09-11 1253'!$D$2:$D$309="In Stock")+('2026-09-11 1253'!$D$2:$D$309="Out of Stock"))*('2026-09-11 1253'!$E$2:$E$309<>"No")),"") | F9: =IFERROR(SUMPRODUCT(('2026-09-12 1252'!$D$2:$D$309="In Stock")*('2026-09-12 1252'!$E$2:$E$309<>"No"))/SUMPRODUCT((('2026-09-12 1252'!$D$2:$D$309="In Stock")+('2026-09-12 1252'!$D$2:$D$309="Out of Stock"))*('2026-09-12 1252'!$E$2:$E$309<>"No")),"") | G9: =IFERROR(SUMPRODUCT(('2026-09-12 1330'!$D$2:$D$155="In Stock")*('2026-09-12 1330'!$E$2:$E$155<>"No"))/SUMPRODUCT((('2026-09-12 1330'!$D$2:$D$155="In Stock")+('2026-09-12 1330'!$D$2:$D$155="Out of Stock"))*('2026-09-12 1330'!$E$2:$E$155<>"No")),"") | H9: =IFERROR(SUMPRODUCT(('2026-09-12 2141'!$D$2:$D$155="In Stock")*('2026-09-12 2141'!$E$2:$E$155<>"No"))/SUMPRODUCT((('2026-09-12 2141'!$D$2:$D$155="In Stock")+('2026-09-12 2141'!$D$2:$D$155="Out of Stock"))*('2026-09-12 2141'!$E$2:$E$155<>"No")),"") | I9: =IFERROR(SUMPRODUCT(('2026-09-12 2158'!$D$2:$D$155="In Stock")*('2026-09-12 2158'!$E$2:$E$155<>"No"))/SUMPRODUCT((('2026-09-12 2158'!$D$2:$D$155="In Stock")+('2026-09-12 2158'!$D$2:$D$155="Out of Stock"))*('2026-09-12 2158'!$E$2:$E$155<>"No")),"") | J9: =IFERROR(SUMPRODUCT(('2026-09-13 0625'!$D$2:$D$155="In Stock")*('2026-09-13 0625'!$E$2:$E$155<>"No"))/SUMPRODUCT((('2026-09-13 0625'!$D$2:$D$155="In Stock")+('2026-09-13 0625'!$D$2:$D$155="Out of Stock"))*('2026-09-13 0625'!$E$2:$E$155<>"No")),"") | K9: =IFERROR(SUMPRODUCT(('2026-09-13 0640'!$D$2:$D$463="In Stock")*('2026-09-13 0640'!$E$2:$E$463<>"No"))/SUMPRODUCT((('2026-09-13 0640'!$D$2:$D$463="In Stock")+('2026-09-13 0640'!$D$2:$D$463="Out of Stock"))*('2026-09-13 0640'!$E$2:$E$463<>"No")),"") | L9: =IFERROR(SUMPRODUCT(('2026-09-13 0759'!$D$2:$D$463="In Stock")*('2026-09-13 0759'!$E$2:$E$463<>"No"))/SUMPRODUCT((('2026-09-13 0759'!$D$2:$D$463="In Stock")+('2026-09-13 0759'!$D$2:$D$463="Out of Stock"))*('2026-09-13 0759'!$E$2:$E$463<>"No")),"") | M9: =IFERROR(SUMPRODUCT(('2026-09-13 0954'!$D$2:$D$463="In Stock")*('2026-09-13 0954'!$E$2:$E$463<>"No"))/SUMPRODUCT((('2026-09-13 0954'!$D$2:$D$463="In Stock")+('2026-09-13 0954'!$D$2:$D$463="Out of Stock"))*('2026-09-13 0954'!$E$2:$E$463<>"No")),"") | N9: =IFERROR(SUMPRODUCT(('2026-09-13 1159'!$D$2:$D$463="In Stock")*('2026-09-13 1159'!$E$2:$E$463<>"No"))/SUMPRODUCT((('2026-09-13 1159'!$D$2:$D$463="In Stock")+('2026-09-13 1159'!$D$2:$D$463="Out of Stock"))*('2026-09-13 1159'!$E$2:$E$463<>"No")),"") | O9: =IFERROR(SUMPRODUCT(('2026-09-13 1858'!$D$2:$D$463="In Stock")*('2026-09-13 1858'!$E$2:$E$463<>"No"))/SUMPRODUCT((('2026-09-13 1858'!$D$2:$D$463="In Stock")+('2026-09-13 1858'!$D$2:$D$463="Out of Stock"))*('2026-09-13 1858'!$E$2:$E$463<>"No")),"") | P9: =IFERROR(SUMPRODUCT(('2026-09-14 0851'!$D$2:$D$463="In Stock")*('2026-09-14 0851'!$E$2:$E$463<>"No"))/SUMPRODUCT((('2026-09-14 0851'!$D$2:$D$463="In Stock")+('2026-09-14 0851'!$D$2:$D$463="Out of Stock"))*('2026-09-14 0851'!$E$2:$E$463<>"No")),"")
A10: Not carried (excluded from the % above)
A11: Pincode | B11: 2026-09-10 16:02 | C11: 2026-09-10 21:49 | D11: 2026-09-11 12:01 | E11: 2026-09-11 12:53 | F11: 2026-09-12 12:52 | G11: 2026-09-12 13:30 | H11: 2026-09-12 21:41 | I11: 2026-09-12 21:58 | J11: 2026-09-13 06:25 | K11: 2026-09-13 06:40 | L11: 2026-09-13 07:59 | M11: 2026-09-13 09:54 | N11: 2026-09-13 11:59 | O11: 2026-09-13 18:58 | P11: 2026-09-14 08:51
A12: 110060 | B12: =IF(SUMPRODUCT(--('2026-09-10 1602'!$A$2:$A$309="110060"))=0,"",SUMPRODUCT(('2026-09-10 1602'!$A$2:$A$309="110060")*('2026-09-10 1602'!$D$2:$D$309="Not Available")*('2026-09-10 1602'!$E$2:$E$309<>"No"))) | C12: =IF(SUMPRODUCT(--('2026-09-10 2149'!$A$2:$A$309="110060"))=0,"",SUMPRODUCT(('2026-09-10 2149'!$A$2:$A$309="110060")*('2026-09-10 2149'!$D$2:$D$309="Not Available")*('2026-09-10 2149'!$E$2:$E$309<>"No"))) | D12: =IF(SUMPRODUCT(--('2026-09-11 1201'!$A$2:$A$309="110060"))=0,"",SUMPRODUCT(('2026-09-11 1201'!$A$2:$A$309="110060")*('2026-09-11 1201'!$D$2:$D$309="Not Available")*('2026-09-11 1201'!$E$2:$E$309<>"No"))) | E12: =IF(SUMPRODUCT(--('2026-09-11 1253'!$A$2:$A$309="110060"))=0,"",SUMPRODUCT(('2026-09-11 1253'!$A$2:$A$309="110060")*('2026-09-11 1253'!$D$2:$D$309="Not Available")*('2026-09-11 1253'!$E$2:$E$309<>"No"))) | F12: =IF(SUMPRODUCT(--('2026-09-12 1252'!$A$2:$A$309="110060"))=0,"",SUMPRODUCT(('2026-09-12 1252'!$A$2:$A$309="110060")*('2026-09-12 1252'!$D$2:$D$309="Not Available")*('2026-09-12 1252'!$E$2:$E$309<>"No"))) | G12: =IF(SUMPRODUCT(--('2026-09-12 1330'!$A$2:$A$155="110060"))=0,"",SUMPRODUCT(('2026-09-12 1330'!$A$2:$A$155="110060")*('2026-09-12 1330'!$D$2:$D$155="Not Available")*('2026-09-12 1330'!$E$2:$E$155<>"No"))) | H12: =IF(SUMPRODUCT(--('2026-09-12 2141'!$A$2:$A$155="110060"))=0,"",SUMPRODUCT(('2026-09-12 2141'!$A$2:$A$155="110060")*('2026-09-12 2141'!$D$2:$D$155="Not Available")*('2026-09-12 2141'!$E$2:$E$155<>"No"))) | I12: =IF(SUMPRODUCT(--('2026-09-12 2158'!$A$2:$A$155="110060"))=0,"",SUMPRODUCT(('2026-09-12 2158'!$A$2:$A$155="110060")*('2026-09-12 2158'!$D$2:$D$155="Not Available")*('2026-09-12 2158'!$E$2:$E$155<>"No"))) | J12: =IF(SUMPRODUCT(--('2026-09-13 0625'!$A$2:$A$155="110060"))=0,"",SUMPRODUCT(('2026-09-13 0625'!$A$2:$A$155="110060")*('2026-09-13 0625'!$D$2:$D$155="Not Available")*('2026-09-13 0625'!$E$2:$E$155<>"No"))) | K12: =IF(SUMPRODUCT(--('2026-09-13 0640'!$A$2:$A$463="110060"))=0,"",SUMPRODUCT(('2026-09-13 0640'!$A$2:$A$463="110060")*('2026-09-13 0640'!$D$2:$D$463="Not Available")*('2026-09-13 0640'!$E$2:$E$463<>"No"))) | L12: =IF(SUMPRODUCT(--('2026-09-13 0759'!$A$2:$A$463="110060"))=0,"",SUMPRODUCT(('2026-09-13 0759'!$A$2:$A$463="110060")*('2026-09-13 0759'!$D$2:$D$463="Not Available")*('2026-09-13 0759'!$E$2:$E$463<>"No"))) | M12: =IF(SUMPRODUCT(--('2026-09-13 0954'!$A$2:$A$463="110060"))=0,"",SUMPRODUCT(('2026-09-13 0954'!$A$2:$A$463="110060")*('2026-09-13 0954'!$D$2:$D$463="Not Available")*('2026-09-13 0954'!$E$2:$E$463<>"No"))) | N12: =IF(SUMPRODUCT(--('2026-09-13 1159'!$A$2:$A$463="110060"))=0,"",SUMPRODUCT(('2026-09-13 1159'!$A$2:$A$463="110060")*('2026-09-13 1159'!$D$2:$D$463="Not Available")*('2026-09-13 1159'!$E$2:$E$463<>"No"))) | O12: =IF(SUMPRODUCT(--('2026-09-13 1858'!$A$2:$A$463="110060"))=0,"",SUMPRODUCT(('2026-09-13 1858'!$A$2:$A$463="110060")*('2026-09-13 1858'!$D$2:$D$463="Not Available")*('2026-09-13 1858'!$E$2:$E$463<>"No"))) | P12: =IF(SUMPRODUCT(--('2026-09-14 0851'!$A$2:$A$463="110060"))=0,"",SUMPRODUCT(('2026-09-14 0851'!$A$2:$A$463="110060")*('2026-09-14 0851'!$D$2:$D$463="Not Available")*('2026-09-14 0851'!$E$2:$E$463<>"No")))
A13: 400011 | B13: =IF(SUMPRODUCT(--('2026-09-10 1602'!$A$2:$A$309="400011"))=0,"",SUMPRODUCT(('2026-09-10 1602'!$A$2:$A$309="400011")*('2026-09-10 1602'!$D$2:$D$309="Not Available")*('2026-09-10 1602'!$E$2:$E$309<>"No"))) | C13: =IF(SUMPRODUCT(--('2026-09-10 2149'!$A$2:$A$309="400011"))=0,"",SUMPRODUCT(('2026-09-10 2149'!$A$2:$A$309="400011")*('2026-09-10 2149'!$D$2:$D$309="Not Available")*('2026-09-10 2149'!$E$2:$E$309<>"No"))) | D13: =IF(SUMPRODUCT(--('2026-09-11 1201'!$A$2:$A$309="400011"))=0,"",SUMPRODUCT(('2026-09-11 1201'!$A$2:$A$309="400011")*('2026-09-11 1201'!$D$2:$D$309="Not Available")*('2026-09-11 1201'!$E$2:$E$309<>"No"))) | E13: =IF(SUMPRODUCT(--('2026-09-11 1253'!$A$2:$A$309="400011"))=0,"",SUMPRODUCT(('2026-09-11 1253'!$A$2:$A$309="400011")*('2026-09-11 1253'!$D$2:$D$309="Not Available")*('2026-09-11 1253'!$E$2:$E$309<>"No"))) | F13: =IF(SUMPRODUCT(--('2026-09-12 1252'!$A$2:$A$309="400011"))=0,"",SUMPRODUCT(('2026-09-12 1252'!$A$2:$A$309="400011")*('2026-09-12 1252'!$D$2:$D$309="Not Available")*('2026-09-12 1252'!$E$2:$E$309<>"No"))) | G13: =IF(SUMPRODUCT(--('2026-09-12 1330'!$A$2:$A$155="400011"))=0,"",SUMPRODUCT(('2026-09-12 1330'!$A$2:$A$155="400011")*('2026-09-12 1330'!$D$2:$D$155="Not Available")*('2026-09-12 1330'!$E$2:$E$155<>"No"))) | H13: =IF(SUMPRODUCT(--('2026-09-12 2141'!$A$2:$A$155="400011"))=0,"",SUMPRODUCT(('2026-09-12 2141'!$A$2:$A$155="400011")*('2026-09-12 2141'!$D$2:$D$155="Not Available")*('2026-09-12 2141'!$E$2:$E$155<>"No"))) | I13: =IF(SUMPRODUCT(--('2026-09-12 2158'!$A$2:$A$155="400011"))=0,"",SUMPRODUCT(('2026-09-12 2158'!$A$2:$A$155="400011")*('2026-09-12 2158'!$D$2:$D$155="Not Available")*('2026-09-12 2158'!$E$2:$E$155<>"No"))) | J13: =IF(SUMPRODUCT(--('2026-09-13 0625'!$A$2:$A$155="400011"))=0,"",SUMPRODUCT(('2026-09-13 0625'!$A$2:$A$155="400011")*('2026-09-13 0625'!$D$2:$D$155="Not Available")*('2026-09-13 0625'!$E$2:$E$155<>"No"))) | K13: =IF(SUMPRODUCT(--('2026-09-13 0640'!$A$2:$A$463="400011"))=0,"",SUMPRODUCT(('2026-09-13 0640'!$A$2:$A$463="400011")*('2026-09-13 0640'!$D$2:$D$463="Not Available")*('2026-09-13 0640'!$E$2:$E$463<>"No"))) | L13: =IF(SUMPRODUCT(--('2026-09-13 0759'!$A$2:$A$463="400011"))=0,"",SUMPRODUCT(('2026-09-13 0759'!$A$2:$A$463="400011")*('2026-09-13 0759'!$D$2:$D$463="Not Available")*('2026-09-13 0759'!$E$2:$E$463<>"No"))) | M13: =IF(SUMPRODUCT(--('2026-09-13 0954'!$A$2:$A$463="400011"))=0,"",SUMPRODUCT(('2026-09-13 0954'!$A$2:$A$463="400011")*('2026-09-13 0954'!$D$2:$D$463="Not Available")*('2026-09-13 0954'!$E$2:$E$463<>"No"))) | N13: =IF(SUMPRODUCT(--('2026-09-13 1159'!$A$2:$A$463="400011"))=0,"",SUMPRODUCT(('2026-09-13 1159'!$A$2:$A$463="400011")*('2026-09-13 1159'!$D$2:$D$463="Not Available")*('2026-09-13 1159'!$E$2:$E$463<>"No"))) | O13: =IF(SUMPRODUCT(--('2026-09-13 1858'!$A$2:$A$463="400011"))=0,"",SUMPRODUCT(('2026-09-13 1858'!$A$2:$A$463="400011")*('2026-09-13 1858'!$D$2:$D$463="Not Available")*('2026-09-13 1858'!$E$2:$E$463<>"No"))) | P13: =IF(SUMPRODUCT(--('2026-09-14 0851'!$A$2:$A$463="400011"))=0,"",SUMPRODUCT(('2026-09-14 0851'!$A$2:$A$463="400011")*('2026-09-14 0851'!$D$2:$D$463="Not Available")*('2026-09-14 0851'!$E$2:$E$463<>"No")))
A14: 400051 | B14: =IF(SUMPRODUCT(--('2026-09-10 1602'!$A$2:$A$309="400051"))=0,"",SUMPRODUCT(('2026-09-10 1602'!$A$2:$A$309="400051")*('2026-09-10 1602'!$D$2:$D$309="Not Available")*('2026-09-10 1602'!$E$2:$E$309<>"No"))) | C14: =IF(SUMPRODUCT(--('2026-09-10 2149'!$A$2:$A$309="400051"))=0,"",SUMPRODUCT(('2026-09-10 2149'!$A$2:$A$309="400051")*('2026-09-10 2149'!$D$2:$D$309="Not Available")*('2026-09-10 2149'!$E$2:$E$309<>"No"))) | D14: =IF(SUMPRODUCT(--('2026-09-11 1201'!$A$2:$A$309="400051"))=0,"",SUMPRODUCT(('2026-09-11 1201'!$A$2:$A$309="400051")*('2026-09-11 1201'!$D$2:$D$309="Not Available")*('2026-09-11 1201'!$E$2:$E$309<>"No"))) | E14: =IF(SUMPRODUCT(--('2026-09-11 1253'!$A$2:$A$309="400051"))=0,"",SUMPRODUCT(('2026-09-11 1253'!$A$2:$A$309="400051")*('2026-09-11 1253'!$D$2:$D$309="Not Available")*('2026-09-11 1253'!$E$2:$E$309<>"No"))) | F14: =IF(SUMPRODUCT(--('2026-09-12 1252'!$A$2:$A$309="400051"))=0,"",SUMPRODUCT(('2026-09-12 1252'!$A$2:$A$309="400051")*('2026-09-12 1252'!$D$2:$D$309="Not Available")*('2026-09-12 1252'!$E$2:$E$309<>"No"))) | G14: =IF(SUMPRODUCT(--('2026-09-12 1330'!$A$2:$A$155="400051"))=0,"",SUMPRODUCT(('2026-09-12 1330'!$A$2:$A$155="400051")*('2026-09-12 1330'!$D$2:$D$155="Not Available")*('2026-09-12 1330'!$E$2:$E$155<>"No"))) | H14: =IF(SUMPRODUCT(--('2026-09-12 2141'!$A$2:$A$155="400051"))=0,"",SUMPRODUCT(('2026-09-12 2141'!$A$2:$A$155="400051")*('2026-09-12 2141'!$D$2:$D$155="Not Available")*('2026-09-12 2141'!$E$2:$E$155<>"No"))) | I14: =IF(SUMPRODUCT(--('2026-09-12 2158'!$A$2:$A$155="400051"))=0,"",SUMPRODUCT(('2026-09-12 2158'!$A$2:$A$155="400051")*('2026-09-12 2158'!$D$2:$D$155="Not Available")*('2026-09-12 2158'!$E$2:$E$155<>"No"))) | J14: =IF(SUMPRODUCT(--('2026-09-13 0625'!$A$2:$A$155="400051"))=0,"",SUMPRODUCT(('2026-09-13 0625'!$A$2:$A$155="400051")*('2026-09-13 0625'!$D$2:$D$155="Not Available")*('2026-09-13 0625'!$E$2:$E$155<>"No"))) | K14: =IF(SUMPRODUCT(--('2026-09-13 0640'!$A$2:$A$463="400051"))=0,"",SUMPRODUCT(('2026-09-13 0640'!$A$2:$A$463="400051")*('2026-09-13 0640'!$D$2:$D$463="Not Available")*('2026-09-13 0640'!$E$2:$E$463<>"No"))) | L14: =IF(SUMPRODUCT(--('2026-09-13 0759'!$A$2:$A$463="400051"))=0,"",SUMPRODUCT(('2026-09-13 0759'!$A$2:$A$463="400051")*('2026-09-13 0759'!$D$2:$D$463="Not Available")*('2026-09-13 0759'!$E$2:$E$463<>"No"))) | M14: =IF(SUMPRODUCT(--('2026-09-13 0954'!$A$2:$A$463="400051"))=0,"",SUMPRODUCT(('2026-09-13 0954'!$A$2:$A$463="400051")*('2026-09-13 0954'!$D$2:$D$463="Not Available")*('2026-09-13 0954'!$E$2:$E$463<>"No"))) | N14: =IF(SUMPRODUCT(--('2026-09-13 1159'!$A$2:$A$463="400051"))=0,"",SUMPRODUCT(('2026-09-13 1159'!$A$2:$A$463="400051")*('2026-09-13 1159'!$D$2:$D$463="Not Available")*('2026-09-13 1159'!$E$2:$E$463<>"No"))) | O14: =IF(SUMPRODUCT(--('2026-09-13 1858'!$A$2:$A$463="400051"))=0,"",SUMPRODUCT(('2026-09-13 1858'!$A$2:$A$463="400051")*('2026-09-13 1858'!$D$2:$D$463="Not Available")*('2026-09-13 1858'!$E$2:$E$463<>"No"))) | P14: =IF(SUMPRODUCT(--('2026-09-14 0851'!$A$2:$A$463="400051"))=0,"",SUMPRODUCT(('2026-09-14 0851'!$A$2:$A$463="400051")*('2026-09-14 0851'!$D$2:$D$463="Not Available")*('2026-09-14 0851'!$E$2:$E$463<>"No")))
A15: 560037 | B15: =IF(SUMPRODUCT(--('2026-09-10 1602'!$A$2:$A$309="560037"))=0,"",SUMPRODUCT(('2026-09-10 1602'!$A$2:$A$309="560037")*('2026-09-10 1602'!$D$2:$D$309="Not Available")*('2026-09-10 1602'!$E$2:$E$309<>"No"))) | C15: =IF(SUMPRODUCT(--('2026-09-10 2149'!$A$2:$A$309="560037"))=0,"",SUMPRODUCT(('2026-09-10 2149'!$A$2:$A$309="560037")*('2026-09-10 2149'!$D$2:$D$309="Not Available")*('2026-09-10 2149'!$E$2:$E$309<>"No"))) | D15: =IF(SUMPRODUCT(--('2026-09-11 1201'!$A$2:$A$309="560037"))=0,"",SUMPRODUCT(('2026-09-11 1201'!$A$2:$A$309="560037")*('2026-09-11 1201'!$D$2:$D$309="Not Available")*('2026-09-11 1201'!$E$2:$E$309<>"No"))) | E15: =IF(SUMPRODUCT(--('2026-09-11 1253'!$A$2:$A$309="560037"))=0,"",SUMPRODUCT(('2026-09-11 1253'!$A$2:$A$309="560037")*('2026-09-11 1253'!$D$2:$D$309="Not Available")*('2026-09-11 1253'!$E$2:$E$309<>"No"))) | F15: =IF(SUMPRODUCT(--('2026-09-12 1252'!$A$2:$A$309="560037"))=0,"",SUMPRODUCT(('2026-09-12 1252'!$A$2:$A$309="560037")*('2026-09-12 1252'!$D$2:$D$309="Not Available")*('2026-09-12 1252'!$E$2:$E$309<>"No"))) | G15: =IF(SUMPRODUCT(--('2026-09-12 1330'!$A$2:$A$155="560037"))=0,"",SUMPRODUCT(('2026-09-12 1330'!$A$2:$A$155="560037")*('2026-09-12 1330'!$D$2:$D$155="Not Available")*('2026-09-12 1330'!$E$2:$E$155<>"No"))) | H15: =IF(SUMPRODUCT(--('2026-09-12 2141'!$A$2:$A$155="560037"))=0,"",SUMPRODUCT(('2026-09-12 2141'!$A$2:$A$155="560037")*('2026-09-12 2141'!$D$2:$D$155="Not Available")*('2026-09-12 2141'!$E$2:$E$155<>"No"))) | I15: =IF(SUMPRODUCT(--('2026-09-12 2158'!$A$2:$A$155="560037"))=0,"",SUMPRODUCT(('2026-09-12 2158'!$A$2:$A$155="560037")*('2026-09-12 2158'!$D$2:$D$155="Not Available")*('2026-09-12 2158'!$E$2:$E$155<>"No"))) | J15: =IF(SUMPRODUCT(--('2026-09-13 0625'!$A$2:$A$155="560037"))=0,"",SUMPRODUCT(('2026-09-13 0625'!$A$2:$A$155="560037")*('2026-09-13 0625'!$D$2:$D$155="Not Available")*('2026-09-13 0625'!$E$2:$E$155<>"No"))) | K15: =IF(SUMPRODUCT(--('2026-09-13 0640'!$A$2:$A$463="560037"))=0,"",SUMPRODUCT(('2026-09-13 0640'!$A$2:$A$463="560037")*('2026-09-13 0640'!$D$2:$D$463="Not Available")*('2026-09-13 0640'!$E$2:$E$463<>"No"))) | L15: =IF(SUMPRODUCT(--('2026-09-13 0759'!$A$2:$A$463="560037"))=0,"",SUMPRODUCT(('2026-09-13 0759'!$A$2:$A$463="560037")*('2026-09-13 0759'!$D$2:$D$463="Not Available")*('2026-09-13 0759'!$E$2:$E$463<>"No"))) | M15: =IF(SUMPRODUCT(--('2026-09-13 0954'!$A$2:$A$463="560037"))=0,"",SUMPRODUCT(('2026-09-13 0954'!$A$2:$A$463="560037")*('2026-09-13 0954'!$D$2:$D$463="Not Available")*('2026-09-13 0954'!$E$2:$E$463<>"No"))) | N15: =IF(SUMPRODUCT(--('2026-09-13 1159'!$A$2:$A$463="560037"))=0,"",SUMPRODUCT(('2026-09-13 1159'!$A$2:$A$463="560037")*('2026-09-13 1159'!$D$2:$D$463="Not Available")*('2026-09-13 1159'!$E$2:$E$463<>"No"))) | O15: =IF(SUMPRODUCT(--('2026-09-13 1858'!$A$2:$A$463="560037"))=0,"",SUMPRODUCT(('2026-09-13 1858'!$A$2:$A$463="560037")*('2026-09-13 1858'!$D$2:$D$463="Not Available")*('2026-09-13 1858'!$E$2:$E$463<>"No"))) | P15: =IF(SUMPRODUCT(--('2026-09-14 0851'!$A$2:$A$463="560037"))=0,"",SUMPRODUCT(('2026-09-14 0851'!$A$2:$A$463="560037")*('2026-09-14 0851'!$D$2:$D$463="Not Available")*('2026-09-14 0851'!$E$2:$E$463<>"No")))
A16: All pincodes | B16: =SUMPRODUCT(('2026-09-10 1602'!$D$2:$D$309="Not Available")*('2026-09-10 1602'!$E$2:$E$309<>"No")) | C16: =SUMPRODUCT(('2026-09-10 2149'!$D$2:$D$309="Not Available")*('2026-09-10 2149'!$E$2:$E$309<>"No")) | D16: =SUMPRODUCT(('2026-09-11 1201'!$D$2:$D$309="Not Available")*('2026-09-11 1201'!$E$2:$E$309<>"No")) | E16: =SUMPRODUCT(('2026-09-11 1253'!$D$2:$D$309="Not Available")*('2026-09-11 1253'!$E$2:$E$309<>"No")) | F16: =SUMPRODUCT(('2026-09-12 1252'!$D$2:$D$309="Not Available")*('2026-09-12 1252'!$E$2:$E$309<>"No")) | G16: =SUMPRODUCT(('2026-09-12 1330'!$D$2:$D$155="Not Available")*('2026-09-12 1330'!$E$2:$E$155<>"No")) | H16: =SUMPRODUCT(('2026-09-12 2141'!$D$2:$D$155="Not Available")*('2026-09-12 2141'!$E$2:$E$155<>"No")) | I16: =SUMPRODUCT(('2026-09-12 2158'!$D$2:$D$155="Not Available")*('2026-09-12 2158'!$E$2:$E$155<>"No")) | J16: =SUMPRODUCT(('2026-09-13 0625'!$D$2:$D$155="Not Available")*('2026-09-13 0625'!$E$2:$E$155<>"No")) | K16: =SUMPRODUCT(('2026-09-13 0640'!$D$2:$D$463="Not Available")*('2026-09-13 0640'!$E$2:$E$463<>"No")) | L16: =SUMPRODUCT(('2026-09-13 0759'!$D$2:$D$463="Not Available")*('2026-09-13 0759'!$E$2:$E$463<>"No")) | M16: =SUMPRODUCT(('2026-09-13 0954'!$D$2:$D$463="Not Available")*('2026-09-13 0954'!$E$2:$E$463<>"No")) | N16: =SUMPRODUCT(('2026-09-13 1159'!$D$2:$D$463="Not Available")*('2026-09-13 1159'!$E$2:$E$463<>"No")) | O16: =SUMPRODUCT(('2026-09-13 1858'!$D$2:$D$463="Not Available")*('2026-09-13 1858'!$E$2:$E$463<>"No")) | P16: =SUMPRODUCT(('2026-09-14 0851'!$D$2:$D$463="Not Available")*('2026-09-14 0851'!$E$2:$E$463<>"No"))

Sheet 2026-09-10 1602
A1: Pincode | B1: Item | C1: ProductName | D1: is_out_of_stock | E1: Serviceable | F1: Quantity | G1: Base_Final quantity | H1: Base_Final unit | I1: Segment | J1: Grocery | K1: National / PL | L1: Product_Link | M1: Backup_Links | N1: Price | O1: MRP | P1: ZeptoSaverPrice | Q1: Weight | R1: Store_ID | S1: Final_Qty | T1: Final_unit | U1: Pincode_Used | V1: Used_Link | W1: Captured_At
A2: 400051 | B2: Aashirvaad Select | Pure MP Sharbati Wheat Atta for Soft Makhmali Rotis | C2: Aashirvaad Select | D2: In Stock | F2: 5 kg | G2: 5000 | H2: g | I2: Atta, Rice & Dal | J2: Atta | L2: https://www.zepto.com/pn/aashirvaad-select-pure-mp-sharbati-wheat-atta-for-soft-makhmali-rotis/pvid/2e1f7fe5-2d09-4282-81c7-b4eaf6b1d86d | N2: 307 | O2: 384 | Q2: 1 pack (5 kg) | R2: 48328608-7aaf-4857-b869-dae167d5f320 | S2: 5000 | T2: g | U2: 400051 | V2: https://www.zepto.com/pn/aashirvaad-select-pure-mp-sharbati-wheat-atta-for-soft-makhmali-rotis/pvid/2e1f7fe5-2d09-4282-81c7-b4eaf6b1d86d | W2: 2026-09-10 16:03:33
A3: 400051 | B3: Fortune Chakki Fresh Atta | C3: Fortune Chakki Fresh Atta | D3: Out of Stock | F3: 5 kg | G3: 5000 | H3: g | I3: Atta, Rice & Dal | J3: Atta | L3: https://www.zepto.com/pn/fortune-chakki-fresh-atta/pvid/14a11cfe-fd72-4901-bf2e-22bc0aba21c0 | N3: 220 | O3: 277 | Q3: 1 pack (5 kg) | R3: 48328608-7aaf-4857-b869-dae167d5f320 | S3: 5000 | T3: g | U3: 400051 | V3: https://www.zepto.com/pn/fortune-chakki-fresh-atta/pvid/14a11cfe-fd72-4901-bf2e-22bc0aba21c0 | W3: 2026-09-10 16:03:42
A4: 400051 | B4: Fortune 100% Chana Dal Besan | C4: Fortune Besan | D4: In Stock | F4: 1 kg | G4: 1000 | H4: g | I4: Atta, Rice & Dal | J4: Besan, Sooji & Maida | L4: https://www.zepto.com/pn/fortune-besan/pvid/1a091cc5-bcde-4ba9-aa49-c81cf27efa72 | N4: 118 | O4: 169 | Q4: 1 pack (1 kg) | R4: 48328608-7aaf-4857-b869-dae167d5f320 | S4: 1000 | T4: g | U4: 400051 | V4: https://www.zepto.com/pn/fortune-besan/pvid/1a091cc5-bcde-4ba9-aa49-c81cf27efa72 | W4: 2026-09-10 16:03:50
A5: 400051 | B5: Rajdhani Sooji/Rava | C5: Rajdhani Premium Sooji | D5: In Stock | F5: 1 kg | G5: 1000 | H5: g | I5: Atta, Rice & Dal | J5: Besan, Sooji & Maida | L5: https://www.zepto.com/pn/rajdhani-premium-sooji/pvid/3d19b418-0df7-4dce-ae3a-a642ab84c1e0 | N5: 84 | O5: 98 | Q5: 1 pack (1 kg) | R5: 48328608-7aaf-4857-b869-dae167d5f320 | S5: 1000 | T5: g | U5: 400051 | V5: https://www.zepto.com/pn/rajdhani-premium-sooji/pvid/3d19b418-0df7-4dce-ae3a-a642ab84c1e0 | W5: 2026-09-10 16:03:59
A6: 400051 | B6: Tata Sampann Unpolished Masoor Dal | C6: Tata Sampann Masoor Dal - Split | D6: In Stock | F6: 500 g | G6: 500 | H6: g | I6: Atta, Rice & Dal | J6: Moong & Masoor | L6: https://www.zepto.com/pn/tata-sampann-masoor-dal-split/pvid/216e3985-3ce7-4849-9990-cd3a98196f04 | N6: 81 | O6: 87 | Q6: 1 pack (500 g) | R6: 48328608-7aaf-4857-b869-dae167d5f320 | S6: 500 | T6: g | U6: 400051 | V6: https://www.zepto.com/pn/tata-sampann-masoor-dal-split/pvid/216e3985-3ce7-4849-9990-cd3a98196f04 | W6: 2026-09-10 16:04:08
A7: 400051 | B7: Tata Sampann Unpolished Organic Moong Sabut | C7: Tata Sampann Organic Unpolished Moong Dal | D7: In Stock | F7: 1 kg | G7: 1000 | H7: g | I7: Atta, Rice & Dal | J7: Moong & Masoor | L7: https://www.zepto.com/pn/tata-sampann-organic-unpolished-moong-dal/pvid/770af74d-f995-46af-9a5a-f2e282371016 | N7: 242 | O7: 270 | Q7: 1 pack (1 kg) | R7: 48328608-7aaf-4857-b869-dae167d5f320 | S7: 1000 | T7: g | U7: 400051 | V7: https://www.zepto.com/pn/tata-sampann-organic-unpolished-moong-dal/pvid/770af74d-f995-46af-9a5a-f2e282371016 | W7: 2026-09-10 16:04:16
A8: 400051 | B8: Nutrela Soya Mini Chunks | C8: Nutrela Mini Soya Chunks | D8: Out of Stock | F8: 200 g | G8: 200 | H8: g | I8: Atta, Rice & Dal | J8: Rajma, Chhole & Others | L8: https://www.zepto.com/pn/nutrela-mini-soya-chunks/pvid/eacffa26-2c0e-4931-8f26-29faa228472f | N8: 50 | O8: 55 | Q8: 1 pack (200 g) | R8: 48328608-7aaf-4857-b869-dae167d5f320 | S8: 200 | T8: g | U8: 400051 | V8: https://www.zepto.com/pn/nutrela-mini-soya-chunks/pvid/eacffa26-2c0e-4931-8f26-29faa228472f | W8: 2026-09-10 16:04:25
A9: 400051 | B9: Tata Sampann Unpolished Kabuli Chana (Big Size) | C9: Tata Sampann Unpolished Kabuli Chana | D9: Out of Stock | F9: 500 g | G9: 500 | H9: g | I9: Atta, Rice & Dal | J9: Rajma, Chhole & Others | L9: https://www.zepto.com/pn/tata-sampann-unpolished-kabuli-chana-medium-size/pvid/ea6f2d5d-4f9d-4323-9513-09b1b8029e12 | N9: 145 | O9: 168 | Q9: 1 pack (1 kg) | R9: 48328608-7aaf-4857-b869-dae167d5f320 | S9: 1000 | T9: g | U9: 400051 | V9: https://www.zepto.com/pn/tata-sampann-unpolished-kabuli-chana-medium-size/pvid/ea6f2d5d-4f9d-4323-9513-09b1b8029e12 | W9: 2026-09-10 16:04:32
A10: 400051 | B10: Tata Sampann Unpolished Rajma | C10: Tata Sampann Unpolished Rajma | D10: In Stock | F10: 500 g | G10: 500 | H10: g | I10: Atta, Rice & Dal | J10: Rajma, Chhole & Others | L10: https://www.zepto.com/pn/tata-sampann-unpolished-rajma-chitra/pvid/2e047530-c785-4480-ad13-80874d0a0a02 | N10: 90 | O10: 108 | Q10: 1 pack (500 g) | R10: 48328608-7aaf-4857-b869-dae167d5f320 | S10: 500 | T10: g | U10: 400051 | V10: https://www.zepto.com/pn/tata-sampann-unpolished-rajma-chitra/pvid/2e047530-c785-4480-ad13-80874d0a0a02 | W10: 2026-09-10 16:04:41
A11: 400051 | B11: Daawat Super Basmati Rice (Long Grain) | C11: Daawat Super Pure Basmati Rice | D11: In Stock | F11: 5 kg | G11: 5000 | H11: g | I11: Atta, Rice & Dal | J11: Rice | L11: https://www.zepto.com/pn/daawat-super-basmati-rice-long-grain/pvid/2da2dcca-ab8e-4e00-afbc-7dd0652fcaca | N11: 832 | O11: 995 | Q11: 1 pack (5 kg) | R11: 48328608-7aaf-4857-b869-dae167d5f320 | S11: 5000 | T11: g | U11: 400051 | V11: https://www.zepto.com/pn/daawat-super-basmati-rice-long-grain/pvid/2da2dcca-ab8e-4e00-afbc-7dd0652fcaca | W11: 2026-09-10 16:04:50
A12: 400051 | B12: India Gate Daily Premium Basmati Rice (Long Grain) | C12: India Gate Flavourful and Fine Daily Premium Basmati Rice | Long and Slender Grains | D12: In Stock | F12: 5 kg | G12: 5000 | H12: g | I12: Atta, Rice & Dal | J12: Rice | L12: https://www.zepto.com/pn/india-gate-flavourful-and-fine-daily-premium-basmati-rice-long-and-slender-grains/pvid/82afa262-7f22-4fa4-b73b-8476d0cf5e6c | N12: 528 | O12: 680 | Q12: 1 pack (5 kg) | R12: 48328608-7aaf-4857-b869-dae167d5f320 | S12: 5000 | T12: g | U12: 400051 | V12: https://www.zepto.com/pn/india-gate-flavourful-and-fine-daily-premium-basmati-rice-long-and-slender-grains/pvid/82afa262-7f22-4fa4-b73b-8476d0cf5e6c | W12: 2026-09-10 16:04:59
A13: 400051 | B13: Tata Sampann Unpolished Chana Dal | C13: Tata Sampann Unpolished Chana Dal | D13: Out of Stock | F13: 500 g | G13: 500 | H13: g | I13: Atta, Rice & Dal | J13: Toor, Urad & Chana | L13: https://www.zepto.com/pn/tata-sampann-unpolished-chana-dal/pvid/2aa43aa2-14b5-45ee-b2c4-502193df52c3 | N13: 70 | O13: 81 | Q13: 1 pack (500 g) | R13: 48328608-7aaf-4857-b869-dae167d5f320 | S13: 500 | T13: g | U13: 400051 | V13: https://www.zepto.com/pn/tata-sampann-unpolished-chana-dal/pvid/2aa43aa2-14b5-45ee-b2c4-502193df52c3 | W13: 2026-09-10 16:05:07
... A15: 400051 | B15: Nestle Cerelac Wheat Apple Baby Cereal (6 - 24 Months) | C15: Nestle CERELAC Wheat Apple Baby Food Cereal, No Preservatives, 6 to 24 Months Baby | D15: In Stock | F15: 350 g | G15: 350 | H15: g | I15: Baby Care | J15: Baby Food | L15: https://www.zepto.com/pn/nestle-cerelac-wheat-apple-baby-food-cereal-no-preservatives-6-to-24-months-baby/pvid/eceafd23-1aaa-489f-aea6-f33d59ff8f1e | N15: 280 | O15: 280 | Q15: 1 pack (350 g) | R15: 48328608-7aaf-4857-b869-dae167d5f320 | S15: 350 | T15: g | U15: 400051 | V15: https://www.zepto.com/pn/nestle-cerelac-wheat-apple-baby-food-cereal-no-preservatives-6-to-24-months-baby/pvid/eceafd23-1aaa-489f-aea6-f33d59ff8f1e | W15: 2026-09-10 16:05:23
A16: 400051 | B16: Himalaya Gentle Baby Wipes | C16: Himalaya Gentle Baby Wipes | D16: Out of Stock | F16: 2 x 72 wipes | G16: 144 | H16: pcs | I16: Baby Care | J16: Baby Wipes | L16: https://www.zepto.com/pn/himalaya-gentle-baby-wipes/pvid/f4b0a5d7-49e0-471b-bc93-72131ebfe0dc | N16: 258 | O16: 280 | Q16: 72pcs | R16: 48328608-7aaf-4857-b869-dae167d5f320 | U16: 400051 | V16: https://www.zepto.com/pn/himalaya-gentle-baby-wipes/pvid/f4b0a5d7-49e0-471b-bc93-72131ebfe0dc | W16: 2026-09-10 16:05:31
A17: 400051 | B17: Johnson's Baby Soap | C17: Johnson Baby Soap Blossoms | D17: In Stock | F17: 3 pcs | G17: 3 | H17: pcs | I17: Baby Care | J17: Bathing Needs | L17: https://www.zepto.com/pn/johnson-baby-soap-blossoms/pvid/1aa108a6-25c8-4ec0-8c99-91e9e0bb1548 | N17: 72 | O17: 75 | Q17: 1 pc (75 g) | R17: 48328608-7aaf-4857-b869-dae167d5f320 | S17: 75 | T17: g | U17: 400051 | V17: https://www.zepto.com/pn/johnson-baby-soap-blossoms/pvid/1aa108a6-25c8-4ec0-8c99-91e9e0bb1548 | W17: 2026-09-10 16:05:40
A18: 400051 | B18: Pampers Happy Sleep Pant Style Baby Diaper (M) | C18: Pampers Premium Care Pants M 20 | D18: Out of Stock | F18: 48 pcs | G18: 48 | H18: pcs | I18: Baby Care | J18: Diapers & More | L18: https://www.zepto.com/pn/pampers-premium-care-pants-m-20-no-marks-design-indias-softest-diaper/pvid/c24ab2ac-660d-4e8a-89a5-4519cb1e7942 | N18: 320 | O18: 350 | Q18: 20pcs | R18: 48328608-7aaf-4857-b869-dae167d5f320 | U18: 400051 | V18: https://www.zepto.com/pn/pampers-premium-care-pants-m-20-no-marks-design-indias-softest-diaper/pvid/c24ab2ac-660d-4e8a-89a5-4519cb1e7942 | W18: 2026-09-10 16:05:49
A19: 400051 | B19: Johnson's Baby Lotion | C19: Johnson's Baby Lotion | D19: In Stock | F19: 200 ml | G19: 200 | H19: ml | I19: Baby Care | J19: Skin & Hair Care | L19: https://www.zepto.com/pn/johnsons-baby-lotion/pvid/2c157578-52ac-4ac6-84c0-d24747d8c894 | N19: 202 | O19: 230 | Q19: 1 pc (200 ml) | R19: 48328608-7aaf-4857-b869-dae167d5f320 | S19: 200 | T19: ml | U19: 400051 | V19: https://www.zepto.com/pn/johnsons-baby-lotion/pvid/2c157578-52ac-4ac6-84c0-d24747d8c894 | W19: 2026-09-10 16:05:57
A20: 400051 | B20: Weikfield Double Action Baking Powder | C20: Weikfield Baking Powder Jar | D20: In Stock | F20: 100 g | G20: 100 | H20: g | I20: Bakery & Biscuits | J20: Baking Ingredients | L20: https://www.zepto.com/pn/weikfield-baking-powder-jar-double-acting/pvid/d0d7ef4e-617d-4029-8d60-82e490c2ac6e | N20: 39 | O20: 40 | Q20: 1 pc (100 g) | R20: 48328608-7aaf-4857-b869-dae167d5f320 | S20: 100 | T20: g | U20: 400051 | V20: https://www.zepto.com/pn/weikfield-baking-powder-jar-double-acting/pvid/d0d7ef4e-617d-4029-8d60-82e490c2ac6e | W20: 2026-09-10 16:06:05
A21: 400051 | B21: Lotte Choco Pie | C21: Lotte Choco Pie | D21: In Stock | F21: 168 g | G21: 168 | H21: g | I21: Bakery & Biscuits | J21: Cakes & Rolls | L21: https://www.zepto.com/pn/lotte-choco-pie-soft-cake-snack/pvid/6e6d41b4-c7c4-4cf4-929c-491aec13a436 | N21: 88 | O21: 99 | Q21: 1 pack (168 g) | R21: 48328608-7aaf-4857-b869-dae167d5f320 | S21: 168 | T21: g | U21: 400051 | V21: https://www.zepto.com/pn/lotte-choco-pie-soft-cake-snack/pvid/6e6d41b4-c7c4-4cf4-929c-491aec13a436 | W21: 2026-09-10 16:06:14
A22: 400051 | B22: Britannia Original Bourbon Creme Biscuit | C22: Britannia The Original Bourbon | D22: In Stock | F22: 150 g | G22: 150 | H22: g | I22: Bakery & Biscuits | J22: Cookies | L22: https://www.zepto.com/pn/britannia-the-original-bourbon-creme-biscuit-with-chocolate-chocolatey-indulgence-in-every-layer/pvid/18cfaa3d-559e-487d-b1c4-33d200c4f757 | N22: 31 | O22: 40 | Q22: 1 pack (160 g) | R22: 48328608-7aaf-4857-b869-dae167d5f320 | S22: 160 | T22: g | U22: 400051 | V22: https://www.zepto.com/pn/britannia-the-original-bourbon-creme-biscuit-with-chocolate-chocolatey-indulgence-in-every-layer/pvid/18cfaa3d-559e-487d-b1c4-33d200c4f757 | W22: 2026-09-10 16:06:22
A23: 400051 | B23: Britannia Good Day Cashew Biscuit | C23: Britannia Good Day Cashew Cookies | D23: In Stock | F23: 200 g | G23: 200 | H23: g | I23: Bakery & Biscuits | J23: Cookies | L23: https://www.zepto.com/pn/britannia-good-day-cashew-cookies-trans-fat-free/pvid/aab332df-fbc5-48a0-b289-e3b223661b5c | N23: 44 | O23: 45 | Q23: 1 pack (200 g) | R23: 48328608-7aaf-4857-b869-dae167d5f320 | S23: 200 | T23: g | U23: 400051 | V23: https://www.zepto.com/pn/britannia-good-day-cashew-cookies-trans-fat-free/pvid/aab332df-fbc5-48a0-b289-e3b223661b5c | W23: 2026-09-10 16:06:30
A24: 400051 | B24: Malkist Cheese Flavoured Cracker Biscuit - Family Pack | C24: Malkist Cheese Crunchy Layered Crackers | D24: In Stock | F24: 144 g | G24: 144 | H24: g | I24: Bakery & Biscuits | J24: Cream Biscuits | L24: https://www.zepto.com/pn/malkist-cheese-crunchy-layered-crackers/pvid/ff124783-3c69-427e-8e35-510a857135b7 | N24: 57 | O24: 60 | Q24: 1 pack (144 g or 150 g) | R24: 48328608-7aaf-4857-b869-dae167d5f320 | S24: 144 | T24: g | U24: 400051 | V24: https://www.zepto.com/pn/malkist-cheese-crunchy-layered-crackers/pvid/ff124783-3c69-427e-8e35-510a857135b7 | W24: 2026-09-10 16:06:39
A25: 400051 | B25: Britannia Marie Gold Marie Biscuits (208 g) | C25: Britannia Vita Marie Gold Biscuits | D25: In Stock | F25: 208 g | G25: 208 | H25: g | I25: Bakery & Biscuits | J25: Glucose & Marie | L25: https://www.zepto.com/pn/britannia-vita-marie-gold-biscuits-trans-fat-free/pvid/51ffd532-68d7-4620-993d-c0ea1d01dfc5 | N25: 38 | O25: 45 | Q25: 1 pack (248 g) | R25: 48328608-7aaf-4857-b869-dae167d5f320 | S25: 248 | T25: g | U25: 400051 | V25: https://www.zepto.com/pn/britannia-vita-marie-gold-biscuits-trans-fat-free/pvid/51ffd532-68d7-4620-993d-c0ea1d01dfc5 | W25: 2026-09-10 16:06:47
A26: 400051 | B26: Britannia NutriChoice Digestive High Fibre Biscuit - 250 g Family Pack | C26: Britannia Nutrichoice High-Fibre Digestive Biscuits | D26: In Stock | F26: 250 g | G26: 250 | H26: g | I26: Bakery & Biscuits | J26: Healthy & Digestive | L26: https://www.zepto.com/pn/britannia-nutrichoice-high-fibre-digestive-biscuits/pvid/f586520f-750a-4593-998f-6cbf0ba8a9a2 | N26: 24 | O26: 25 | Q26: 1 pack (91.7 g or 100 g) | R26: 48328608-7aaf-4857-b869-dae167d5f320 | S26: 91.7 | T26: g | U26: 400051 | V26: https://www.zepto.com/pn/britannia-nutrichoice-high-fibre-digestive-biscuits/pvid/f586520f-750a-4593-998f-6cbf0ba8a9a2 | W26: 2026-09-10 16:06:55
A27: 400051 | B27: McVitie's Digestive High Fibre Biscuit | C27: Mcvitie's Digestive High Fibre Biscuits With Goodness Of Wholewheat,Super Saver Family Pack | D27: In Stock | F27: 959.1 g | G27: 959.1 | H27: g | I27: Bakery & Biscuits | J27: Healthy & Digestive | L27: https://www.zepto.com/pn/mcvities-digestive-high-fibre-biscuits-with-goodness-of-wholewheatsuper-saver-family-pack/pvid/b004a8a7-269a-4d4a-91bc-046ff039d3e8 | N27: 130 | O27: 220 | Q27: 1 pack (959.1 g) | R27: 48328608-7aaf-4857-b869-dae167d5f320 | S27: 959.1 | T27: g | U27: 400051 | V27: https://www.zepto.com/pn/mcvities-digestive-high-fibre-biscuits-with-goodness-of-wholewheatsuper-saver-family-pack/pvid/b004a8a7-269a-4d4a-91bc-046ff039d3e8 | W27: 2026-09-10 16:07:09
A28: 400051 | B28: Nivea Nourishing Body Lotion | C28: NIVEA Nourishing Body Lotion Body Milk | D28: In Stock | F28: 600 ml | G28: 600 | H28: ml | I28: Beauty & Cosmetics | J28: Body & Skin Care | L28: https://www.zepto.com/pn/nivea-nourishing-body-lotion-body-milk48-h-moisturization2x-almond-oilfor-very-dry-skin/pvid/beb074f2-5177-4d23-bcf6-2809bebf7e3e | N28: 322 | O28: 550 | Q28: 1 pc (400 ml) | R28: 48328608-7aaf-4857-b869-dae167d5f320 | S28: 400 | T28: ml | U28: 400051 | V28: https://www.zepto.com/pn/nivea-nourishing-body-lotion-body-milk48-h-moisturization2x-almond-oilfor-very-dry-skin/pvid/beb074f2-5177-4d23-bcf6-2809bebf7e3e | W28: 2026-09-10 16:07:19
A29: 400051 | B29: Maybelline New York Colossal Kajal (Deep Black) | C29: Maybelline New York The Colossal Kajal, Smudgeproof &amp; Waterproof Lasts Up To 24H - Deep Black | D29: In Stock | F29: 0.35 g | G29: 0.35 | H29: g | I29: Beauty & Cosmetics | J29: Eye Makeup | L29: https://www.zepto.com/pn/maybelline-new-york-the-colossal-kajal-smudgeproof-waterproof-lasts-up-to-24h-deep-black/pvid/7a27d6ad-6398-43b7-bc6e-36487651a732 | N29: 173 | O29: 220 | Q29: 1 pc (0.35 g) | R29: 48328608-7aaf-4857-b869-dae167d5f320 | S29: 0.35 | T29: g | U29: 400051 | V29: https://www.zepto.com/pn/maybelline-new-york-the-colossal-kajal-smudgeproof-waterproof-lasts-up-to-24h-deep-black/pvid/7a27d6ad-6398-43b7-bc6e-36487651a732 | W29: 2026-09-10 16:07:28
A30: 400051 | B30: Pond's Bright Beauty Serum Skin Treatment Cream 34 g | C30: Pond's Bright Beauty Anti-Spot Serum Cream With Niacinamide And SPF 15 PA++ | D30: In Stock | F30: 35 g | G30: 35 | H30: g | I30: Beauty & Cosmetics | J30: Face Care | L30: https://www.zepto.com/pn/ponds-bright-beauty-anti-spot-serum-cream-with-niacinamide-and-spf-15-pa/pvid/5554b8fd-d11e-4637-a134-d4da7f091c88 | N30: 298 | O30: 359 | Q30: 1 pc (50 g) | R30: 48328608-7aaf-4857-b869-dae167d5f320 | S30: 50 | T30: g | U30: 400051 | V30: https://www.zepto.com/pn/ponds-bright-beauty-anti-spot-serum-cream-with-niacinamide-and-spf-15-pa/pvid/5554b8fd-d11e-4637-a134-d4da7f091c88 | W30: 2026-09-10 16:07:36
... A37: 400051 | B37: Surf Excel Easy Wash Detergent Powder | C37: Surf Excel Easy Wash Detergent Powder | D37: In Stock | F37: 1 kg | G37: 1000 | H37: g | I37: Cleaning Essentials | J37: Detergent Powder & Bars | L37: https://www.zepto.com/pn/surf-excel-easy-wash-detergent-powder/pvid/05167024-5986-44c6-af23-9011d9738402 | N37: 161 | O37: 167 | Q37: 1 pack (1 kg) | R37: 74aa405e-238e-4103-abb3-096bd7e6f553 | S37: 1000 | T37: g | U37: 400051 | V37: https://www.zepto.com/pn/surf-excel-easy-wash-detergent-powder/pvid/05167024-5986-44c6-af23-9011d9738402 | W37: 2026-09-10 16:08:39
A38: 400051 | B38: Scotch Brite Scrub Pad | C38: Scotch Brite Scrub Pad (Pack of 5) | D38: Out of Stock | F38: 5 pcs | G38: 5 | H38: pcs | I38: Cleaning Essentials | J38: Dishwashing Accessories | L38: https://www.zepto.com/pn/scotch-brite-scrub-pad-pack-of-5/pvid/4d2944bd-38ef-4482-8843-4a86e9009683 | N38: 75 | O38: 90 | Q38: 1 pack (5 pcs) | R38: 74aa405e-238e-4103-abb3-096bd7e6f553 | U38: 400051 | V38: https://www.zepto.com/pn/scotch-brite-scrub-pad-pack-of-5/pvid/4d2944bd-38ef-4482-8843-4a86e9009683 | W38: 2026-09-10 16:08:47
A39: 400051 | B39: Vim Lemon Dishwash Bar (300 g) | C39: Vim Lemon Dishwash Bar | D39: In Stock | F39: 300 g | G39: 300 | H39: g | I39: Cleaning Essentials | J39: Dishwashing Bars & Tubs | L39: https://www.zepto.com/pn/vim-lemon-dishwash-bar/pvid/28eeaa3f-f739-45fd-b797-e138fd64fc62 | N39: 55 | O39: 55 | Q39: 1 pc (480 g) | R39: 74aa405e-238e-4103-abb3-096bd7e6f553 | S39: 480 | T39: g | U39: 400051 | V39: https://www.zepto.com/pn/vim-lemon-dishwash-bar/pvid/28eeaa3f-f739-45fd-b797-e138fd64fc62 | W39: 2026-09-10 16:08:56
A40: 400051 | B40: Vim Lemon Dishwash Gel | C40: Vim Lemon Dishwash Liquid Gel | D40: In Stock | F40: 750 ml | G40: 750 | H40: ml | I40: Cleaning Essentials | J40: Dishwashing Gels & Tablets | L40: https://www.zepto.com/pn/vim-lemon-dishwash-liquid-gel/pvid/ff2f7925-64d6-4fd5-8fe8-c093de4c6488 | N40: 139 | O40: 140 | Q40: 1 pc (500 ml) | R40: 74aa405e-238e-4103-abb3-096bd7e6f553 | S40: 500 | T40: ml | U40: 400051 | V40: https://www.zepto.com/pn/vim-lemon-dishwash-liquid-gel/pvid/ff2f7925-64d6-4fd5-8fe8-c093de4c6488 | W40: 2026-09-10 16:09:04
A41: 400051 | B41: Comfort After Wash Fabric Conditioner (Lily Fresh) | C41: Comfort Morning Fresh After Wash Fabric Conditioner | D41: Out of Stock | F41: 860 ml | G41: 860 | H41: ml | I41: Cleaning Essentials | J41: Fabric Conditioner & Additives | L41: https://www.zepto.com/pn/comfort-morning-fresh-after-wash-fabric-conditioner/pvid/7d9316fc-60ec-4b2f-93c0-e95af778c2e7 | N41: 188 | O41: 245 | Q41: 1 pc (860 ml) | R41: 74aa405e-238e-4103-abb3-096bd7e6f553 | S41: 860 | T41: ml | U41: 400051 | V41: https://www.zepto.com/pn/comfort-morning-fresh-after-wash-fabric-conditioner/pvid/7d9316fc-60ec-4b2f-93c0-e95af778c2e7 | W41: 2026-09-10 16:09:12
A42: 400051 | B42: Lizol Disinfectant Surface & Floor Cleaner (Citrus) 2 l | C42: Lizol Citrus Floor Cleaner Liquid | D42: In Stock | F42: 2 ltr | G42: 2000 | H42: ml | I42: Cleaning Essentials | J42: Floor & Surface Cleaners | L42: https://www.zepto.com/pn/lizol-citrus-floor-cleaner-liquid/pvid/1c17d5d5-f472-4e57-8e76-a49225ef107c | N42: 155 | O42: 169 | Q42: 1 pack (625 ml) | R42: 74aa405e-238e-4103-abb3-096bd7e6f553 | S42: 625 | T42: ml | U42: 400051 | V42: https://www.zepto.com/pn/lizol-citrus-floor-cleaner-liquid/pvid/1c17d5d5-f472-4e57-8e76-a49225ef107c | W42: 2026-09-10 16:09:21
